File: Lab 1/No Temper .is_tens_RawData.csv
Specimen properties : Length,"100.00000",mm
Specimen properties : Thickness,"1.00000",mm
Specimen properties : Width,"10.00000",mm
Test : Rate 1,"5.00000",mm/min

Time,Extension,Load
(s),(mm),(N)
"0.00000","0.00000","0.52161"
"0.10000","0.00515","6.60016"
"0.20000","0.01424","8.72039"
"0.30000","0.02361","16.11253"
"0.40000","0.03261","19.40611"
"0.50000","0.04132","31.00665"
"0.60000","0.04985","37.36550"
"0.70000","0.05838","39.30109"
"0.80000","0.06672","54.09129"
"0.90000","0.07525","75.92101"
"1.00000","0.08349","87.62064"
"1.10000","0.09183","96.83245"
"1.20000","0.10027","108.60648"
"1.30000","0.10851","123.75117"
"1.40000","0.11695","153.49371"
"1.50000","0.12529","203.53189"
"1.60000","0.13353","274.06219"
"1.70000","0.14197","354.89792"
"1.80000","0.15021","437.42075"
"1.90000","0.15855","519.63403"
"2.00000","0.16689","597.49176"
"2.10000","0.17514","659.00958"
"2.20000","0.18357","691.94269"
"2.30000","0.19182","721.92883"
"2.40000","0.20025","739.95471"
"2.50000","0.20859","760.55664"
"2.60000","0.21693","789.69952"
"2.70000","0.22527","821.41992"
"2.80000","0.23352","856.64838"
"2.90000","0.24186","888.18671"
"3.00000","0.25020","925.53442"
"3.10000","0.25854","962.93317"
"3.20000","0.26688","991.90961"
"3.30000","0.27522","1031.78821"
"3.40000","0.28365","1075.22424"
"3.50000","0.29199","1117.44678"
"3.60000","0.30033","1157.98572"
"3.70000","0.30867","1195.42834"
"3.80000","0.31692","1223.79749"
"3.90000","0.32526","1259.95068"
"4.00000","0.33360","1296.86841"
"4.10000","0.34184","1336.89441"
"4.20000","0.35018","1375.12122"
"4.30000","0.35852","1411.39368"
"4.40000","0.36686","1455.91199"
"4.50000","0.37520","1498.10083"
"4.60000","0.38354","1535.08655"
"4.70000","0.39188","1563.84973"
"4.80000","0.40022","1570.34961"
"4.90000","0.40856","1567.58167"
"5.00000","0.41690","1575.72705"
"5.10000","0.42524","1555.01978"
"5.20000","0.43358","1557.31445"
"5.30000","0.44192","1567.50586"
"5.40000","0.45026","1576.38989"
"5.50000","0.45860","1576.52063"
"5.60000","0.46694","1583.14539"
"5.70000","0.47528","1592.78589"
"5.80000","0.48362","1622.60681"
"5.90000","0.49196","1647.42456"
"6.00000","0.50021","1672.30273"
"6.10000","0.50855","1694.26721"
"6.20000","0.51689","1724.38489"
"6.30000","0.52523","1735.12622"
"6.40000","0.53366","1751.76770"
"6.50000","0.54191","1793.31372"
"6.60000","0.55024","1812.05273"
"6.70000","0.55858","1836.74353"
"6.80000","0.56692","1864.41443"
"6.90000","0.57536","1903.81860"
"7.00000","0.58360","1941.63416"
"7.10000","0.59194","1974.55029"
"7.20000","0.60028","2003.76416"
"7.30000","0.60862","2039.52124"
"7.40000","0.61696","2075.99536"
"7.50000","0.62521","2117.75342"
"7.60000","0.63355","2160.37964"
"7.70000","0.64189","2204.06177"
"7.80000","0.65023","2251.36914"
"7.90000","0.65857","2295.87622"
"8.00000","0.66682","2340.75195"
"8.10000","0.67525","2384.00146"
"8.20000","0.68359","2428.42407"
"8.30000","0.69193","2473.07861"
"8.40000","0.70027","2517.84521"
"8.50000","0.70861","2563.15332"
"8.60000","0.71686","2608.53076"
"8.70000","0.72520","2653.70630"
"8.80000","0.73344","2701.34155"
"8.90000","0.74187","2749.11401"
"9.00000","0.75012","2797.81909"
"9.10000","0.75855","2844.96826"
"9.20000","0.76689","2892.28125"
"9.30000","0.77523","2938.19702"
"9.40000","0.78357","2985.83765"
"9.50000","0.79191","3034.97681"
"9.60000","0.80025","3083.46362"
"9.70000","0.80850","3131.50854"
"9.80000","0.81684","3177.03857"
"9.90000","0.82518","3223.79370"
"10.00000","0.83352","3274.26318"
"10.10000","0.84186","3324.49927"
"10.20000","0.85020","3373.18433"
"10.30000","0.85854","3419.09351"
"10.40000","0.86697","3466.92212"
"10.50000","0.87522","3522.23730"
"10.60000","0.88356","3575.02710"
"10.70000","0.89181","3628.19775"
"10.80000","0.90015","3676.86011"
"10.90000","0.90849","3725.16357"
"11.00000","0.91683","3779.19409"
"11.10000","0.92526","3832.85059"
"11.20000","0.93360","3887.27051"
"11.30000","0.94194","3940.74536"
"11.40000","0.95028","3995.61182"
"11.50000","0.95862","4048.06470"
"11.60000","0.96696","4101.49414"
"11.70000","0.97520","4157.76416"
"11.80000","0.98354","4212.34570"
"11.90000","0.99179","4266.13672"
"12.00000","1.00013","4318.80225"
"12.10000","1.00856","4375.06348"
"12.20000","1.01681","4431.70752"
"12.30000","1.02524","4486.08545"
"12.40000","1.03358","4539.23926"
"12.50000","1.04192","4591.89551"
"12.60000","1.05017","4648.44531"
"12.70000","1.05851","4705.76514"
"12.80000","1.06685","4763.94385"
"12.90000","1.07519","4822.43359"
"13.00000","1.08353","4877.42334"
"13.10000","1.09187","4937.01025"
"13.20000","1.10021","4996.33203"
"13.30000","1.10855","5054.69727"
"13.40000","1.11689","5113.09180"
"13.50000","1.12523","5170.47217"
"13.60000","1.13357","5229.35742"
"13.70000","1.14191","5290.29883"
"13.80000","1.15025","5349.57520"
"13.90000","1.15849","5410.86328"
"14.00000","1.16683","5470.13037"
"14.10000","1.17517","5529.38379"
"14.20000","1.18351","5591.14941"
"14.30000","1.19185","5651.61279"
"14.40000","1.20019","5713.60986"
"14.50000","1.20853","5773.82422"
"14.60000","1.21687","5833.30518"
"14.70000","1.22512","5896.21826"
"14.80000","1.23346","5958.01416"
"14.90000","1.24180","6018.76562"
"15.00000","1.25014","6080.83545"
"15.10000","1.25848","6142.09766"
"15.20000","1.26691","6207.67725"
"15.30000","1.27535","6271.62451"
"15.40000","1.28359","6334.03662"
"15.50000","1.29193","6396.69971"
"15.60000","1.30027","6457.81006"
"15.70000","1.30861","6521.52295"
"15.80000","1.31695","6585.39893"
"15.90000","1.32520","6650.26172"
"16.00000","1.33354","6714.27637"
"16.10000","1.34188","6778.73291"
"16.20000","1.35012","6842.93066"
"16.30000","1.35856","6908.79004"
"16.40000","1.36690","6976.33105"
"16.50000","1.37524","7041.14893"
"16.60000","1.38358","7106.63965"
"16.70000","1.39182","7171.19043"
"16.80000","1.40016","7237.87451"
"16.90000","1.40850","7305.64307"
"17.00000","1.41684","7373.06641"
"17.10000","1.42518","7440.03711"
"17.20000","1.43352","7505.95166"
"17.30000","1.44186","7573.01611"
"17.40000","1.45020","7642.36279"
"17.50000","1.45854","7709.18750"
"17.60000","1.46688","7776.28809"
"17.70000","1.47522","7823.80322"
"17.80000","1.48347","7900.62939"
"17.90000","1.49181","7974.71484"
"18.00000","1.50015","8043.27344"
"18.10000","1.50849","8112.66455"
"18.20000","1.51683","8181.97266"
"18.30000","1.52517","8249.32324"
"18.40000","1.53351","8321.07812"
"18.50000","1.54185","8390.25977"
"18.60000","1.55019","8461.38867"
"18.70000","1.55853","8531.52441"
"18.80000","1.56687","8599.79883"
"18.90000","1.57521","8671.58301"
"19.00000","1.58355","8741.97559"
"19.10000","1.59189","8813.93750"
"19.20000","1.60023","8886.75684"
"19.30000","1.60857","8956.85938"
"19.40000","1.61681","9028.81543"
"19.50000","1.62515","9099.99121"
"19.60000","1.63349","9171.99902"
"19.70000","1.64183","9244.73047"
"19.80000","1.65017","9316.44238"
"19.90000","1.65851","9388.51758"
"20.00000","1.66695","9460.88574"
"20.10000","1.67519","9533.58594"
"20.20000","1.68363","9605.99805"
"20.30000","1.69187","9678.93164"
"20.40000","1.70021","9749.16992"
"20.50000","1.70855","9823.24219"
"20.60000","1.71680","9898.47461"
"20.70000","1.72514","9971.00977"
"20.80000","1.73348","10043.31738"
"20.90000","1.74182","10117.99414"
"21.00000","1.75025","10189.61621"
"21.10000","1.75850","10264.84180"
"21.20000","1.76693","10339.34668"
"21.30000","1.77527","10413.72754"
"21.40000","1.78352","10488.57617"
"21.50000","1.79186","10560.47461"
"21.60000","1.80020","10637.80566"
"21.70000","1.80854","10713.08301"
"21.80000","1.81678","10788.82617"
"21.90000","1.82512","10864.01660"
"22.00000","1.83356","10937.55176"
"22.10000","1.84180","11016.01562"
"22.20000","1.85024","11092.49316"
"22.30000","1.85858","11168.36523"
"22.40000","1.86692","11245.28223"
"22.50000","1.87526","11316.76660"
"22.60000","1.88350","11394.90430"
"22.70000","1.89184","11469.85840"
"22.80000","1.90009","11547.72754"
"22.90000","1.90852","11624.21973"
"23.00000","1.91686","11698.47949"
"23.10000","1.92520","11775.26758"
"23.20000","1.93364","11850.60840"
"23.30000","1.94188","11929.05469"
"23.40000","1.95031","12006.25781"
"23.50000","1.95856","12081.09766"
"23.60000","1.96690","12156.45703"
"23.70000","1.97524","12233.93750"
"23.80000","1.98349","12310.24316"
"23.90000","1.99183","12386.97656"
"24.00000","2.00017","12464.23047"
"24.10000","2.00851","12540.09277"
"24.20000","2.01685","12619.08887"
"24.30000","2.02519","12697.93066"
"24.40000","2.03362","12776.68750"
"24.50000","2.04187","12854.31543"
"24.60000","2.05021","12931.07422"
"24.70000","2.05855","13009.47559"
"24.80000","2.06679","13089.03809"
"24.90000","2.07523","13168.18262"
"25.00000","2.08357","13248.30176"
"25.10000","2.09191","13325.62012"
"25.20000","2.10025","13403.82129"
"25.30000","2.10849","13482.83008"
"25.40000","2.11693","13562.13965"
"25.50000","2.12517","13642.95508"
"25.60000","2.13361","13722.40625"
"25.70000","2.14185","13801.62695"
"25.80000","2.15010","13883.25879"
"25.90000","2.15853","13965.43555"
"26.00000","2.16687","14046.57227"
"26.10000","2.17521","14126.24316"
"26.20000","2.18355","14207.00586"
"26.30000","2.19180","14285.79883"
"26.40000","2.20023","14368.75879"
"26.50000","2.20848","14451.72266"
"26.60000","2.21682","14532.78223"
"26.70000","2.22516","14613.99219"
"26.80000","2.23350","14694.61035"
"26.90000","2.24184","14777.92285"
"27.00000","2.25018","14859.94922"
"27.10000","2.25861","14943.05566"
"27.20000","2.26695","15026.24414"
"27.30000","2.27529","15105.34766"
"27.40000","2.28372","15187.71094"
"27.50000","2.29188","15267.72070"
"27.60000","2.30031","15347.59668"
"27.70000","2.30856","15428.72949"
"27.80000","2.31680","15507.98145"
"27.90000","2.32523","15591.15527"
"28.00000","2.33348","15672.58105"
"28.10000","2.34182","15754.82812"
"28.20000","2.35016","15839.95703"
"28.30000","2.35850","15920.35742"
"28.40000","2.36693","16004.65137"
"28.50000","2.37518","16087.24609"
"28.60000","2.38352","16170.28906"
"28.70000","2.39186","16254.62207"
"28.80000","2.40011","16336.86133"
"28.90000","2.40854","16420.50977"
"29.00000","2.41679","16502.99023"
"29.10000","2.42522","16585.45312"
"29.20000","2.43356","16669.44336"
"29.30000","2.44190","16749.78125"
"29.40000","2.45024","16830.91016"
"29.50000","2.45849","16911.47070"
"29.60000","2.46683","16992.66992"
"29.70000","2.47517","17075.99023"
"29.80000","2.48351","17158.12891"
"29.90000","2.49185","17241.06445"
"30.00000","2.50009","17325.01758"
"30.10000","2.50853","17408.14844"
"30.20000","2.51687","17494.18164"
"30.30000","2.52520","17575.48047"
"30.40000","2.53354","17660.41602"
"30.50000","2.54188","17743.80859"
"30.60000","2.55022","17826.63477"
"30.70000","2.55847","17910.31250"
"30.80000","2.56690","17992.82031"
"30.90000","2.57524","18077.31641"
"31.00000","2.58349","18158.73438"
"31.10000","2.59183","18242.06641"
"31.20000","2.60008","18325.94531"
"31.30000","2.60851","18408.63281"
"31.40000","2.61685","18493.49805"
"31.50000","2.62519","18574.62891"
"31.60000","2.63353","18657.24609"
"31.70000","2.64178","18739.80664"
"31.80000","2.65021","18821.97266"
"31.90000","2.65855","18906.21875"
"32.00000","2.66689","18988.04102"
"32.10000","2.67523","19071.76562"
"32.20000","2.68348","19156.00195"
"32.30000","2.69191","19237.57031"
"32.40000","2.70016","19321.44336"
"32.50000","2.70849","19403.95508"
"32.60000","2.71683","19487.68750"
"32.70000","2.72508","19572.13086"
"32.80000","2.73351","19655.89062"
"32.90000","2.74185","19742.13281"
"33.00000","2.75019","19825.98633"
"33.10000","2.75853","19908.51562"
"33.20000","2.76687","19994.15234"
"33.30000","2.77521","20077.09961"
"33.40000","2.78355","20162.72461"
"33.50000","2.79189","20245.31445"
"33.60000","2.80023","20328.31836"
"33.70000","2.80848","20411.59180"
"33.80000","2.81682","20494.54883"
"33.90000","2.82516","20582.22266"
"34.00000","2.83350","20664.98047"
"34.10000","2.84184","20747.74023"
"34.20000","2.85018","20832.18164"
"34.30000","2.85861","20913.73633"
"34.40000","2.86686","20999.10938"
"34.50000","2.87520","21082.00586"
"34.60000","2.88345","21165.85742"
"34.70000","2.89178","21249.29688"
"34.80000","2.90022","21333.60938"
"34.90000","2.90846","21419.67383"
"35.00000","2.91690","21503.50000"
"35.10000","2.92524","21587.43945"
"35.20000","2.93358","21670.78125"
"35.30000","2.94192","21755.60156"
"35.40000","2.95026","21841.08594"
"35.50000","2.95860","21924.31055"
"35.60000","2.96684","22007.50781"
"35.70000","2.97518","22087.93750"
"35.80000","2.98352","22171.54297"
"35.90000","2.99177","22255.07227"
"36.00000","3.00020","22339.19141"
"36.10000","3.00854","22423.22656"
"36.20000","3.01688","22506.33984"
"36.30000","3.02522","22589.37305"
"36.40000","3.03356","22673.43359"
"36.50000","3.04190","22755.67578"
"36.60000","3.05015","22840.36719"
"36.70000","3.05849","22922.27734"
"36.80000","3.06683","23005.85547"
"36.90000","3.07517","23088.55664"
"37.00000","3.08351","23171.79883"
"37.10000","3.09185","23257.29688"
"37.20000","3.10028","23338.69336"
"37.30000","3.10862","23422.51367"
"37.40000","3.11687","23505.88867"
"37.50000","3.12521","23588.24609"
"37.60000","3.13345","23671.51172"
"37.70000","3.14179","23753.94531"
"37.80000","3.15013","23836.98242"
"37.90000","3.15847","23917.85742"
"38.00000","3.16691","24000.23828"
"38.10000","3.17515","24083.55859"
"38.20000","3.18359","24167.20312"
"38.30000","3.19193","24249.23633"
"38.40000","3.20017","24331.25000"
"38.50000","3.20851","24414.76758"
"38.60000","3.21676","24497.24414"
"38.70000","3.22519","24580.66992"
"38.80000","3.23344","24664.61133"
"38.90000","3.24187","24745.90039"
"39.00000","3.25031","24832.97070"
"39.10000","3.25855","24915.22656"
"39.20000","3.26699","24998.21094"
"39.30000","3.27533","25082.82422"
"39.40000","3.28367","25163.83203"
"39.50000","3.29191","25246.00391"
"39.60000","3.30016","25326.90234"
"39.70000","3.30850","25409.02539"
"39.80000","3.31674","25492.04883"
"39.90000","3.32518","25572.90430"
"40.00000","3.33352","25655.43945"
"40.10000","3.34186","25737.58398"
"40.20000","3.35020","25821.48828"
"40.30000","3.35854","25902.98047"
"40.40000","3.36688","25986.21289"
"40.50000","3.37522","26067.88672"
"40.60000","3.38346","26149.44531"
"40.70000","3.39190","26231.98242"
"40.80000","3.40014","26314.83594"
"40.90000","3.40858","26395.97656"
"41.00000","3.41682","26477.58398"
"41.10000","3.42526","26559.65430"
"41.20000","3.43360","26642.77344"
"41.30000","3.44184","26725.02148"
"41.40000","3.45028","26807.46875"
"41.50000","3.45852","26887.80469"
"41.60000","3.46686","26969.42383"
"41.70000","3.47520","27051.27539"
"41.80000","3.48345","27134.77344"
"41.90000","3.49188","27215.75000"
"42.00000","3.50013","27295.20117"
"42.10000","3.50856","27376.68750"
"42.20000","3.51690","27458.40234"
"42.30000","3.52524","27538.84180"
"42.40000","3.53358","27622.25000"
"42.50000","3.54192","27702.18555"
"42.60000","3.55026","27782.89648"
"42.70000","3.55851","27863.78906"
"42.80000","3.56685","27944.36719"
"42.90000","3.57528","28025.09961"
"43.00000","3.58353","28104.58008"
"43.10000","3.59187","28183.89258"
"43.20000","3.60011","28265.16992"
"43.30000","3.60855","28345.88867"
"43.40000","3.61689","28426.91797"
"43.50000","3.62513","28507.18555"
"43.60000","3.63357","28586.45312"
"43.70000","3.64181","28667.08398"
"43.80000","3.65015","28747.35938"
"43.90000","3.65849","28827.27148"
"44.00000","3.66683","28906.16992"
"44.10000","3.67527","28986.44531"
"44.20000","3.68351","29065.14453"
"44.30000","3.69185","29144.16406"
"44.40000","3.70019","29224.55664"
"44.50000","3.70853","29304.49609"
"44.60000","3.71687","29383.03320"
"44.70000","3.72512","29462.86523"
"44.80000","3.73346","29542.04883"
"44.90000","3.74189","29621.05664"
"45.00000","3.75023","29699.79688"
"45.10000","3.75857","29778.09570"
"45.20000","3.76682","29857.57031"
"45.30000","3.77516","29936.83203"
"45.40000","3.78350","30016.78906"
"45.50000","3.79184","30094.18164"
"45.60000","3.80018","30175.04297"
"45.70000","3.80842","30253.26953"
"45.80000","3.81686","30331.42969"
"45.90000","3.82520","30411.97656"
"46.00000","3.83354","30489.22070"
"46.10000","3.84188","30570.50391"
"46.20000","3.85022","30646.30273"
"46.30000","3.85856","30724.05078"
"46.40000","3.86680","30802.30664"
"46.50000","3.87514","30878.82617"
"46.60000","3.88348","30957.89258"
"46.70000","3.89182","31035.66211"
"46.80000","3.90026","31112.92969"
"46.90000","3.90850","31191.90039"
"47.00000","3.91684","31268.35547"
"47.10000","3.92527","31347.41211"
"47.20000","3.93352","31423.80664"
"47.30000","3.94195","31500.48047"
"47.40000","3.95020","31577.97070"
"47.50000","3.95845","31653.75000"
"47.60000","3.96679","31732.28125"
"47.70000","3.97513","31809.43750"
"47.80000","3.98356","31885.51953"
"47.90000","3.99181","31961.04102"
"48.00000","4.00015","32037.62695"
"48.10000","4.00858","32116.88086"
"48.20000","4.01692","32189.85547"
"48.30000","4.02526","32266.53320"
"48.40000","4.03351","32341.11328"
"48.50000","4.04185","32416.09375"
"48.60000","4.05019","32492.26758"
"48.70000","4.05853","32568.17773"
"48.80000","4.06687","32645.24023"
"48.90000","4.07520","32720.91406"
"49.00000","4.08354","32796.25000"
"49.10000","4.09189","32872.48438"
"49.20000","4.10022","32947.56250"
"49.30000","4.10856","33023.33984"
"49.40000","4.11690","33096.58203"
"49.50000","4.12524","33171.25000"
"49.60000","4.13340","33246.00000"
"49.70000","4.14183","33321.24219"
"49.80000","4.15017","33396.07422"
"49.90000","4.15851","33469.37109"
"50.00000","4.16685","33543.21094"
"50.10000","4.17519","33619.10156"
"50.20000","4.18353","33692.98438"
"50.30000","4.19187","33767.72656"
"50.40000","4.20021","33840.75391"
"50.50000","4.20855","33912.57031"
"50.60000","4.21670","33986.39062"
"50.70000","4.22514","34059.15234"
"50.80000","4.23357","34134.31641"
"50.90000","4.24200","34207.16406"
"51.00000","4.25034","34278.79688"
"51.10000","4.25859","34350.71094"
"51.20000","4.26702","34423.37891"
"51.30000","4.27527","34496.02734"
"51.40000","4.28361","34565.55469"
"51.50000","4.29195","34636.46484"
"51.60000","4.30019","34708.44141"
"51.70000","4.30844","34780.75000"
"51.80000","4.31678","34852.50000"
"51.90000","4.32521","34922.91406"
"52.00000","4.33355","34990.46875"
"52.10000","4.34189","35063.24609"
"52.20000","4.35023","35134.32031"
"52.30000","4.35857","35207.16406"
"52.40000","4.36691","35275.81250"
"52.50000","4.37516","35345.97266"
"52.60000","4.38350","35415.04688"
"52.70000","4.39184","35484.87891"
"52.80000","4.40018","35555.98438"
"52.90000","4.40852","35625.57422"
"53.00000","4.41686","35695.58203"
"53.10000","4.42520","35764.00391"
"53.20000","4.43363","35833.12500"
"53.30000","4.44179","35903.00781"
"53.40000","4.45022","35970.37109"
"53.50000","4.45847","36038.93359"
"53.60000","4.46680","36106.32812"
"53.70000","4.47514","36176.40625"
"53.80000","4.48348","36246.43750"
"53.90000","4.49182","36313.82422"
"54.00000","4.50016","36383.06250"
"54.10000","4.50860","36451.44531"
"54.20000","4.51694","36519.24609"
"54.30000","4.52528","36587.92578"
"54.40000","4.53362","36654.99609"
"54.50000","4.54186","36723.35547"
"54.60000","4.55030","36789.54688"
"54.70000","4.55864","36856.17578"
"54.80000","4.56688","36921.69531"
"54.90000","4.57522","36986.67578"
"55.00000","4.58347","37052.21875"
"55.10000","4.59181","37119.38672"
"55.20000","4.60024","37186.44922"
"55.30000","4.60849","37252.28125"
"55.40000","4.61683","37317.77344"
"55.50000","4.62517","37385.08984"
"55.60000","4.63351","37450.87109"
"55.70000","4.64185","37517.59375"
"55.80000","4.65019","37582.88672"
"55.90000","4.65853","37647.41797"
"56.00000","4.66678","37712.60156"
"56.10000","4.67521","37778.66406"
"56.20000","4.68355","37843.27734"
"56.30000","4.69189","37907.82812"
"56.40000","4.70013","37973.04297"
"56.50000","4.70847","38036.46484"
"56.60000","4.71681","38100.98828"
"56.70000","4.72515","38165.15625"
"56.80000","4.73359","38227.16406"
"56.90000","4.74193","38290.89062"
"57.00000","4.75017","38353.34375"
"57.10000","4.75861","38416.45312"
"57.20000","4.76685","38480.03906"
"57.30000","4.77529","38541.35156"
"57.40000","4.78353","38603.50391"
"57.50000","4.79187","38665.14062"
"57.60000","4.80021","38727.89844"
"57.70000","4.80846","38790.18359"
"57.80000","4.81689","38850.81250"
"57.90000","4.82514","38912.79688"
"58.00000","4.83348","38974.44141"
"58.10000","4.84182","39035.53516"
"58.20000","4.85016","39095.17969"
"58.30000","4.85859","39157.09375"
"58.40000","4.86684","39216.80859"
"58.50000","4.87518","39276.07812"
"58.60000","4.88352","39336.40234"
"58.70000","4.89186","39396.45703"
"58.80000","4.90029","39455.60156"
"58.90000","4.90854","39513.61719"
"59.00000","4.91697","39571.89844"
"59.10000","4.92522","39631.64453"
"59.20000","4.93365","39689.17578"
"59.30000","4.94199","39747.53125"
"59.40000","4.95024","39801.92188"
"59.50000","4.95858","39859.20703"
"59.60000","4.96682","39917.20703"
"59.70000","4.97516","39973.80859"
"59.80000","4.98350","40031.73828"
"59.90000","4.99184","40085.95312"
"60.00000","5.00028","40143.99219"
"60.10000","5.00852","40198.81641"
"60.20000","5.01686","40254.87109"
"60.30000","5.02520","40311.38281"
"60.40000","5.03345","40366.07422"
"60.50000","5.04188","40421.13281"
"60.60000","5.05013","40476.94922"
"60.70000","5.05856","40532.40625"
"60.80000","5.06690","40586.64844"
"60.90000","5.07524","40638.90234"
"61.00000","5.08368","40693.15625"
"61.10000","5.09192","40746.28516"
"61.20000","5.10026","40799.33594"
"61.30000","5.10860","40851.64062"
"61.40000","5.11694","40902.80078"
"61.50000","5.12528","40955.66406"
"61.60000","5.13343","41007.58594"
"61.70000","5.14187","41059.93359"
"61.80000","5.15011","41112.46484"
"61.90000","5.15845","41164.07422"
"62.00000","5.16689","41220.26953"
"62.10000","5.17523","41269.47656"
"62.20000","5.18357","41322.64453"
"62.30000","5.19181","41375.10938"
"62.40000","5.20015","41425.99219"
"62.50000","5.20849","41477.36328"
"62.60000","5.21674","41527.58984"
"62.70000","5.22527","41580.32812"
"62.80000","5.23361","41630.53516"
"62.90000","5.24204","41679.00781"
"63.00000","5.25038","41729.23047"
"63.10000","5.25863","41777.10547"
"63.20000","5.26706","41825.05469"
"63.30000","5.27521","41872.56250"
"63.40000","5.28355","41918.23828"
"63.50000","5.29189","41966.81250"
"63.60000","5.30014","42013.33984"
"63.70000","5.30857","42061.08984"
"63.80000","5.31682","42108.07812"
"63.90000","5.32516","42154.04688"
"64.00000","5.33350","42203.66797"
"64.10000","5.34184","42247.52344"
"64.20000","5.35027","42296.10156"
"64.30000","5.35852","42342.31641"
"64.40000","5.36686","42387.84766"
"64.50000","5.37510","42434.03125"
"64.60000","5.38354","42478.99609"
"64.70000","5.39188","42524.90234"
"64.80000","5.40022","42569.00000"
"64.90000","5.40856","42612.48828"
"65.00000","5.41690","42657.05859"
"65.10000","5.42533","42699.09375"
"65.20000","5.43367","42743.84375"
"65.30000","5.44192","42785.33984"
"65.40000","5.45026","42828.65625"
"65.50000","5.45850","42872.16797"
"65.60000","5.46684","42914.96094"
"65.70000","5.47518","42959.39844"
"65.80000","5.48352","42999.29297"
"65.90000","5.49186","43042.05859"
"66.00000","5.50020","43086.13672"
"66.10000","5.50863","43126.26562"
"66.20000","5.51697","43169.22266"
"66.30000","5.52531","43208.34766"
"66.40000","5.53356","43250.35156"
"66.50000","5.54181","43290.66406"
"66.60000","5.55024","43330.05469"
"66.70000","5.55849","43371.38281"
"66.80000","5.56683","43409.46094"
"66.90000","5.57517","43449.92188"
"67.00000","5.58351","43489.22266"
"67.10000","5.59194","43529.75391"
"67.20000","5.60019","43569.67188"
"67.30000","5.60862","43606.43750"
"67.40000","5.61696","43645.45703"
"67.50000","5.62521","43681.80078"
"67.60000","5.63355","43720.08203"
"67.70000","5.64189","43757.85938"
"67.80000","5.65032","43793.94531"
"67.90000","5.65857","43832.06641"
"68.00000","5.66690","43867.97656"
"68.10000","5.67525","43904.50391"
"68.20000","5.68349","43940.55469"
"68.30000","5.69193","43977.55469"
"68.40000","5.70017","44014.01172"
"68.50000","5.70851","44048.98047"
"68.60000","5.71685","44085.94922"
"68.70000","5.72510","44120.30469"
"68.80000","5.73353","44155.28516"
"68.90000","5.74187","44189.71094"
"69.00000","5.75021","44224.21875"
"69.10000","5.75855","44259.66016"
"69.20000","5.76689","44293.89453"
"69.30000","5.77523","44326.67969"
"69.40000","5.78357","44360.10547"
"69.50000","5.79191","44392.67578"
"69.60000","5.80025","44426.62109"
"69.70000","5.80859","44458.85156"
"69.80000","5.81693","44490.82812"
"69.90000","5.82518","44523.37500"
"70.00000","5.83370","44555.38281"
"70.10000","5.84195","44587.61328"
"70.20000","5.85020","44618.47266"
"70.30000","5.85854","44650.87109"
"70.40000","5.86678","44681.78906"
"70.50000","5.87522","44712.64844"
"70.60000","5.88355","44744.97266"
"70.70000","5.89189","44775.62500"
"70.80000","5.90023","44806.88281"
"70.90000","5.90857","44835.89453"
"71.00000","5.91701","44866.75391"
"71.10000","5.92525","44897.34375"
"71.20000","5.93359","44924.05078"
"71.30000","5.94184","44952.24219"
"71.40000","5.95018","44980.12500"
"71.50000","5.95852","45009.38672"
"71.60000","5.96686","45037.26953"
"71.70000","5.97520","45066.04688"
"71.80000","5.98354","45092.99219"
"71.90000","5.99188","45121.82031"
"72.00000","6.00022","45150.49219"
"72.10000","6.00856","45175.09766"
"72.20000","6.01690","45203.28516"
"72.30000","6.02515","45230.55469"
"72.40000","6.03349","45257.07031"
"72.50000","6.04183","45285.34375"
"72.60000","6.05017","45312.43750"
"72.70000","6.05860","45337.64453"
"72.80000","6.06684","45363.58203"
"72.90000","6.07528","45388.16406"
"73.00000","6.08362","45414.83594"
"73.10000","6.09196","45439.89844"
"73.20000","6.10030","45464.05078"
"73.30000","6.10854","45487.60938"
"73.40000","6.11688","45511.67578"
"73.50000","6.12522","45537.15234"
"73.60000","6.13356","45561.19922"
"73.70000","6.14190","45584.87109"
"73.80000","6.15024","45606.98438"
"73.90000","6.15858","45633.25391"
"74.00000","6.16683","45656.25000"
"74.10000","6.17526","45678.76172"
"74.20000","6.18360","45704.43359"
"74.30000","6.19185","45725.82812"
"74.40000","6.20010","45748.81641"
"74.50000","6.20844","45772.89453"
"74.60000","6.21696","45797.14844"
"74.70000","6.22530","45818.76562"
"74.80000","6.23364","45838.37500"
"74.90000","6.24198","45861.11719"
"75.00000","6.25023","45883.87891"
"75.10000","6.25866","45904.48828"
"75.20000","6.26691","45925.26562"
"75.30000","6.27525","45943.42578"
"75.40000","6.28359","45965.67578"
"75.50000","6.29174","45987.03906"
"75.60000","6.30017","46005.98047"
"75.70000","6.30851","46026.56250"
"75.80000","6.31685","46043.31641"
"75.90000","6.32529","46066.57422"
"76.00000","6.33353","46084.15625"
"76.10000","6.34197","46103.93750"
"76.20000","6.35021","46123.88281"
"76.30000","6.35865","46141.12500"
"76.40000","6.36689","46161.07031"
"76.50000","6.37514","46178.64844"
"76.60000","6.38357","46198.30078"
"76.70000","6.39191","46215.88281"
"76.80000","6.40025","46232.37500"
"76.90000","6.40859","46252.65234"
"77.00000","6.41693","46269.69531"
"77.10000","6.42527","46288.90625"
"77.20000","6.43352","46306.01562"
"77.30000","6.44186","46321.58594"
"77.40000","6.45020","46340.12109"
"77.50000","6.45854","46356.42578"
"77.60000","6.46688","46373.72656"
"77.70000","6.47512","46389.78125"
"77.80000","6.48356","46404.16016"
"77.90000","6.49190","46423.50000"
"78.00000","6.50033","46436.64844"
"78.10000","6.50867","46455.83594"
"78.20000","6.51692","46470.03125"
"78.30000","6.52526","46485.54297"
"78.40000","6.53360","46500.50391"
"78.50000","6.54194","46515.16797"
"78.60000","6.55028","46530.67969"
"78.70000","6.55843","46542.93359"
"78.80000","6.56686","46557.33984"
"78.90000","6.57520","46573.01953"
"79.00000","6.58364","46587.65625"
"79.10000","6.59198","46602.88281"
"79.20000","6.60022","46615.19141"
"79.30000","6.60866","46630.23047"
"79.40000","6.61681","46642.78125"
"79.50000","6.62524","46657.00391"
"79.60000","6.63358","46670.23828"
"79.70000","6.64192","46680.49219"
"79.80000","6.65026","46692.75391"
"79.90000","6.65851","46705.44531"
"80.00000","6.66694","46715.84766"
"80.10000","6.67528","46728.95312"
"80.20000","6.68353","46739.30859"
"80.30000","6.69187","46750.94531"
"80.40000","6.70021","46762.06641"
"80.50000","6.70855","46773.84375"
"80.60000","6.71689","46786.71484"
"80.70000","6.72523","46796.19922"
"80.80000","6.73357","46807.30078"
"80.90000","6.74191","46817.08203"
"81.00000","6.75025","46829.24219"
"81.10000","6.75859","46838.92969"
"81.20000","6.76693","46846.81641"
"81.30000","6.77527","46856.63672"
"81.40000","6.78351","46865.03516"
"81.50000","6.79185","46874.72656"
"81.60000","6.80019","46883.04688"
"81.70000","6.80863","46890.39844"
"81.80000","6.81687","46899.11719"
"81.90000","6.82521","46907.04688"
"82.00000","6.83365","46914.95703"
"82.10000","6.84189","46921.72266"
"82.20000","6.85023","46929.24609"
"82.30000","6.85848","46937.46875"
"82.40000","6.86691","46942.96875"
"82.50000","6.87525","46950.83984"
"82.60000","6.88359","46956.72266"
"82.70000","6.89202","46961.50391"
"82.80000","6.90027","46965.63281"
"82.90000","6.90870","46969.98438"
"83.00000","6.91695","46975.44141"
"83.10000","6.92529","46977.74219"
"83.20000","6.93363","46980.50781"
"83.30000","6.94188","46983.67578"
"83.40000","6.95022","46986.75000"
"83.50000","6.95846","46990.78516"
"83.60000","6.96680","46991.14453"
"83.70000","6.97524","46993.37500"
"83.80000","6.98358","46994.80078"
"83.90000","6.99192","46995.37891"
"84.00000","7.00026","46994.80469"
"84.10000","7.00860","46993.82031"
"84.20000","7.01694","46992.71094"
"84.30000","7.02528","46989.88672"
"84.40000","7.03362","46988.40625"
"84.50000","7.04186","46985.35938"
"84.60000","7.05030","46980.50000"
"84.70000","7.05864","46977.82812"
"84.80000","7.06707","46970.10156"
"84.90000","7.07532","46965.73047"
"85.00000","7.08366","46960.20312"
"85.10000","7.09199","46952.41406"
"85.20000","7.10024","46944.93359"
"85.30000","7.10858","46936.18359"
"85.40000","7.11692","46929.46484"
"85.50000","7.12517","46921.24219"
"85.60000","7.13351","46911.70703"
"85.70000","7.14185","46900.80469"
"85.80000","7.15028","46890.72266"
"85.90000","7.15862","46878.99609"
"86.00000","7.16687","46864.23047"
"86.10000","7.17530","46850.45312"
"86.20000","7.18345","46835.43359"
"86.30000","7.19189","46818.09766"
"86.40000","7.20023","46803.29297"
"86.50000","7.20857","46787.28125"
"86.60000","7.21700","46768.60156"
"86.70000","7.22534","46750.13281"
"86.80000","7.23368","46730.24219"
"86.90000","7.24202","46710.62891"
"87.00000","7.25036","46688.04297"
"87.10000","7.25861","46667.12109"
"87.20000","7.26685","46644.82031"
"87.30000","7.27519","46623.13281"
"87.40000","7.28353","46601.11328"
"87.50000","7.29187","46576.74219"
"87.60000","7.30021","46552.39844"
"87.70000","7.30855","46524.66797"
"87.80000","7.31698","46500.08203"
"87.90000","7.32523","46470.55078"
"88.00000","7.33366","46442.17969"
"88.10000","7.34200","46414.15234"
"88.20000","7.35025","46383.57812"
"88.30000","7.35859","46353.39062"
"88.40000","7.36684","46323.49609"
"88.50000","7.37527","46295.50781"
"88.60000","7.38361","46266.45703"
"88.70000","7.39195","46236.28516"
"88.80000","7.40029","46205.48438"
"88.90000","7.40863","46172.91797"
"89.00000","7.41706","46139.91797"
"89.10000","7.42531","46104.86719"
"89.20000","7.43356","46067.69922"
"89.30000","7.44190","46032.46875"
"89.40000","7.45014","45995.94922"
"89.50000","7.45858","45959.26562"
"89.60000","7.46692","45920.76953"
"89.70000","7.47526","45880.07812"
"89.80000","7.48359","45842.39844"
"89.90000","7.49193","45798.74219"
"90.00000","7.50037","45759.02734"
"90.10000","7.50861","45715.48828"
"90.20000","7.51695","45671.39844"
"90.30000","7.52529","45630.65625"
"90.40000","7.53354","45588.26562"
"90.50000","7.54197","45545.43750"
"90.60000","7.55022","45499.03906"
"90.70000","7.55856","45452.41406"
"90.80000","7.56690","45406.07812"
"90.90000","7.57533","45356.55078"
"91.00000","7.58367","45308.43750"
"91.10000","7.59192","45256.62109"
"91.20000","7.60035","45205.39453"
"91.30000","7.60860","45152.05469"
"91.40000","7.61694","45097.98047"
"91.50000","7.62528","45043.48828"
"91.60000","7.63352","44984.12891"
"91.70000","7.64196","44917.78906"
"91.80000","7.65021","44843.47266"
"91.90000","7.65864","44740.95703"
"91.97000","7.66688","26751.14258"