File: Lab 1/temper 440C 1hr.is_tens_RawData.csv
Specimen properties : Length,100,mm
Specimen properties : Thickness,1,mm
Specimen properties : Width,10,mm
Test : Rate 1,5,mm/min
,,
Time,Extension,Load
(s),(mm),(N)
0,0,0.21725
0.1,0.0044,6.44279
0.2,0.01349,9.65009
0.3,0.02305,13.97355
0.4,0.03224,33.49188
0.5,0.04104,62.0619
0.6,0.04966,77.29037
0.7,0.05819,91.24818
0.8,0.06663,105.99339
0.9,0.07497,122.78646
1,0.08331,153.0649
1.1,0.09174,208.75908
1.2,0.10017,292.59116
1.3,0.10851,393.34631
1.4,0.11685,503.16245
1.5,0.12519,621.26105
1.6,0.13353,740.44812
1.7,0.14178,864.13007
1.8,0.15012,989.04523
1.9,0.15827,1110.63672
2,0.16661,1230.24951
2.1,0.17504,1347.96423
2.2,0.18338,1463.61414
2.3,0.19182,1576.97815
2.4,0.20006,1688.66064
2.5,0.2084,1796.4408
2.6,0.21674,1900.7959
2.7,0.22508,2002.85278
2.8,0.23352,2104.39941
2.9,0.24176,2204.02393
3,0.2501,2301.16113
3.1,0.25844,2395.67114
3.2,0.26669,2492.33032
3.3,0.27512,2587.99878
3.4,0.28337,2684.17822
3.5,0.2918,2780.63525
3.6,0.30005,2875.65039
3.7,0.30839,2968.50903
3.8,0.31673,3064.21948
3.9,0.32497,3159.06519
4,0.33341,3255.35278
4.1,0.34175,3351.53442
4.2,0.35009,3446.13647
4.3,0.35843,3538.81909
4.4,0.36677,3634.07739
4.5,0.37511,3727.45215
4.6,0.38345,3821.57593
4.7,0.39179,3915.67358
4.8,0.40013,4005.21655
4.9,0.40837,4098.34326
5,0.41671,4189.70605
5.1,0.42505,4280.39648
5.2,0.4333,4372.58398
5.3,0.44173,4461.96777
5.4,0.44998,4553.81592
5.5,0.45841,4646.02539
5.6,0.46675,4736.95654
5.7,0.475,4828.17871
5.8,0.48343,4918.71631
5.9,0.49168,5009.55078
6,0.50011,5101.69678
6.1,0.50836,5191.35645
6.2,0.51679,5279.7041
6.3,0.52513,5368.39307
6.4,0.53338,5455.79248
6.5,0.54181,5544.83008
6.6,0.55006,5631.66309
6.7,0.5584,5718.52197
6.8,0.56674,5803.79932
6.9,0.57498,5887.35254
7,0.58342,5972.49268
7.1,0.59166,6058.99072
7.2,0.6,6142.89209
7.3,0.60834,6227.07227
7.4,0.61668,6309.99658
7.5,0.62512,6393.00928
7.6,0.63336,6475.80322
7.7,0.6417,6557.6792
7.8,0.65004,6638.02344
7.9,0.65838,6718.90527
8,0.66672,6797.79785
8.1,0.67506,6876.06055
8.2,0.6834,6953.00928
8.3,0.69174,7026.53027
8.4,0.70008,7097.34619
8.5,0.70842,7165.72754
8.6,0.71667,7236.92236
8.7,0.72501,7307.64209
8.8,0.73335,7377.95361
8.9,0.74169,7448.32812
9,0.75012,7516.92871
9.1,0.75837,7588.94238
9.2,0.76671,7661.01904
9.3,0.77505,7734.20703
9.4,0.78339,7805.20898
9.5,0.79182,7875.53027
9.6,0.80007,7948.36133
9.7,0.80841,8019.521
9.8,0.81665,8094.1543
9.9,0.82499,8167.65479
10,0.83333,8238.63965
10.1,0.84167,8312.55859
10.2,0.85011,8384.06934
10.3,0.85835,8457.39648
10.4,0.86679,8528.86621
10.5,0.87513,8600.28711
10.6,0.88337,8670.76172
10.7,0.89171,8744.24023
10.8,0.89996,8817.46582
10.9,0.90839,8889.6748
11,0.91673,8963.125
11.1,0.92507,9034.82031
11.2,0.93341,9109.39062
11.3,0.94175,9185.43164
11.4,0.95018,9259.08984
11.5,0.95852,9333.69727
11.6,0.96677,9405.9707
11.7,0.97511,9479.30957
11.8,0.98336,9554.71289
11.9,0.9917,9629.69922
12,1.00004,9705.87793
12.1,1.00838,9780.49512
12.2,1.01672,9856.24023
12.3,1.02506,9932.11035
12.4,1.0334,10005.45215
12.5,1.04174,10080.8623
12.6,1.05008,10154.64551
12.7,1.05842,10226.7168
12.8,1.06666,10301.35645
12.9,1.075,10376.28418
13,1.08344,10453.09277
13.1,1.09178,10528.83301
13.2,1.10021,10603.4707
13.3,1.10855,10683.08789
13.4,1.11689,10757.88379
13.5,1.12523,10836.78613
13.6,1.13347,10913.20801
13.7,1.14181,10987.99902
13.8,1.14997,11065.25098
13.9,1.15831,11144.08496
14,1.16665,11222.50684
14.1,1.17499,11301.37109
14.2,1.18342,11377.78809
14.3,1.19167,11454.42969
14.4,1.2001,11531.80664
14.5,1.20844,11609.84863
14.6,1.21678,11686.4707
14.7,1.22512,11762.88086
14.8,1.23337,11838.33691
14.9,1.24171,11914.15234
15,1.25005,11990.59375
15.1,1.25839,12068.00098
15.2,1.26673,12146.26172
15.3,1.27507,12225.50098
15.4,1.28341,12302.90332
15.5,1.29175,12382.96582
15.6,1.30008,12462.4248
15.7,1.30833,12539.8916
15.8,1.31667,12619.3584
15.9,1.32501,12697.55176
16,1.33335,12779.23242
16.1,1.34169,12858.67285
16.2,1.35003,12939.26953
16.3,1.35846,13018.74023
16.4,1.3668,13094.9541
16.5,1.37514,13174.38379
16.6,1.38339,13252.06055
16.7,1.39173,13330.57422
16.8,1.40007,13408.25391
16.9,1.40841,13483.77148
17,1.41666,13562.01367
17.1,1.425,13638.41992
17.2,1.43334,13717.05371
17.3,1.44177,13797.58887
17.4,1.45011,13874.69727
17.5,1.45836,13953.70508
17.6,1.46679,14032.67676
17.7,1.47504,14112.42676
17.8,1.48338,14191.2627
17.9,1.49171,14271.58691
18,1.50005,14350.85352
18.1,1.50839,14432.15332
18.2,1.51673,14512.87891
18.3,1.52507,14590.37207
18.4,1.53341,14669.48242
18.5,1.54166,14745.36035
18.6,1.55,14823.65625
18.7,1.55834,14903.66016
18.8,1.56668,14982.9541
18.9,1.57502,15062.99512
19,1.58336,15138.64258
19.1,1.5917,15216.76465
19.2,1.60004,15297.78223
19.3,1.60838,15378.44043
19.4,1.61672,15458.45312
19.5,1.62506,15536.37402
19.6,1.6334,15616.34375
19.7,1.64165,15695.12598
19.8,1.64999,15775.88281
19.9,1.65842,15857.02344
20,1.66676,15938.08789
20.1,1.6751,16018.36816
20.2,1.68334,16098.50391
20.3,1.69178,16181.65234
20.4,1.70002,16262.00195
20.5,1.70836,16340.33203
20.6,1.7167,16417.13477
20.7,1.72504,16496.58984
20.8,1.73338,16575.23828
20.9,1.74172,16655.07031
21,1.75006,16732.51562
21.1,1.7584,16809.32422
21.2,1.76674,16887.97852
21.3,1.77508,16968.89453
21.4,1.78342,17049.72852
21.5,1.79167,17128.5957
21.6,1.80001,17207.67969
21.7,1.80835,17287.97656
21.8,1.81669,17369
21.9,1.82503,17453.8125
22,1.83346,17535.90625
22.1,1.8418,17615.89844
22.2,1.85005,17696.18555
22.3,1.85848,17776.85547
22.4,1.86673,17857.52734
22.5,1.87507,17937.36523
22.6,1.88341,18017.55664
22.7,1.89165,18097.13672
22.8,1.89999,18178.25977
22.9,1.90833,18259.93945
23,1.91677,18339.89062
23.1,1.92511,18419.48438
23.2,1.93345,18499.49805
23.3,1.94179,18581.87305
23.4,1.95013,18661.8457
23.5,1.95847,18742.80664
23.6,1.96671,18825.24805
23.7,1.97505,18904.98828
23.8,1.9833,18985.57422
23.9,1.99164,19067.80469
24,2.00007,19150.87695
24.1,2.00832,19234.25195
24.2,2.01675,19316.38867
24.3,2.02509,19398.83008
24.4,2.03343,19481.10938
24.5,2.04177,19561.20703
24.6,2.05002,19641.70898
24.7,2.05836,19721.42969
24.8,2.0667,19803.26562
24.9,2.07513,19884.74414
25,2.08347,19964.57617
25.1,2.09181,20044.79492
25.2,2.10015,20126.65039
25.3,2.10849,20206.2832
25.4,2.11683,20286.08984
25.5,2.12508,20368.5625
25.6,2.13332,20450.82227
25.7,2.14166,20531.03516
25.8,2.15,20613.85742
25.9,2.15825,20697.46289
26,2.16668,20782.89453
26.1,2.17502,20867.72266
26.2,2.18346,20950.45703
26.3,2.1918,21036.11914
26.4,2.20014,21117.4082
26.5,2.20848,21199.41211
26.6,2.21672,21281.83008
26.7,2.22506,21364.29102
26.8,2.2334,21446.91602
26.9,2.24174,21526.34961
27,2.25008,21606.38281
27.1,2.25833,21688.13867
27.2,2.26676,21772.38477
27.3,2.27501,21855.11523
27.4,2.28344,21937.60352
27.5,2.29178,22019.51367
27.6,2.30003,22102.00586
27.7,2.30837,22183.76172
27.8,2.31671,22266.74414
27.9,2.32505,22350.12891
28,2.33339,22431.99219
28.1,2.34173,22516.64258
28.2,2.35007,22600.32422
28.3,2.35841,22685.27734
28.4,2.36675,22770.55078
28.5,2.37509,22851.70703
28.6,2.38343,22931.20703
28.7,2.39177,23012.26172
28.8,2.40001,23094.78906
28.9,2.40835,23175.78906
29,2.41669,23255.125
29.1,2.42503,23336.57227
29.2,2.43337,23418.14648
29.3,2.44171,23499.81836
29.4,2.45005,23582.42188
29.5,2.45849,23666.16602
29.6,2.46673,23746.01562
29.7,2.47507,23828.01562
29.8,2.48332,23911.11328
29.9,2.49175,23994.18359
30,2.50009,24077.25977
30.1,2.50843,24158.94336
30.2,2.51668,24240.86523
30.3,2.52502,24323.20312
30.4,2.53345,24404.85156
30.5,2.5417,24484.79297
30.6,2.55013,24562.47266
30.7,2.55838,24643.71875
30.8,2.56672,24724.67969
30.9,2.57506,24804.07031
31,2.5834,24879.38867
31.1,2.59174,24951.3457
31.2,2.60008,25026.47266
31.3,2.60832,25094.91211
31.4,2.61676,25162.5625
31.5,2.625,25221.14844
31.6,2.63344,25260.68945
31.7,2.64168,25277.36133
31.8,2.65002,25270.28711
31.9,2.65846,25266.49023
32,2.6667,25254.48242
32.1,2.67514,25233.33398
32.2,2.68348,25220.39062
32.3,2.69172,25195.37305
32.4,2.70006,25190.45508
32.5,2.7084,25191.03906
32.6,2.71674,25196.71289
32.7,2.72508,25207.70508
32.8,2.73342,25221.17188
32.9,2.74176,25235.75195
33,2.75001,25248.19141
33.1,2.75844,25253.15625
33.2,2.76678,25258.94922
33.3,2.77512,25278.87891
33.4,2.78346,25295.54102
33.5,2.79171,25315.89062
33.6,2.80005,25342.12109
33.7,2.80839,25361.70117
33.8,2.81673,25376.76758
33.9,2.82507,25399.75977
34,2.83341,25431.31055
34.1,2.84184,25460.57422
34.2,2.85009,25481.96094
34.3,2.85843,25498.50391
34.4,2.86677,25518.63867
34.5,2.87501,25534.33203
34.6,2.88335,25552.96094
34.7,2.89169,25569.82617
34.8,2.90003,25585.40039
34.9,2.90837,25594.14453
35,2.9168,25602.88281
35.1,2.92514,25615.13477
35.2,2.93339,25635.03711
35.3,2.94182,25655.24609
35.4,2.95016,25678.96484
35.5,2.95841,25701.71875
35.6,2.96675,25723.97852
35.7,2.975,25745.42188
35.8,2.98343,25766.91797
35.9,2.99168,25786.78125
36,3.00011,25806.42383
36.1,3.00845,25825.49805
36.2,3.01679,25844.26953
36.3,3.02513,25863.29297
36.4,3.03338,25880.38672
36.5,3.04172,25897.94727
36.6,3.05006,25913.88281
36.7,3.0584,25931.35547
36.8,3.06683,25948.83984
36.9,3.07517,25964.41797
37,3.08351,25978.92969
37.1,3.09185,25994.5332
37.2,3.10019,26011.45898
37.3,3.10853,26025.63867
37.4,3.11677,26040.98242
37.5,3.12511,26056.54688
37.6,3.13336,26072.85742
37.7,3.1417,26089.0625
37.8,3.15004,26104.64062
37.9,3.15838,26120.47852
38,3.16681,26133.40234
38.1,3.17506,26150.61328
38.2,3.18349,26164.82031
38.3,3.19183,26179.12305
38.4,3.20017,26193.80859
38.5,3.20851,26206.32031
38.6,3.21676,26218.53125
38.7,3.2251,26232.03125
38.8,3.23344,26246.13086
38.9,3.24178,26259.80664
39,3.25012,26271.99023
39.1,3.25836,26284.81055
39.2,3.2668,26297.75195
39.3,3.27514,26308.73242
39.4,3.28338,26322.27148
39.5,3.29172,26336.37695
39.6,3.30006,26348.10547
39.7,3.3084,26360.95508
39.8,3.31674,26374.33398
39.9,3.32508,26385.71484
40,3.33352,26396.85547
40.1,3.34176,26408.98438
40.2,3.3502,26421.12305
40.3,3.35854,26433.66797
40.4,3.36678,26445.31445
40.5,3.37512,26458.69922
40.6,3.38346,26469.06055
40.7,3.3918,26478.60938
40.8,3.40005,26489.32617
40.9,3.40839,26500.44922
41,3.41673,26511.50781
41.1,3.42507,26521.80859
41.2,3.43341,26533.70117
41.3,3.44175,26543.45117
41.4,3.45009,26553.52344
41.5,3.45843,26566.24609
41.6,3.46677,26577.72852
41.7,3.47511,26588.52344
41.8,3.48335,26599.62695
41.9,3.49179,26608.82812
42,3.50013,26619.19922
42.1,3.50847,26631.54688
42.2,3.51681,26642.50977
42.3,3.52515,26651.9668
42.4,3.53349,26661.33594
42.5,3.54183,26672.02148
42.6,3.55007,26680.39258
42.7,3.55851,26690.12891
42.8,3.56675,26699.57812
42.9,3.57509,26709.19922
43,3.58334,26718.57422
43.1,3.59168,26728.34375
43.2,3.60011,26738.97656
43.3,3.60845,26746.12109
43.4,3.61679,26755.51172
43.5,3.62504,26767.34375
43.6,3.63338,26776.79297
43.7,3.64172,26787.45312
43.8,3.65006,26796.22852
43.9,3.65849,26804.41797
44,3.66674,26813.81641
44.1,3.67508,26821.88672
44.2,3.68351,26833.10742
44.3,3.69176,26842.51367
44.4,3.70019,26851.00781
44.5,3.70844,26860.68359
44.6,3.71678,26870.12891
44.7,3.72512,26877.38477
44.8,3.73346,26885.0332
44.9,3.74189,26892.92383
45,3.75014,26899.27539
45.1,3.75848,26909.18359
45.2,3.76682,26917.73828
45.3,3.77516,26924.03516
45.4,3.7835,26932.80078
45.5,3.79174,26941.22461
45.6,3.80008,26951.79492
45.7,3.80842,26961.10352
45.8,3.81676,26970.23828
45.9,3.8252,26976.56445
46,3.83344,26984.78125
46.1,3.84178,26993.26953
46.2,3.85012,27003.88477
46.3,3.85846,27011.94336
46.4,3.8668,27019.95703
46.5,3.87505,27027.37695
46.6,3.88348,27034.60547
46.7,3.89173,27042.78516
46.8,3.90007,27049.87305
46.9,3.9085,27057.40625
47,3.91675,27062.66602
47.1,3.92509,27073.6875
47.2,3.93343,27079.40625
47.3,3.94177,27086.00781
47.4,3.95011,27095.56836
47.5,3.95835,27101.63086
47.6,3.96669,27111.62305
47.7,3.97494,27119.84766
47.8,3.98337,27128.85352
47.9,3.99181,27135.8125
48,4.00015,27141.96484
48.1,4.00849,27148.61133
48.2,4.01673,27157.27344
48.3,4.02517,27165.8418
48.4,4.03341,27172.26953
48.5,4.04175,27179.0293
48.6,4.05019,27188.63281
48.7,4.05853,27194.09766
48.8,4.06687,27199.23242
48.9,4.0752,27205.46484
49,4.08354,27209.70508
49.1,4.09189,27217.74219
49.2,4.10013,27222.32617
49.3,4.10847,27230.92773
49.4,4.11672,27237.72266
49.5,4.12496,27244.03516
49.6,4.1334,27252.7168
49.7,4.14164,27260.74414
49.8,4.15008,27269.1875
49.9,4.15842,27275.85938
50,4.16676,27281.07227
50.1,4.17519,27288.69531
50.2,4.18353,27296.85547
50.3,4.19187,27303.13477
50.4,4.20012,27308.28516
50.5,4.20855,27314.20898
50.6,4.2168,27320.30078
50.7,4.22514,27325.52539
50.8,4.23348,27331.82617
50.9,4.24172,27336.63086
51,4.25006,27343.74414
51.1,4.2584,27353.26562
51.2,4.26674,27354.91406
51.3,4.27517,27362.22656
51.4,4.28342,27368.31055
51.5,4.29176,27374.5625
51.6,4.3001,27382.35352
51.7,4.30844,27387.54492
51.8,4.31678,27395.46289
51.9,4.32503,27400.78906
52,4.33346,27406.64844
52.1,4.34189,27413.51172
52.2,4.35014,27417.54102
52.3,4.35857,27423.87109
52.4,4.36682,27429.45508
52.5,4.37516,27435.82227
52.6,4.3835,27444.16211
52.7,4.39175,27448.47461
52.8,4.40009,27451.00781
52.9,4.40843,27455.60742
53,4.41677,27460.60547
53.1,4.42511,27466.54688
53.2,4.43345,27470.45117
53.3,4.44179,27476.49023
53.4,4.45013,27481.40625
53.5,4.45847,27486.5918
53.6,4.46671,27492.96484
53.7,4.47514,27500.00586
53.8,4.48339,27506.63086
53.9,4.49173,27510.94141
54,4.50007,27516.34961
54.1,4.50841,27522.58984
54.2,4.51675,27527.66992
54.3,4.52509,27535.51562
54.4,4.53343,27538.30859
54.5,4.54177,27542.99609
54.6,4.55011,27548.91797
54.7,4.55845,27552.86328
54.8,4.5667,27556.5957
54.9,4.57513,27559.67969
55,4.58338,27565.51562
55.1,4.59172,27571.63867
55.2,4.60006,27575.66211
55.3,4.6084,27580.93164
55.4,4.61674,27584.7832
55.5,4.62508,27588.54883
55.6,4.63342,27593.85156
55.7,4.64176,27599.25977
55.8,4.65009,27605.37305
55.9,4.65843,27609.55078
56,4.66678,27614.11719
56.1,4.67511,27618.3418
56.2,4.68345,27623.38477
56.3,4.69179,27628.38086
56.4,4.70013,27633.60352
56.5,4.70847,27637.7207
56.6,4.71672,27642.43555
56.7,4.72515,27648.28125
56.8,4.73349,27649.51562
56.9,4.74183,27652.47266
57,4.75008,27656.08789
57.1,4.75842,27659.66992
57.2,4.76685,27663.07617
57.3,4.7751,27666.11328
57.4,4.78344,27671.80469
57.5,4.79178,27674.53711
57.6,4.80012,27677.51758
57.7,4.80846,27683.03711
57.8,4.8168,27688.66797
57.9,4.82514,27693.0957
58,4.83348,27696.68164
58.1,4.84182,27699.48242
58.2,4.85016,27703.26758
58.3,4.8584,27710.19727
58.4,4.86674,27713.74219
58.5,4.87508,27717.18164
58.6,4.88342,27720.06055
58.7,4.89176,27723.2793
58.8,4.9001,27724.99609
58.9,4.90844,27728.97852
59,4.91678,27731.72852
59.1,4.92522,27736.46094
59.2,4.93346,27738.66406
59.3,4.9418,27740.97656
59.4,4.95014,27744.58008
59.5,4.95839,27747.83984
59.6,4.96673,27751.13867
59.7,4.97507,27755.41602
59.8,4.98341,27760.26172
59.9,4.99175,27764.67578
60,5.00009,27767.77148
60.1,5.00843,27771.26953
60.2,5.01677,27774.10352
60.3,5.02502,27777.53125
60.4,5.03345,27782.51758
60.5,5.04179,27785.48828
60.6,5.05022,27788.89258
60.7,5.05856,27794.72266
60.8,5.0669,27793.46484
60.9,5.07515,27792.55859
61,5.08349,27795.13086
61.1,5.09183,27797.85156
61.2,5.10007,27798.27734
61.3,5.10841,27800.24023
61.4,5.11666,27804.625
61.5,5.125,27808.66016
61.6,5.13334,27812.11523
61.7,5.14168,27815.55273
61.8,5.15011,27818.52539
61.9,5.15845,27822.53711
62,5.16679,27825.06055
62.1,5.17523,27827.61719
62.2,5.18347,27830.61523
62.3,5.19181,27834.21875
62.4,5.20015,27838.16211
62.5,5.2084,27840.24414
62.6,5.21674,27842.21094
62.7,5.22508,27844.79883
62.8,5.23342,27845.27148
62.9,5.24176,27845.9043
63,5.2501,27848.23828
63.1,5.25844,27850.97656
63.2,5.26678,27853.33008
63.3,5.27512,27854.99609
63.4,5.28346,27856.16602
63.5,5.2918,27858.49023
63.6,5.30004,27860.45117
63.7,5.30838,27863.4043
63.8,5.31682,27864.95703
63.9,5.32516,27867.56836
64,5.3335,27869.29688
64.1,5.34184,27872.60742
64.2,5.35018,27873.13672
64.3,5.35852,27874.77344
64.4,5.36676,27877
64.5,5.3751,27879.48242
64.6,5.38344,27882.06641
64.7,5.39178,27884.99219
64.8,5.40003,27887.8125
64.9,5.40837,27884.70117
65,5.4168,27886.75195
65.1,5.42505,27887.06055
65.2,5.43348,27887.62109
65.3,5.44182,27889.51367
65.4,5.45007,27890.08984
65.5,5.4585,27891.12891
65.6,5.46675,27892.66016
65.7,5.47509,27894.10352
65.8,5.48343,27895.96094
65.9,5.49167,27898.82031
66,5.5002,27900.03711
66.1,5.50845,27902.45703
66.2,5.51679,27904.16406
66.3,5.52513,27904.57031
66.4,5.53347,27909.67773
66.5,5.54181,27909.36523
66.6,5.55005,27910.58789
66.7,5.55849,27911.81445
66.8,5.56673,27911.03516
66.9,5.57507,27908.87109
67,5.58341,27912.22656
67.1,5.59175,27910.97461
67.2,5.60019,27912.65039
67.3,5.60843,27913.76367
67.4,5.61677,27913.87109
67.5,5.62511,27913.59961
67.6,5.63336,27913.42383
67.7,5.64179,27913.9668
67.8,5.65013,27915.51953
67.9,5.65847,27917.61133
68,5.66681,27919.57031
68.1,5.67515,27919.23828
68.2,5.68349,27920.19922
68.3,5.69183,27920.66016
68.4,5.70008,27921.06641
68.5,5.70851,27924.02734
68.6,5.71676,27923.44922
68.7,5.72519,27924.50391
68.8,5.73344,27927.32422
68.9,5.74178,27924.06445
69,5.75002,27924.44531
69.1,5.75846,27921.54492
69.2,5.7668,27922.02539
69.3,5.77504,27921.63281
69.4,5.78338,27921.96484
69.5,5.79172,27922.27344
69.6,5.80006,27921.75391
69.7,5.8085,27921.25977
69.8,5.81674,27921.38086
69.9,5.82508,27922.4375
70,5.83342,27924.02539
70.1,5.84176,27924.12305
70.2,5.8502,27923.99609
70.3,5.85844,27922.94922
70.4,5.86678,27927.03516
70.5,5.87503,27925.52148
70.6,5.88346,27927.11914
70.7,5.8918,27923.70312
70.8,5.90014,27920.52539
70.9,5.90848,27919.22461
71,5.91673,27919.17578
71.1,5.92516,27916.71094
71.2,5.9335,27918.44531
71.3,5.94175,27916.2793
71.4,5.95009,27916.1875
71.5,5.95833,27914.99805
71.6,5.96677,27914.16992
71.7,5.97511,27913.75
71.8,5.98345,27911.15625
71.9,5.99179,27910.98047
72,6.00013,27911.14844
72.1,6.00847,27910
72.2,6.01671,27909.5293
72.3,6.02515,27908.37305
72.4,6.03349,27907.05469
72.5,6.04183,27906.70898
72.6,6.05017,27906.29297
72.7,6.05851,27904.61719
72.8,6.06684,27904.91602
72.9,6.07518,27901.16406
73,6.08343,27898.44336
73.1,6.09186,27893.23633
73.2,6.10002,27891.37891
73.3,6.10836,27889.25977
73.4,6.11679,27887.17773
73.5,6.12504,27882.88086
73.6,6.13338,27881.0293
73.7,6.14172,27878.98242
73.8,6.15015,27876.13867
73.9,6.15849,27874.83594
74,6.16683,27872.89062
74.1,6.17517,27872.00781
74.2,6.18351,27869.82031
74.3,6.19185,27866.74219
74.4,6.2001,27865.18555
74.5,6.20844,27865.9082
74.6,6.21677,27862.74023
74.7,6.22502,27858.97461
74.8,6.23346,27854.07227
74.9,6.2418,27851.32812
75,6.25013,27847.59961
75.1,6.25848,27843.38672
75.2,6.26672,27839.43945
75.3,6.27515,27837.89648
75.4,6.2834,27833.72656
75.5,6.29174,27829.39062
75.6,6.30008,27824.16602
75.7,6.30842,27820.01172
75.8,6.31685,27814.83008
75.9,6.32519,27811.23828
76,6.33353,27809.08398
76.1,6.34187,27805.4082
76.2,6.35012,27801.56055
76.3,6.35846,27796.76367
76.4,6.36671,27791.50977
76.5,6.37505,27787.19922
76.6,6.38348,27785.30469
76.7,6.39173,27779.09375
76.8,6.40006,27774.42969
76.9,6.4084,27771.67188
77,6.41675,27764.60352
77.1,6.42509,27754.93359
77.2,6.43342,27749.04883
77.3,6.44176,27742.54102
77.4,6.45011,27735.50391
77.5,6.45845,27729.86914
77.6,6.46678,27722.71875
77.7,6.47512,27715.50195
77.8,6.48346,27708.13086
77.9,6.49171,27702.53711
78,6.50014,27698.30859
78.1,6.50848,27692.83594
78.2,6.51682,27685.26758
78.3,6.52516,27677.85742
78.4,6.53341,27671.53125
78.5,6.54184,27668.27344
78.6,6.55009,27660.80273
78.7,6.55843,27651.16602
78.8,6.56677,27639.47266
78.9,6.57511,27630.52344
79,6.58345,27621.29297
79.1,6.59179,27612.06055
79.2,6.60013,27603.98047
79.3,6.60847,27594.99805
79.4,6.61681,27586.8418
79.5,6.62515,27576.7832
79.6,6.63339,27567.24023
79.7,6.64183,27556.56836
79.8,6.65017,27543.60156
79.9,6.65841,27533.09961
80,6.66685,27524.26172
80.1,6.67519,27514.24219
80.2,6.68353,27504.46289
80.3,6.69187,27491.05469
80.4,6.70021,27478.46289
80.5,6.70855,27466.23242
80.6,6.71679,27454.79297
80.7,6.72513,27441.70703
80.8,6.73347,27425.93945
80.9,6.74181,27414.11328
81,6.75006,27399.30078
81.1,6.75849,27381.30078
81.2,6.76683,27365.15625
81.3,6.77508,27349.89844
81.4,6.78351,27333.14844
81.5,6.79176,27317.24023
81.6,6.8001,27300.73633
81.7,6.80844,27283.71094
81.8,6.81678,27267.11328
81.9,6.82512,27248.75586
82,6.83346,27231.36523
82.1,6.8418,27215.64258
82.2,6.85014,27198.04297
82.3,6.85848,27178.5918
82.4,6.86682,27159.53516
82.5,6.87516,27141.40039
82.6,6.8835,27125.42188
82.7,6.89184,27101.79102
82.8,6.90008,27079.86914
82.9,6.90852,27060.38867
83,6.91676,27037.60352
83.1,6.9251,27017.53125
83.2,6.93344,26997.95117
83.3,6.94169,26978.14453
83.4,6.95012,26960.09375
83.5,6.95837,26937.30664
83.6,6.9668,26915.68164
83.7,6.97514,26892.91602
83.8,6.98339,26870.19336
83.9,6.99182,26849.56445
84,7.00016,26827.14258
84.1,7.0085,26805.86523
84.2,7.01684,26785.00195
84.3,7.02518,26761.32617
84.4,7.03352,26739.12109
84.5,7.04186,26716.91211
84.6,7.0502,26693.32617
84.7,7.05854,26672.71484
84.8,7.06679,26647.625
84.9,7.07513,26627.46875
85,7.08337,26602.96875
85.1,7.09171,26577.29688
85.2,7.10005,26553.21094
85.3,7.10839,26529.45312
85.4,7.11673,26505.90234
85.5,7.12507,26481.9375
85.6,7.13341,26458.39062
85.7,7.14185,26433.39258
85.8,7.15019,26408.74023
85.9,7.15853,26385.91016
86,7.16687,26362.53516
86.1,7.17521,26339.02344
86.2,7.18355,26315.01172
86.3,7.19179,26289.90625
86.4,7.20013,26266.28906
86.5,7.20838,26243.12109
86.6,7.21681,26221.81445
86.7,7.22515,26195.18359
86.8,7.23349,26166.91016
86.9,7.24174,26141.41406
87,7.25008,26113.04492
87.1,7.25851,26087.38867
87.2,7.26676,26061.83594
87.3,7.2751,26036.96289
87.4,7.28344,26013.53516
87.5,7.29178,25988.24414
87.6,7.30012,25962.77344
87.7,7.30846,25934.54492
87.8,7.31689,25907.50391
87.9,7.32523,25880.48633
88,7.33348,25854.14648
88.1,7.34191,25829.67969
88.2,7.35016,25802.64453
88.3,7.3585,25774.93164
88.4,7.36674,25748.83789
88.5,7.37508,25721.3125
88.6,7.38352,25693.81055
88.7,7.39176,25668.26367
88.8,7.4001,25636.63477
88.9,7.40844,25609.64844
89,7.41678,25581.05078
89.1,7.42522,25554.29102
89.2,7.43346,25522.4043
89.3,7.4418,25491.83398
89.4,7.45005,25464.85352
89.5,7.45848,25434.94922
89.6,7.46682,25407.34961
89.7,7.47507,25378.21484
89.8,7.4835,25348.16211
89.9,7.49184,25319.66016
90,7.50018,25290.08594
90.1,7.50852,25260.79492
90.2,7.51677,25232.46484
90.3,7.5252,25201.5957
90.4,7.53345,25171.41016
90.5,7.54179,25141.32617
90.6,7.55013,25110.50195
90.7,7.55847,25084.02734
90.8,7.56681,25049.01953
90.9,7.57515,25016.57617
91,7.58349,24982.88867
91.1,7.59183,24949.67578
91.2,7.60017,24917.18164
91.3,7.60851,24885.70703
91.4,7.61675,24853.72656
91.5,7.62509,24821.78906
91.6,7.63343,24788.52734
91.7,7.64177,24754.24219
91.8,7.65011,24720.27148
91.9,7.65845,24685.93164
92,7.66688,24650.67383
92.1,7.67522,24618.49609
92.2,7.68357,24584.70508
92.3,7.69191,24551
92.4,7.70015,24515.24219
92.5,7.70849,24478.62695
92.6,7.71683,24443.29688
92.7,7.72508,24406.29883
92.8,7.73342,24370.54297
92.9,7.74176,24333.41992
93,7.75019,24296.7793
93.1,7.75844,24260.19336
93.2,7.76687,24219.23438
93.3,7.77502,24180.56445
93.4,7.78346,24142.65625
93.5,7.7918,24103.09375
93.6,7.80014,24063.51758
93.7,7.80848,24025.16602
93.8,7.81672,23986.33594
93.9,7.82515,23947.55859
94,7.83349,23909.10742
94.1,7.84184,23869.6582
94.2,7.85017,23829.4375
94.3,7.85851,23789.85742
94.4,7.86685,23746.92188
94.5,7.87519,23704.30078
94.6,7.88344,23660.95117
94.7,7.89187,23621.86719
94.8,7.90012,23575.13867
94.9,7.90855,23529.95117
95,7.91689,23482.83008
95.1,7.92514,23435.9043
95.2,7.93348,23390.55664
95.3,7.94173,23347.30859
95.4,7.95016,23302.39453
95.5,7.9585,23257.4082
95.6,7.96684,23209.99414
95.7,7.97518,23160.28125
95.8,7.98343,23113.91406
95.9,7.99186,23064.45508
96,8.0002,23015.91602
96.1,8.00854,22969.33008
96.2,8.01697,22918.47656
96.3,8.02522,22869.36719
96.4,8.03356,22817.4043
96.5,8.0418,22766.46875
96.6,8.05014,22712.51758
96.7,8.05848,22657.35547
96.8,8.06682,22607.54297
96.9,8.07507,22546.85352
97,8.08332,22490.46484
97.1,8.09175,22434.79492
97.2,8.10009,22372.89648
97.3,8.10843,22308.09375
97.4,8.11677,22239.99609
97.5,8.12511,22134.72852
97.526,8.12811,12396.30176