File: Lab 1/temper 370C 1hr.is_tens_RawData.csv
Specimen properties : Length,"100.00000",mm
Specimen properties : Thickness,"1.00000",mm
Specimen properties : Width,"10.00000",mm
Test : Rate 1,"5.00000",mm/min

Time,Extension,Load
(s),(mm),(N)
"0.00000","0.00000","0.21399"
"0.10000","0.00506","18.94478"
"0.20000","0.01424","32.27101"
"0.30000","0.02361","47.19391"
"0.40000","0.03252","81.27548"
"0.50000","0.04123","123.64262"
"0.60000","0.04976","168.94569"
"0.70000","0.05829","212.36081"
"0.80000","0.06663","261.61935"
"0.90000","0.07506","321.05444"
"1.00000","0.08340","388.66113"
"1.10000","0.09174","464.53848"
"1.20000","0.10008","546.99133"
"1.30000","0.10842","634.77179"
"1.40000","0.11666","726.80060"
"1.50000","0.12500","820.90411"
"1.60000","0.13334","912.46588"
"1.70000","0.14168","1001.83588"
"1.80000","0.15002","1096.66760"
"1.90000","0.15836","1194.22986"
"2.00000","0.16670","1293.47607"
"2.10000","0.17504","1392.40210"
"2.20000","0.18338","1490.73547"
"2.30000","0.19172","1592.30908"
"2.40000","0.20006","1690.63831"
"2.50000","0.20831","1789.45154"
"2.60000","0.21665","1887.60107"
"2.70000","0.22499","1979.92236"
"2.80000","0.23333","2068.20850"
"2.90000","0.24176","2154.86108"
"3.00000","0.25001","2242.94653"
"3.10000","0.25835","2331.34424"
"3.20000","0.26678","2417.91260"
"3.30000","0.27503","2505.71973"
"3.40000","0.28337","2593.21191"
"3.50000","0.29171","2680.33301"
"3.60000","0.30005","2767.38525"
"3.70000","0.30839","2852.71265"
"3.80000","0.31663","2938.77393"
"3.90000","0.32507","3023.84033"
"4.00000","0.33331","3110.17310"
"4.10000","0.34175","3195.93872"
"4.20000","0.35009","3279.97681"
"4.30000","0.35833","3360.44507"
"4.40000","0.36677","3441.65332"
"4.50000","0.37501","3524.69897"
"4.60000","0.38335","3606.51831"
"4.70000","0.39169","3687.92822"
"4.80000","0.40003","3766.08252"
"4.90000","0.40837","3844.67871"
"5.00000","0.41671","3923.77637"
"5.10000","0.42515","4000.96069"
"5.20000","0.43339","4079.59863"
"5.30000","0.44173","4158.04980"
"5.40000","0.45017","4234.90967"
"5.50000","0.45841","4314.70703"
"5.60000","0.46675","4393.56250"
"5.70000","0.47500","4472.26855"
"5.80000","0.48334","4551.53369"
"5.90000","0.49168","4629.90625"
"6.00000","0.50002","4709.83252"
"6.10000","0.50836","4789.07617"
"6.20000","0.51670","4868.09717"
"6.30000","0.52504","4947.41748"
"6.40000","0.53338","5023.96875"
"6.50000","0.54162","5097.81982"
"6.60000","0.54996","5173.44043"
"6.70000","0.55830","5246.64258"
"6.80000","0.56664","5316.74854"
"6.90000","0.57508","5384.24170"
"7.00000","0.58332","5444.50342"
"7.10000","0.59176","5515.33643"
"7.20000","0.60000","5584.15674"
"7.30000","0.60844","5653.23730"
"7.40000","0.61678","5722.56299"
"7.50000","0.62502","5790.91260"
"7.60000","0.63336","5857.14258"
"7.70000","0.64161","5928.17236"
"7.80000","0.65004","5998.52002"
"7.90000","0.65838","6068.08350"
"8.00000","0.66672","6135.86914"
"8.10000","0.67506","6204.82227"
"8.20000","0.68331","6275.52637"
"8.30000","0.69174","6346.79736"
"8.40000","0.70008","6416.67236"
"8.50000","0.70833","6486.50830"
"8.60000","0.71667","6555.09814"
"8.70000","0.72491","6625.76465"
"8.80000","0.73335","6697.42969"
"8.90000","0.74169","6769.41504"
"9.00000","0.75012","6841.38623"
"9.10000","0.75846","6909.91357"
"9.20000","0.76680","6980.19727"
"9.30000","0.77514","7050.96191"
"9.40000","0.78348","7122.05615"
"9.50000","0.79173","7193.44775"
"9.60000","0.80007","7262.96387"
"9.70000","0.80831","7333.93408"
"9.80000","0.81665","7404.08594"
"9.90000","0.82499","7476.45703"
"10.00000","0.83333","7550.04346"
"10.10000","0.84177","7622.63770"
"10.20000","0.85011","7694.04248"
"10.30000","0.85845","7767.52832"
"10.40000","0.86679","7840.61719"
"10.50000","0.87513","7913.45459"
"10.60000","0.88337","7985.91504"
"10.70000","0.89171","8059.97852"
"10.80000","0.90015","8134.73096"
"10.90000","0.90839","8209.03223"
"11.00000","0.91673","8282.80176"
"11.10000","0.92507","8356.74902"
"11.20000","0.93341","8430.75000"
"11.30000","0.94175","8503.97949"
"11.40000","0.95009","8578.14062"
"11.50000","0.95843","8651.86914"
"11.60000","0.96677","8726.67676"
"11.70000","0.97502","8800.41211"
"11.80000","0.98336","8874.99219"
"11.90000","0.99160","8950.71387"
"12.00000","1.00004","9025.76562"
"12.10000","1.00828","9101.75586"
"12.20000","1.01662","9177.59863"
"12.30000","1.02515","9253.66602"
"12.40000","1.03340","9329.63770"
"12.50000","1.04174","9404.95312"
"12.60000","1.04998","9481.29102"
"12.70000","1.05832","9556.08887"
"12.80000","1.06676","9631.49023"
"12.90000","1.07500","9708.78809"
"13.00000","1.08334","9786.09766"
"13.10000","1.09168","9862.51562"
"13.20000","1.10002","9939.69336"
"13.30000","1.10836","10016.22852"
"13.40000","1.11661","10093.41699"
"13.50000","1.12504","10170.30957"
"13.60000","1.13338","10248.15332"
"13.70000","1.14163","10323.65137"
"13.80000","1.15006","10400.93945"
"13.90000","1.15840","10478.93848"
"14.00000","1.16665","10557.49609"
"14.10000","1.17508","10637.25977"
"14.20000","1.18333","10717.05566"
"14.30000","1.19176","10792.79297"
"14.40000","1.20001","10871.25684"
"14.50000","1.20835","10951.13867"
"14.60000","1.21669","11030.91992"
"14.70000","1.22503","11111.43555"
"14.80000","1.23337","11190.76270"
"14.90000","1.24171","11269.19727"
"15.00000","1.25005","11349.13867"
"15.10000","1.25839","11429.11914"
"15.20000","1.26673","11510.05664"
"15.30000","1.27507","11589.98340"
"15.40000","1.28331","11668.26367"
"15.50000","1.29165","11749.14062"
"15.60000","1.29999","11830.00000"
"15.70000","1.30833","11910.87891"
"15.80000","1.31667","11990.45898"
"15.90000","1.32501","12070.33398"
"16.00000","1.33335","12151.18066"
"16.10000","1.34169","12232.40234"
"16.20000","1.35003","12313.48340"
"16.30000","1.35837","12394.62402"
"16.40000","1.36671","12474.61816"
"16.50000","1.37505","12553.66211"
"16.60000","1.38330","12636.01465"
"16.70000","1.39164","12717.29883"
"16.80000","1.40007","12801.14648"
"16.90000","1.40832","12883.20312"
"17.00000","1.41675","12962.51465"
"17.10000","1.42500","13044.72656"
"17.20000","1.43334","13125.49902"
"17.30000","1.44177","13208.07812"
"17.40000","1.45002","13289.00195"
"17.50000","1.45836","13369.12793"
"17.60000","1.46660","13447.53906"
"17.70000","1.47504","13529.92383"
"17.80000","1.48328","13612.56250"
"17.90000","1.49171","13693.85547"
"18.00000","1.50005","13774.52148"
"18.10000","1.50830","13854.12109"
"18.20000","1.51673","13935.60742"
"18.30000","1.52507","14017.78418"
"18.40000","1.53332","14099.82422"
"18.50000","1.54166","14181.21289"
"18.60000","1.54991","14262.49023"
"18.70000","1.55834","14344.07715"
"18.80000","1.56668","14428.58105"
"18.90000","1.57502","14511.55566"
"19.00000","1.58345","14593.86035"
"19.10000","1.59170","14674.37891"
"19.20000","1.60013","14754.51855"
"19.30000","1.60838","14837.73438"
"19.40000","1.61672","14918.92773"
"19.50000","1.62506","15001.76758"
"19.60000","1.63331","15083.00488"
"19.70000","1.64165","15162.77051"
"19.80000","1.64999","15245.15137"
"19.90000","1.65833","15325.34180"
"20.00000","1.66676","15407.75195"
"20.10000","1.67510","15488.43848"
"20.20000","1.68353","15568.06250"
"20.30000","1.69178","15650.74512"
"20.40000","1.70012","15731.40332"
"20.50000","1.70846","15813.41602"
"20.60000","1.71670","15893.07812"
"20.70000","1.72504","15973.13477"
"20.80000","1.73338","16056.11133"
"20.90000","1.74182","16138.42090"
"21.00000","1.75016","16220.22363"
"21.10000","1.75850","16301.05566"
"21.20000","1.76693","16381.40039"
"21.30000","1.77518","16462.83594"
"21.40000","1.78342","16542.89453"
"21.50000","1.79176","16624.59766"
"21.60000","1.80001","16705.86328"
"21.70000","1.80835","16785.45508"
"21.80000","1.81660","16866.69922"
"21.90000","1.82503","16947.50195"
"22.00000","1.83337","17028.94531"
"22.10000","1.84171","17112.16406"
"22.20000","1.85014","17192.31250"
"22.30000","1.85839","17272.70898"
"22.40000","1.86673","17353.80664"
"22.50000","1.87507","17435.33984"
"22.60000","1.88331","17517.03906"
"22.70000","1.89175","17597.89062"
"22.80000","1.89999","17677.64062"
"22.90000","1.90843","17757.96484"
"23.00000","1.91667","17839.06836"
"23.10000","1.92511","17919.02734"
"23.20000","1.93345","17999.69141"
"23.30000","1.94179","18078.57227"
"23.40000","1.95013","18157.90625"
"23.50000","1.95828","18238.08008"
"23.60000","1.96662","18317.26562"
"23.70000","1.97496","18397.02930"
"23.80000","1.98330","18473.69922"
"23.90000","1.99164","18550.78320"
"24.00000","1.99998","18630.08398"
"24.10000","2.00841","18708.44531"
"24.20000","2.01675","18784.23633"
"24.30000","2.02509","18859.59961"
"24.40000","2.03343","18934.12695"
"24.50000","2.04168","19009.61719"
"24.60000","2.05002","19083.61328"
"24.70000","2.05836","19157.73047"
"24.80000","2.06670","19230.60156"
"24.90000","2.07504","19301.80859"
"25.00000","2.08328","19374.62109"
"25.10000","2.09172","19444.52930"
"25.20000","2.10006","19515.84180"
"25.30000","2.10840","19585.68750"
"25.40000","2.11674","19651.92969"
"25.50000","2.12498","19720.82812"
"25.60000","2.13332","19788.04688"
"25.70000","2.14166","19855.68164"
"25.80000","2.15000","19921.04688"
"25.90000","2.15834","19985.99219"
"26.00000","2.16668","20049.99414"
"26.10000","2.17502","20111.42578"
"26.20000","2.18336","20171.89453"
"26.30000","2.19170","20232.89258"
"26.40000","2.20004","20291.90430"
"26.50000","2.20829","20351.14844"
"26.60000","2.21672","20405.87109"
"26.70000","2.22506","20465.17773"
"26.80000","2.23340","20523.01172"
"26.90000","2.24174","20581.40820"
"27.00000","2.24999","20641.95703"
"27.10000","2.25842","20698.55859"
"27.20000","2.26667","20761.03320"
"27.30000","2.27501","20821.11719"
"27.40000","2.28335","20883.17188"
"27.50000","2.29169","20945.24805"
"27.60000","2.30003","21005.06641"
"27.70000","2.30837","21069.11328"
"27.80000","2.31671","21130.02148"
"27.90000","2.32505","21192.88086"
"28.00000","2.33339","21256.48047"
"28.10000","2.34173","21317.62500"
"28.20000","2.35007","21381.02148"
"28.30000","2.35841","21442.01953"
"28.40000","2.36665","21506.72656"
"28.50000","2.37499","21569.44531"
"28.60000","2.38333","21632.86133"
"28.70000","2.39167","21696.06250"
"28.80000","2.40001","21759.93164"
"28.90000","2.40835","21823.64453"
"29.00000","2.41669","21888.92773"
"29.10000","2.42503","21952.12305"
"29.20000","2.43337","22015.22656"
"29.30000","2.44171","22077.34961"
"29.40000","2.44996","22140.58398"
"29.50000","2.45839","22204.00781"
"29.60000","2.46673","22268.20117"
"29.70000","2.47507","22331.40234"
"29.80000","2.48351","22394.10742"
"29.90000","2.49175","22458.37891"
"30.00000","2.50009","22519.98828"
"30.10000","2.50843","22580.93750"
"30.20000","2.51677","22643.06055"
"30.30000","2.52511","22704.55078"
"30.40000","2.53336","22766.63086"
"30.50000","2.54170","22826.60156"
"30.60000","2.55004","22888.01562"
"30.70000","2.55838","22948.95898"
"30.80000","2.56672","23008.55469"
"30.90000","2.57506","23068.29297"
"31.00000","2.58340","23128.39648"
"31.10000","2.59174","23187.46680"
"31.20000","2.60008","23245.20703"
"31.30000","2.60842","23302.83594"
"31.40000","2.61666","23360.41602"
"31.50000","2.62500","23417.81445"
"31.60000","2.63334","23475.49805"
"31.70000","2.64168","23532.15234"
"31.80000","2.65002","23586.64258"
"31.90000","2.65836","23641.68555"
"32.00000","2.66670","23698.14258"
"32.10000","2.67504","23753.93750"
"32.20000","2.68338","23805.29883"
"32.30000","2.69172","23858.34961"
"32.40000","2.69997","23911.62891"
"32.50000","2.70831","23964.27930"
"32.60000","2.71665","24017.63867"
"32.70000","2.72508","24071.74219"
"32.80000","2.73342","24122.02344"
"32.90000","2.74185","24172.16992"
"33.00000","2.75019","24223.07227"
"33.10000","2.75844","24273.70312"
"33.20000","2.76687","24322.93164"
"33.30000","2.77512","24371.25977"
"33.40000","2.78337","24419.04492"
"33.50000","2.79171","24467.77930"
"33.60000","2.79986","24516.54492"
"33.70000","2.80829","24566.34570"
"33.80000","2.81663","24613.62695"
"33.90000","2.82497","24658.88867"
"34.00000","2.83341","24708.08594"
"34.10000","2.84165","24753.30273"
"34.20000","2.85009","24801.25195"
"34.30000","2.85843","24846.88086"
"34.40000","2.86677","24890.79883"
"34.50000","2.87511","24935.97656"
"34.60000","2.88326","24979.73242"
"34.70000","2.89169","25024.64062"
"34.80000","2.90003","25068.23828"
"34.90000","2.90837","25109.67578"
"35.00000","2.91671","25153.87891"
"35.10000","2.92505","25196.37891"
"35.20000","2.93348","25239.38086"
"35.30000","2.94173","25282.08398"
"35.40000","2.95007","25322.87891"
"35.50000","2.95832","25364.83398"
"35.60000","2.96666","25406.44922"
"35.70000","2.97500","25447.77344"
"35.80000","2.98334","25489.41602"
"35.90000","2.99168","25528.79492"
"36.00000","3.00002","25570.35352"
"36.10000","3.00836","25608.34570"
"36.20000","3.01679","25649.21289"
"36.30000","3.02504","25688.09180"
"36.40000","3.03338","25726.47070"
"36.50000","3.04172","25764.36914"
"36.60000","3.05006","25802.35352"
"36.70000","3.05840","25840.83984"
"36.80000","3.06674","25877.03125"
"36.90000","3.07508","25913.58398"
"37.00000","3.08341","25950.59961"
"37.10000","3.09175","25986.81445"
"37.20000","3.10009","26023.38281"
"37.30000","3.10834","26058.65039"
"37.40000","3.11677","26095.26562"
"37.50000","3.12502","26131.17188"
"37.60000","3.13336","26165.84570"
"37.70000","3.14170","26201.22461"
"37.80000","3.15004","26234.65039"
"37.90000","3.15838","26267.93359"
"38.00000","3.16663","26303.84766"
"38.10000","3.17506","26334.72070"
"38.20000","3.18340","26369.69727"
"38.30000","3.19174","26402.86719"
"38.40000","3.20008","26436.52539"
"38.50000","3.20833","26469.51758"
"38.60000","3.21676","26500.74609"
"38.70000","3.22501","26533.46289"
"38.80000","3.23335","26564.18359"
"38.90000","3.24178","26594.50195"
"39.00000","3.25003","26626.76562"
"39.10000","3.25846","26656.69336"
"39.20000","3.26671","26687.79102"
"39.30000","3.27504","26716.70312"
"39.40000","3.28338","26747.04883"
"39.50000","3.29172","26777.96484"
"39.60000","3.30006","26807.73438"
"39.70000","3.30840","26836.51172"
"39.80000","3.31674","26864.78516"
"39.90000","3.32499","26892.87891"
"40.00000","3.33333","26922.17188"
"40.10000","3.34176","26948.97070"
"40.20000","3.35001","26977.92578"
"40.30000","3.35835","27005.15625"
"40.40000","3.36669","27033.40430"
"40.50000","3.37503","27061.51953"
"40.60000","3.38337","27088.34180"
"40.70000","3.39171","27114.77930"
"40.80000","3.40005","27139.99805"
"40.90000","3.40839","27167.69922"
"41.00000","3.41682","27191.83789"
"41.10000","3.42516","27218.45117"
"41.20000","3.43341","27243.56641"
"41.30000","3.44175","27266.31250"
"41.40000","3.45009","27292.12695"
"41.50000","3.45833","27316.08984"
"41.60000","3.46677","27341.31445"
"41.70000","3.47501","27364.78125"
"41.80000","3.48345","27387.20117"
"41.90000","3.49169","27411.89844"
"42.00000","3.50003","27435.49609"
"42.10000","3.50847","27458.67969"
"42.20000","3.51671","27481.02344"
"42.30000","3.52505","27503.25586"
"42.40000","3.53330","27526.57617"
"42.50000","3.54164","27549.82422"
"42.60000","3.55007","27572.99219"
"42.70000","3.55832","27594.06250"
"42.80000","3.56675","27615.35352"
"42.90000","3.57509","27637.28125"
"43.00000","3.58343","27656.96875"
"43.10000","3.59177","27680.03125"
"43.20000","3.60011","27700.54102"
"43.30000","3.60845","27721.08398"
"43.40000","3.61670","27742.21875"
"43.50000","3.62504","27762.62500"
"43.60000","3.63338","27783.45312"
"43.70000","3.64172","27802.66016"
"43.80000","3.65006","27822.01758"
"43.90000","3.65840","27841.38281"
"44.00000","3.66674","27862.25000"
"44.10000","3.67498","27881.39648"
"44.20000","3.68342","27899.89453"
"44.30000","3.69166","27920.64844"
"44.40000","3.70000","27938.12695"
"44.50000","3.70834","27957.15039"
"44.60000","3.71668","27977.90430"
"44.70000","3.72512","27994.41797"
"44.80000","3.73355","28013.23828"
"44.90000","3.74180","28028.34570"
"45.00000","3.75023","28045.46680"
"45.10000","3.75848","28062.87109"
"45.20000","3.76682","28078.44922"
"45.30000","3.77506","28096.25781"
"45.40000","3.78331","28112.25000"
"45.50000","3.79174","28129.28906"
"45.60000","3.79999","28147.66797"
"45.70000","3.80833","28164.08008"
"45.80000","3.81667","28180.41406"
"45.90000","3.82501","28197.04492"
"46.00000","3.83344","28213.87695"
"46.10000","3.84178","28229.21289"
"46.20000","3.85003","28244.71680"
"46.30000","3.85837","28261.16406"
"46.40000","3.86671","28276.76758"
"46.50000","3.87505","28291.83398"
"46.60000","3.88329","28307.15234"
"46.70000","3.89173","28322.71680"
"46.80000","3.90007","28338.54297"
"46.90000","3.90841","28353.21094"
"47.00000","3.91684","28367.06641"
"47.10000","3.92509","28381.61523"
"47.20000","3.93343","28395.27344"
"47.30000","3.94177","28408.37891"
"47.40000","3.95011","28421.69727"
"47.50000","3.95845","28436.55859"
"47.60000","3.96669","28450.64648"
"47.70000","3.97503","28463.48242"
"47.80000","3.98328","28476.81641"
"47.90000","3.99171","28491.81641"
"48.00000","4.00005","28505.53711"
"48.10000","4.00839","28516.50977"
"48.20000","4.01683","28529.99023"
"48.30000","4.02507","28543.75000"
"48.40000","4.03341","28556.28711"
"48.50000","4.04175","28569.71680"
"48.60000","4.05000","28582.66016"
"48.70000","4.05843","28593.84961"
"48.80000","4.06668","28606.48047"
"48.90000","4.07511","28617.81055"
"49.00000","4.08336","28631.14258"
"49.10000","4.09179","28642.49414"
"49.20000","4.10013","28653.83008"
"49.30000","4.10838","28665.24414"
"49.40000","4.11672","28675.36523"
"49.50000","4.12506","28688.58008"
"49.60000","4.13340","28699.27930"
"49.70000","4.14174","28710.59766"
"49.80000","4.14998","28720.53711"
"49.90000","4.15832","28732.78516"
"50.00000","4.16666","28744.34375"
"50.10000","4.17510","28753.58789"
"50.20000","4.18344","28765.47070"
"50.30000","4.19168","28776.03125"
"50.40000","4.20002","28787.50586"
"50.50000","4.20836","28798.23828"
"50.60000","4.21670","28809.36328"
"50.70000","4.22504","28819.54688"
"50.80000","4.23338","28828.71289"
"50.90000","4.24172","28839.21484"
"51.00000","4.25006","28849.86914"
"51.10000","4.25840","28860.10352"
"51.20000","4.26684","28869.89062"
"51.30000","4.27508","28877.81055"
"51.40000","4.28342","28887.95117"
"51.50000","4.29176","28897.27344"
"51.60000","4.30010","28906.54492"
"51.70000","4.30844","28914.80273"
"51.80000","4.31678","28921.97656"
"51.90000","4.32512","28934.19531"
"52.00000","4.33337","28941.49219"
"52.10000","4.34180","28951.13281"
"52.20000","4.35005","28961.08398"
"52.30000","4.35839","28968.84766"
"52.40000","4.36673","28979.25586"
"52.50000","4.37507","28987.37695"
"52.60000","4.38341","28996.54883"
"52.70000","4.39175","29005.49219"
"52.80000","4.40009","29012.73633"
"52.90000","4.40843","29021.59766"
"53.00000","4.41677","29028.81445"
"53.10000","4.42511","29037.27344"
"53.20000","4.43335","29045.10156"
"53.30000","4.44179","29051.58008"
"53.40000","4.45013","29059.57031"
"53.50000","4.45847","29067.91602"
"53.60000","4.46680","29075.02734"
"53.70000","4.47505","29081.85352"
"53.80000","4.48348","29088.58008"
"53.90000","4.49182","29098.20312"
"54.00000","4.50007","29103.16211"
"54.10000","4.50850","29111.82422"
"54.20000","4.51666","29119.82031"
"54.30000","4.52509","29126.68945"
"54.40000","4.53334","29135.17578"
"54.50000","4.54177","29141.74414"
"54.60000","4.55002","29149.98828"
"54.70000","4.55836","29156.44141"
"54.80000","4.56679","29162.70117"
"54.90000","4.57513","29171.71094"
"55.00000","4.58347","29176.81836"
"55.10000","4.59181","29184.04102"
"55.20000","4.60006","29189.33008"
"55.30000","4.60849","29195.65430"
"55.40000","4.61674","29202.86719"
"55.50000","4.62508","29209.15430"
"55.60000","4.63342","29216.02148"
"55.70000","4.64166","29221.06055"
"55.80000","4.65009","29227.72461"
"55.90000","4.65834","29235.57422"
"56.00000","4.66678","29238.43359"
"56.10000","4.67511","29245.04492"
"56.20000","4.68336","29250.30859"
"56.30000","4.69170","29255.87891"
"56.40000","4.70004","29263.63281"
"56.50000","4.70847","29269.32227"
"56.60000","4.71681","29274.83594"
"56.70000","4.72515","29279.86328"
"56.80000","4.73349","29285.92188"
"56.90000","4.74183","29292.22266"
"57.00000","4.75017","29297.14844"
"57.10000","4.75842","29302.52539"
"57.20000","4.76676","29305.09180"
"57.30000","4.77510","29311.11523"
"57.40000","4.78335","29316.95312"
"57.50000","4.79169","29322.58203"
"57.60000","4.80003","29328.15039"
"57.70000","4.80837","29330.17578"
"57.80000","4.81671","29336.52930"
"57.90000","4.82505","29341.94141"
"58.00000","4.83348","29345.74414"
"58.10000","4.84172","29351.30078"
"58.20000","4.85016","29355.69922"
"58.30000","4.85840","29360.92383"
"58.40000","4.86665","29365.67969"
"58.50000","4.87508","29370.43555"
"58.60000","4.88333","29376.50977"
"58.70000","4.89176","29379.93750"
"58.80000","4.90010","29385.68945"
"58.90000","4.90835","29389.19727"
"59.00000","4.91678","29394.66602"
"59.10000","4.92512","29399.96094"
"59.20000","4.93346","29402.75391"
"59.30000","4.94180","29407.23828"
"59.40000","4.95005","29411.14844"
"59.50000","4.95839","29415.27734"
"59.60000","4.96673","29418.85547"
"59.70000","4.97507","29421.84180"
"59.80000","4.98341","29425.53711"
"59.90000","4.99175","29429.31445"
"60.00000","5.00018","29431.64062"
"60.10000","5.00843","29435.31836"
"60.20000","5.01686","29439.86328"
"60.30000","5.02511","29443.36328"
"60.40000","5.03345","29446.29102"
"60.50000","5.04179","29450.91797"
"60.60000","5.05003","29453.53125"
"60.70000","5.05847","29457.44336"
"60.80000","5.06671","29460.94531"
"60.90000","5.07515","29463.62109"
"61.00000","5.08339","29468.41211"
"61.10000","5.09173","29471.82617"
"61.20000","5.10017","29475.36719"
"61.30000","5.10841","29477.98438"
"61.40000","5.11675","29479.76562"
"61.50000","5.12500","29484.08203"
"61.60000","5.13343","29486.23828"
"61.70000","5.14177","29488.38867"
"61.80000","5.15002","29491.75195"
"61.90000","5.15845","29493.91016"
"62.00000","5.16670","29496.47070"
"62.10000","5.17504","29497.60352"
"62.20000","5.18338","29501.94727"
"62.30000","5.19172","29504.90625"
"62.40000","5.20006","29507.50195"
"62.50000","5.20840","29510.16406"
"62.60000","5.21665","29513.02734"
"62.70000","5.22508","29516.94336"
"62.80000","5.23333","29518.81836"
"62.90000","5.24176","29520.74023"
"63.00000","5.25010","29524.31836"
"63.10000","5.25844","29525.97656"
"63.20000","5.26678","29528.26367"
"63.30000","5.27502","29530.15234"
"63.40000","5.28346","29532.05078"
"63.50000","5.29170","29534.17969"
"63.60000","5.30004","29535.98438"
"63.70000","5.30838","29537.71094"
"63.80000","5.31672","29540.83984"
"63.90000","5.32506","29543.52148"
"64.00000","5.33340","29543.60156"
"64.10000","5.34174","29544.92773"
"64.20000","5.35008","29547.56055"
"64.30000","5.35842","29548.73242"
"64.40000","5.36676","29551.68555"
"64.50000","5.37510","29553.54102"
"64.60000","5.38354","29554.58984"
"64.70000","5.39178","29556.75781"
"64.80000","5.40012","29556.61133"
"64.90000","5.40846","29558.94141"
"65.00000","5.41680","29559.80078"
"65.10000","5.42514","29559.20312"
"65.20000","5.43339","29560.34570"
"65.30000","5.44173","29561.57422"
"65.40000","5.45007","29564.57422"
"65.50000","5.45841","29565.96680"
"65.60000","5.46675","29565.76562"
"65.70000","5.47499","29566.83398"
"65.80000","5.48343","29569.39648"
"65.90000","5.49177","29570.34766"
"66.00000","5.50011","29569.83984"
"66.10000","5.50845","29569.89648"
"66.20000","5.51669","29571.06836"
"66.30000","5.52503","29571.61133"
"66.40000","5.53337","29572.63281"
"66.50000","5.54171","29573.71094"
"66.60000","5.55015","29573.42773"
"66.70000","5.55839","29573.20117"
"66.80000","5.56683","29573.45312"
"66.90000","5.57507","29573.69727"
"67.00000","5.58341","29574.54297"
"67.10000","5.59175","29575.20508"
"67.20000","5.60009","29574.16211"
"67.30000","5.60843","29574.32031"
"67.40000","5.61668","29575.89062"
"67.50000","5.62502","29575.43945"
"67.60000","5.63345","29575.94727"
"67.70000","5.64170","29573.17578"
"67.80000","5.65004","29574.62109"
"67.90000","5.65838","29573.79883"
"68.00000","5.66672","29571.94141"
"68.10000","5.67506","29572.76758"
"68.20000","5.68330","29570.86328"
"68.30000","5.69174","29571.73633"
"68.40000","5.70008","29569.86133"
"68.50000","5.70851","29569.00000"
"68.60000","5.71685","29568.02930"
"68.70000","5.72519","29564.87305"
"68.80000","5.73353","29562.72070"
"68.90000","5.74178","29559.83789"
"69.00000","5.75012","29557.59375"
"69.10000","5.75846","29556.30469"
"69.20000","5.76670","29553.35938"
"69.30000","5.77504","29552.09961"
"69.40000","5.78329","29551.04688"
"69.50000","5.79172","29549.33008"
"69.60000","5.80006","29546.54688"
"69.70000","5.80840","29542.30859"
"69.80000","5.81674","29541.49805"
"69.90000","5.82508","29535.98438"
"70.00000","5.83352","29533.51172"
"70.10000","5.84176","29531.01758"
"70.20000","5.85010","29527.12695"
"70.30000","5.85844","29523.13477"
"70.40000","5.86669","29518.57812"
"70.50000","5.87512","29514.40430"
"70.60000","5.88337","29509.47656"
"70.70000","5.89171","29504.28125"
"70.80000","5.90014","29500.64844"
"70.90000","5.90839","29493.94531"
"71.00000","5.91682","29488.08008"
"71.10000","5.92507","29481.60156"
"71.20000","5.93341","29475.05469"
"71.30000","5.94175","29469.24609"
"71.40000","5.94999","29462.20703"
"71.50000","5.95843","29455.50586"
"71.60000","5.96667","29447.76172"
"71.70000","5.97501","29439.07617"
"71.80000","5.98335","29433.32227"
"71.90000","5.99179","29422.39062"
"72.00000","6.00013","29414.16211"
"72.10000","6.00837","29405.24219"
"72.20000","6.01671","29394.70703"
"72.30000","6.02505","29385.58398"
"72.40000","6.03339","29373.28125"
"72.50000","6.04173","29361.57031"
"72.60000","6.05007","29350.49219"
"72.70000","6.05841","29338.23438"
"72.80000","6.06675","29327.31836"
"72.90000","6.07518","29313.83789"
"73.00000","6.08352","29301.31250"
"73.10000","6.09177","29286.60742"
"73.20000","6.10011","29272.50781"
"73.30000","6.10845","29260.06836"
"73.40000","6.11679","29244.87891"
"73.50000","6.12513","29230.72070"
"73.60000","6.13338","29215.13086"
"73.70000","6.14172","29199.45703"
"73.80000","6.15006","29185.60742"
"73.90000","6.15840","29168.23633"
"74.00000","6.16683","29153.79492"
"74.10000","6.17508","29136.42578"
"74.20000","6.18342","29119.73828"
"74.30000","6.19166","29102.71289"
"74.40000","6.20010","29084.97461"
"74.50000","6.20834","29067.43359"
"74.60000","6.21677","29048.58203"
"74.70000","6.22512","29030.89844"
"74.80000","6.23336","29013.07617"
"74.90000","6.24180","28993.76367"
"75.00000","6.25013","28975.71680"
"75.10000","6.25848","28953.79102"
"75.20000","6.26681","28934.97656"
"75.30000","6.27506","28915.87891"
"75.40000","6.28340","28895.23828"
"75.50000","6.29174","28875.91406"
"75.60000","6.30008","28853.35352"
"75.70000","6.30842","28833.44531"
"75.80000","6.31676","28813.54297"
"75.90000","6.32510","28791.35352"
"76.00000","6.33344","28771.20312"
"76.10000","6.34178","28748.58008"
"76.20000","6.35012","28726.25977"
"76.30000","6.35846","28704.19336"
"76.40000","6.36680","28681.18945"
"76.50000","6.37505","28659.53711"
"76.60000","6.38348","28635.46094"
"76.70000","6.39182","28612.65625"
"76.80000","6.40016","28587.17188"
"76.90000","6.40850","28564.05469"
"77.00000","6.41675","28541.87109"
"77.10000","6.42509","28516.44727"
"77.20000","6.43342","28493.18945"
"77.30000","6.44176","28468.71094"
"77.40000","6.45011","28445.80664"
"77.50000","6.45845","28420.18945"
"77.60000","6.46678","28394.27539"
"77.70000","6.47512","28369.01758"
"77.80000","6.48346","28343.02148"
"77.90000","6.49180","28318.22852"
"78.00000","6.50005","28290.96289"
"78.10000","6.50839","28265.27344"
"78.20000","6.51673","28239.69336"
"78.30000","6.52507","28212.59180"
"78.40000","6.53341","28186.30078"
"78.50000","6.54175","28159.46875"
"78.60000","6.55009","28132.00000"
"78.70000","6.55843","28104.24609"
"78.80000","6.56686","28074.59766"
"78.90000","6.57511","28047.00195"
"79.00000","6.58345","28018.81055"
"79.10000","6.59179","27989.02930"
"79.20000","6.60003","27961.43555"
"79.30000","6.60847","27931.49414"
"79.40000","6.61671","27902.09375"
"79.50000","6.62505","27871.80859"
"79.60000","6.63339","27841.65430"
"79.70000","6.64174","27811.95312"
"79.80000","6.65007","27780.79297"
"79.90000","6.65841","27748.25391"
"80.00000","6.66675","27715.57227"
"80.10000","6.67509","27685.16016"
"80.20000","6.68343","27654.79297"
"80.30000","6.69177","27621.79102"
"80.40000","6.70011","27588.26562"
"80.50000","6.70855","27552.95117"
"80.60000","6.71689","27519.29492"
"80.70000","6.72513","27485.30469"
"80.80000","6.73357","27450.04297"
"80.90000","6.74181","27415.06445"
"81.00000","6.75015","27377.73633"
"81.10000","6.75840","27340.92383"
"81.20000","6.76674","27304.52734"
"81.30000","6.77508","27267.79297"
"81.40000","6.78342","27230.47461"
"81.50000","6.79176","27189.52930"
"81.60000","6.80010","27150.54102"
"81.70000","6.80844","27109.73242"
"81.80000","6.81687","27065.35742"
"81.90000","6.82512","27006.25000"
"81.97800","6.83065","15094.23145"