File: temper 677C 1hr.is_tens_RawData.csv
Specimen properties : Length,"100.00000",mm
Specimen properties : Thickness,"1.00000",mm
Specimen properties : Width,"10.00000",mm
Test : Rate 1,"5.00000",mm/min

Time,Extension,Load
(s),(mm),(N)
"0.00000","0.00000","0.97989"
"0.15000","0.00937","19.04306"
"0.30000","0.02343","31.60546"
"0.45000","0.03683","46.79193"
"0.60000","0.04976","80.16709"
"0.75000","0.06241","169.78302"
"0.90000","0.07506","283.15100"
"1.05000","0.08752","422.70892"
"1.20000","0.09998","570.33881"
"1.35000","0.11245","719.32959"
"1.50000","0.12500","868.89398"
"1.65000","0.13756","1014.29767"
"1.80000","0.15012","1152.96338"
"1.95000","0.16267","1283.72522"
"2.10000","0.17514","1404.12878"
"2.25000","0.18760","1525.63379"
"2.40000","0.20006","1644.28931"
"2.55000","0.21253","1766.48572"
"2.70000","0.22499","1891.13342"
"2.85000","0.23755","2014.76611"
"3.00000","0.25010","2137.96558"
"3.15000","0.26257","2264.60889"
"3.30000","0.27503","2391.68799"
"3.45000","0.28749","2514.39600"
"3.60000","0.29995","2641.06738"
"3.75000","0.31251","2768.10181"
"3.90000","0.32507","2892.94409"
"4.05000","0.33753","3015.03882"
"4.20000","0.34999","3141.15356"
"4.35000","0.36255","3266.25220"
"4.50000","0.37511","3389.93604"
"4.65000","0.38757","3516.42358"
"4.80000","0.40003","3643.51318"
"4.95000","0.41250","3769.27148"
"5.10000","0.42505","3894.10254"
"5.25000","0.43752","4016.75879"
"5.40000","0.45007","4140.80615"
"5.55000","0.46254","4259.45850"
"5.70000","0.47500","4384.76709"
"5.85000","0.48756","4504.75537"
"6.00000","0.50002","4625.84033"
"6.15000","0.51248","4742.27930"
"6.30000","0.52494","4859.69873"
"6.45000","0.53750","4974.43994"
"6.60000","0.55006","5093.88965"
"6.75000","0.56261","5213.80420"
"6.90000","0.57508","5331.86084"
"7.05000","0.58754","5446.60303"
"7.20000","0.60000","5562.73682"
"7.35000","0.61247","5678.78857"
"7.50000","0.62502","5793.85010"
"7.65000","0.63749","5906.79297"
"7.80000","0.65004","6022.17236"
"7.95000","0.66251","6130.16992"
"8.10000","0.67497","6230.50000"
"8.25000","0.68753","6327.16406"
"8.40000","0.70008","6426.82373"
"8.55000","0.71254","6526.32715"
"8.70000","0.72510","6625.76123"
"8.85000","0.73756","6728.97314"
"9.00000","0.75003","6831.36816"
"9.15000","0.76249","6934.47900"
"9.30000","0.77505","7034.65723"
"9.45000","0.78751","7137.16357"
"9.60000","0.80007","7240.24463"
"9.75000","0.81253","7338.17090"
"9.90000","0.82509","7433.52979"
"10.05000","0.83755","7540.91016"
"10.20000","0.85001","7644.68848"
"10.35000","0.86248","7748.11963"
"10.50000","0.87503","7854.93701"
"10.65000","0.88749","7961.01074"
"10.80000","0.90005","8065.07715"
"10.95000","0.91261","8173.28320"
"11.10000","0.92507","8279.70605"
"11.25000","0.93753","8386.71875"
"11.40000","0.95000","8494.02637"
"11.55000","0.96246","8601.46094"
"11.70000","0.97502","8713.17090"
"11.85000","0.98748","8820.02441"
"12.00000","0.99994","8929.41992"
"12.15000","1.01250","9039.44336"
"12.30000","1.02496","9148.07520"
"12.45000","1.03752","9257.87305"
"12.60000","1.05008","9368.97656"
"12.75000","1.06263","9480.43848"
"12.90000","1.07510","9589.92969"
"13.05000","1.08756","9701.30469"
"13.20000","1.10002","9815.29980"
"13.35000","1.11248","9927.07812"
"13.50000","1.12504","10040.67480"
"13.65000","1.13760","10157.03711"
"13.80000","1.15015","10271.00879"
"13.95000","1.16262","10381.51270"
"14.10000","1.17508","10494.59668"
"14.25000","1.18754","10606.64746"
"14.40000","1.20001","10718.88770"
"14.55000","1.21247","10833.15723"
"14.70000","1.22503","10949.62793"
"14.85000","1.23749","11065.37402"
"15.00000","1.25005","11178.34180"
"15.15000","1.26251","11293.25293"
"15.30000","1.27507","11407.89746"
"15.45000","1.28753","11524.92285"
"15.60000","1.29999","11637.15234"
"15.75000","1.31255","11755.56152"
"15.90000","1.32510","11874.34863"
"16.05000","1.33747","11986.89160"
"16.20000","1.34994","12105.46875"
"16.35000","1.36249","12221.43262"
"16.50000","1.37505","12338.62305"
"16.65000","1.38751","12451.29297"
"16.80000","1.40007","12570.19336"
"16.95000","1.41253","12687.88379"
"17.10000","1.42509","12804.22070"
"17.25000","1.43746","12921.01855"
"17.40000","1.45002","13039.67383"
"17.55000","1.46248","13156.45312"
"17.70000","1.47504","13272.53711"
"17.85000","1.48759","13390.25977"
"18.00000","1.50005","13506.72656"
"18.15000","1.51252","13623.61426"
"18.30000","1.52507","13738.25488"
"18.45000","1.53754","13854.48145"
"18.60000","1.55009","13970.15625"
"18.75000","1.56256","14084.68652"
"18.90000","1.57502","14201.76074"
"19.05000","1.58748","14319.19531"
"19.20000","1.59995","14434.84863"
"19.35000","1.61250","14552.75098"
"19.50000","1.62506","14669.20703"
"19.65000","1.63752","14787.19531"
"19.80000","1.65008","14902.34863"
"19.95000","1.66254","15022.10645"
"20.10000","1.67500","15137.20605"
"20.25000","1.68747","15252.27148"
"20.40000","1.70002","15368.01270"
"20.55000","1.71258","15481.80762"
"20.70000","1.72504","15597.89062"
"20.85000","1.73760","15709.98438"
"21.00000","1.75006","15822.74121"
"21.15000","1.76253","15935.67871"
"21.30000","1.77499","16046.40039"
"21.45000","1.78755","16157.17676"
"21.60000","1.80001","16267.85840"
"21.75000","1.81247","16377.01367"
"21.90000","1.82503","16479.99805"
"22.05000","1.83749","16583.93945"
"22.20000","1.84996","16681.03711"
"22.35000","1.86261","16764.50781"
"22.50000","1.87507","16815.32422"
"22.65000","1.88763","16427.90430"
"22.80000","1.90018","15989.01465"
"22.95000","1.91265","16021.15039"
"23.10000","1.92511","16066.56445"
"23.25000","1.93757","16080.41211"
"23.40000","1.95003","16050.18848"
"23.55000","1.96259","16034.64941"
"23.70000","1.97505","16047.85156"
"23.85000","1.98761","16063.60547"
"24.00000","2.00007","16064.32227"
"24.15000","2.01244","16077.64844"
"24.30000","2.02500","16086.85547"
"24.45000","2.03756","16099.22656"
"24.60000","2.05011","16122.92090"
"24.75000","2.06267","16145.02637"
"24.90000","2.07513","16147.65820"
"25.05000","2.08759","16132.41895"
"25.20000","2.10006","16144.79590"
"25.35000","2.11252","16171.01855"
"25.50000","2.12508","16177.73438"
"25.65000","2.13763","16205.46094"
"25.80000","2.15019","16200.32227"
"25.95000","2.16256","16186.53418"
"26.10000","2.17502","16152.15723"
"26.25000","2.18749","16087.70605"
"26.40000","2.20004","16071.55664"
"26.55000","2.21260","16070.39453"
"26.70000","2.22506","16097.81055"
"26.85000","2.23762","16137.52051"
"27.00000","2.25008","16160.37793"
"27.15000","2.26255","16164.98340"
"27.30000","2.27501","16178.32520"
"27.45000","2.28756","16199.99219"
"27.60000","2.30003","16232.04004"
"27.75000","2.31258","16253.09277"
"27.90000","2.32514","16278.55859"
"28.05000","2.33760","16287.86133"
"28.20000","2.34997","16296.28223"
"28.35000","2.36253","16305.15137"
"28.50000","2.37509","16303.73438"
"28.65000","2.38755","16278.30371"
"28.80000","2.40011","16251.32715"
"28.95000","2.41266","16236.70898"
"29.10000","2.42513","16217.55469"
"29.25000","2.43759","16212.43848"
"29.40000","2.45015","16245.40723"
"29.55000","2.46252","16265.63965"
"29.70000","2.47507","16261.78516"
"29.85000","2.48753","16269.79883"
"30.00000","2.50000","16284.36719"
"30.15000","2.51255","16310.37598"
"30.30000","2.52502","16334.51270"
"30.45000","2.53757","16352.94141"
"30.60000","2.55004","16328.47070"
"30.75000","2.56259","16304.63184"
"30.90000","2.57506","16299.50391"
"31.05000","2.58752","16319.99805"
"31.20000","2.59998","16329.35254"
"31.35000","2.61254","16332.49121"
"31.50000","2.62500","16338.52246"
"31.65000","2.63756","16338.71387"
"31.80000","2.65012","16345.71289"
"31.95000","2.66258","16343.26855"
"32.10000","2.67504","16332.21387"
"32.25000","2.68760","16360.21094"
"32.40000","2.70006","16366.89258"
"32.55000","2.71262","16367.51465"
"32.70000","2.72508","16351.24707"
"32.85000","2.73764","16372.55859"
"33.00000","2.75010","16375.91992"
"33.15000","2.76256","16388.01562"
"33.30000","2.77512","16393.77930"
"33.45000","2.78758","16392.10156"
"33.60000","2.80014","16375.06348"
"33.75000","2.81270","16369.52051"
"33.90000","2.82507","16347.39648"
"34.05000","2.83753","16304.48242"
"34.20000","2.84999","16289.01465"
"34.35000","2.86255","16281.35254"
"34.50000","2.87511","16287.39062"
"34.65000","2.88766","16292.41211"
"34.80000","2.90013","16271.95020"
"34.95000","2.91259","16286.61133"
"35.10000","2.92505","16312.74121"
"35.25000","2.93751","16335.19238"
"35.40000","2.94998","16370.53906"
"35.55000","2.96253","16411.54492"
"35.70000","2.97509","16439.71680"
"35.85000","2.98755","16452.46875"
"36.00000","3.00002","16472.50000"
"36.15000","3.01248","16478.94336"
"36.30000","3.02504","16472.08984"
"36.45000","3.03759","16469.38086"
"36.60000","3.05006","16487.88086"
"36.75000","3.06261","16516.26758"
"36.90000","3.07508","16543.89258"
"37.05000","3.08754","16572.20508"
"37.20000","3.10000","16595.19141"
"37.35000","3.11265","16610.29688"
"37.50000","3.12521","16625.28906"
"37.65000","3.13767","16644.76758"
"37.80000","3.15013","16662.85938"
"37.95000","3.16260","16678.93945"
"38.10000","3.17497","16696.48438"
"38.25000","3.18752","16712.48828"
"38.40000","3.19999","16728.99609"
"38.55000","3.21254","16744.63086"
"38.70000","3.22519","16759.08789"
"38.85000","3.23766","16771.25781"
"39.00000","3.25012","16784.97852"
"39.15000","3.26258","16797.23047"
"39.30000","3.27504","16809.58789"
"39.45000","3.28751","16823.22656"
"39.60000","3.29997","16838.47852"
"39.75000","3.31262","16850.24219"
"39.90000","3.32508","16861.54492"
"40.05000","3.33755","16877.13672"
"40.20000","3.35010","16890.64648"
"40.35000","3.36257","16903.47852"
"40.50000","3.37512","16917.86914"
"40.65000","3.38759","16933.15039"
"40.80000","3.40014","16947.02148"
"40.95000","3.41261","16958.96094"
"41.10000","3.42507","16973.06836"
"41.25000","3.43763","16986.99805"
"41.40000","3.45009","16998.22266"
"41.55000","3.46255","17013.54883"
"41.70000","3.47511","17026.12500"
"41.85000","3.48757","17039.33398"
"42.00000","3.50003","17051.97656"
"42.15000","3.51250","17065.25781"
"42.30000","3.52505","17078.51953"
"42.45000","3.53761","17091.50391"
"42.60000","3.55007","17104.84570"
"42.75000","3.56263","17117.38867"
"42.90000","3.57509","17131.54492"
"43.05000","3.58756","17142.89258"
"43.20000","3.60002","17156.58984"
"43.35000","3.61258","17169.06055"
"43.50000","3.62504","17181.84180"
"43.65000","3.63750","17194.05664"
"43.80000","3.65006","17206.47266"
"43.95000","3.66252","17218.97656"
"44.10000","3.67498","17231.11914"
"44.25000","3.68754","17244.02344"
"44.40000","3.70010","17254.21875"
"44.55000","3.71265","17267.95703"
"44.70000","3.72512","17280.02930"
"44.85000","3.73758","17291.42969"
"45.00000","3.75004","17303.56445"
"45.15000","3.76260","17314.75000"
"45.30000","3.77506","17325.50781"
"45.45000","3.78762","17336.58984"
"45.60000","3.80008","17350.11523"
"45.75000","3.81264","17360.23242"
"45.90000","3.82501","17372.48438"
"46.05000","3.83747","17384.83398"
"46.20000","3.85003","17395.14844"
"46.35000","3.86249","17406.72656"
"46.50000","3.87505","17419.53711"
"46.65000","3.88760","17430.30469"
"46.80000","3.90016","17441.83594"
"46.95000","3.91253","17453.29492"
"47.10000","3.92509","17465.02148"
"47.25000","3.93755","17476.35547"
"47.40000","3.95001","17487.83984"
"47.55000","3.96248","17501.00781"
"47.70000","3.97503","17511.37695"
"47.85000","3.98750","17522.07812"
"48.00000","4.00005","17532.69727"
"48.15000","4.01252","17544.77734"
"48.30000","4.02507","17554.30469"
"48.45000","4.03763","17565.59961"
"48.60000","4.05009","17576.00586"
"48.75000","4.06255","17586.80664"
"48.90000","4.07502","17596.68750"
"49.05000","4.08748","17608.01172"
"49.20000","4.10013","17620.33398"
"49.35000","4.11269","17627.01953"
"49.50000","4.12515","17638.91992"
"49.65000","4.13771","17648.94336"
"49.80000","4.15017","17658.93750"
"49.95000","4.16254","17668.70312"
"50.10000","4.17500","17680.05273"
"50.25000","4.18747","17690.64258"
"50.40000","4.20002","17698.93750"
"50.55000","4.21258","17710.65820"
"50.70000","4.22514","17720.91016"
"50.85000","4.23760","17729.91797"
"51.00000","4.25006","17740.16797"
"51.15000","4.26252","17750.11328"
"51.30000","4.27508","17760.82227"
"51.45000","4.28754","17769.70508"
"51.60000","4.30010","17780.18555"
"51.75000","4.31256","17790.38672"
"51.90000","4.32503","17799.44727"
"52.05000","4.33758","17808.74805"
"52.20000","4.35005","17819.85547"
"52.35000","4.36260","17829.66797"
"52.50000","4.37516","17838.29102"
"52.65000","4.38762","17847.50977"
"52.80000","4.40009","17857.40039"
"52.95000","4.41255","17866.14062"
"53.10000","4.42501","17876.00977"
"53.25000","4.43748","17885.35938"
"53.40000","4.45003","17894.36914"
"53.55000","4.46259","17904.32031"
"53.70000","4.47514","17912.73242"
"53.85000","4.48761","17922.13281"
"54.00000","4.50007","17931.15039"
"54.15000","4.51263","17939.24023"
"54.30000","4.52509","17948.44336"
"54.45000","4.53755","17956.19336"
"54.60000","4.55011","17965.09961"
"54.75000","4.56257","17973.29102"
"54.90000","4.57504","17981.76562"
"55.05000","4.58759","17991.58594"
"55.20000","4.60006","17999.40820"
"55.35000","4.61252","18008.20312"
"55.50000","4.62508","18019.16016"
"55.65000","4.63754","18026.35547"
"55.80000","4.65000","18034.07422"
"55.95000","4.66246","18042.71289"
"56.10000","4.67502","18050.31055"
"56.25000","4.68758","18058.59570"
"56.40000","4.70004","18066.50781"
"56.55000","4.71260","18074.24805"
"56.70000","4.72515","18083.15039"
"56.85000","4.73762","18091.19727"
"57.00000","4.75008","18100.25195"
"57.15000","4.76254","18109.95117"
"57.30000","4.77501","18115.72070"
"57.45000","4.78756","18125.57227"
"57.60000","4.80003","18131.51758"
"57.75000","4.81258","18140.11133"
"57.90000","4.82505","18147.89453"
"58.05000","4.83751","18156.46680"
"58.20000","4.85006","18164.46680"
"58.35000","4.86262","18170.37500"
"58.50000","4.87508","18177.93750"
"58.65000","4.88764","18185.58789"
"58.80000","4.90010","18192.67188"
"58.95000","4.91257","18199.49414"
"59.10000","4.92503","18208.36914"
"59.25000","4.93759","18215.52148"
"59.40000","4.95005","18221.73047"
"59.55000","4.96261","18230.05469"
"59.70000","4.97507","18238.05078"
"59.85000","4.98753","18245.96680"
"60.00000","5.00000","18253.19727"
"60.15000","5.01255","18261.28711"
"60.30000","5.02511","18268.48242"
"60.45000","5.03757","18273.93359"
"60.60000","5.05013","18280.66797"
"60.75000","5.06259","18287.25781"
"60.90000","5.07505","18294.03711"
"61.05000","5.08761","18301.88086"
"61.20000","5.10007","18309.24805"
"61.35000","5.11263","18315.26953"
"61.50000","5.12519","18322.41797"
"61.65000","5.13765","18327.98828"
"61.80000","5.15002","18335.16211"
"61.95000","5.16248","18342.83398"
"62.10000","5.17504","18348.56250"
"62.25000","5.18760","18356.13867"
"62.40000","5.20006","18362.99609"
"62.55000","5.21262","18368.82031"
"62.70000","5.22508","18375.12500"
"62.85000","5.23754","18381.01758"
"63.00000","5.25010","18387.60156"
"63.15000","5.26256","18393.75195"
"63.30000","5.27512","18399.29297"
"63.45000","5.28758","18407.86328"
"63.60000","5.30014","18413.45312"
"63.75000","5.31260","18419.32812"
"63.90000","5.32497","18427.18945"
"64.05000","5.33753","18434.32422"
"64.20000","5.34999","18439.61133"
"64.35000","5.36255","18446.65820"
"64.50000","5.37510","18453.18359"
"64.65000","5.38766","18458.45508"
"64.80000","5.40012","18462.42773"
"64.95000","5.41259","18469.09961"
"65.10000","5.42505","18475.51562"
"65.25000","5.43760","18480.08984"
"65.40000","5.45007","18487.85352"
"65.55000","5.46253","18493.46094"
"65.70000","5.47509","18499.28711"
"65.85000","5.48755","18505.82812"
"66.00000","5.50011","18512.02344"
"66.15000","5.51257","18517.41602"
"66.30000","5.52513","18522.59766"
"66.45000","5.53759","18528.67578"
"66.60000","5.55015","18532.40039"
"66.75000","5.56261","18538.51758"
"66.90000","5.57507","18542.39453"
"67.05000","5.58754","18547.94922"
"67.20000","5.60009","18553.14453"
"67.35000","5.61256","18557.01953"
"67.50000","5.62511","18564.83984"
"67.65000","5.63767","18569.68555"
"67.80000","5.65013","18575.60938"
"67.95000","5.66250","18580.61133"
"68.10000","5.67506","18586.99023"
"68.25000","5.68752","18592.47852"
"68.40000","5.70008","18597.82031"
"68.55000","5.71254","18601.99219"
"68.70000","5.72510","18607.15820"
"68.85000","5.73756","18612.50195"
"69.00000","5.75012","18616.61133"
"69.15000","5.76258","18622.00586"
"69.30000","5.77514","18626.08008"
"69.45000","5.78760","18632.78711"
"69.60000","5.80006","18636.53516"
"69.75000","5.81253","18641.91406"
"69.90000","5.82508","18646.61328"
"70.05000","5.83754","18650.13672"
"70.20000","5.85010","18655.58008"
"70.35000","5.86266","18661.67578"
"70.50000","5.87512","18664.82031"
"70.65000","5.88758","18669.63086"
"70.80000","5.90005","18674.83789"
"70.95000","5.91251","18679.84766"
"71.10000","5.92507","18683.32031"
"71.25000","5.93753","18687.47461"
"71.40000","5.95009","18693.25781"
"71.55000","5.96264","18695.85742"
"71.70000","5.97511","18700.85742"
"71.85000","5.98757","18706.04688"
"72.00000","6.00003","18710.84180"
"72.15000","6.01249","18715.80078"
"72.30000","6.02505","18720.38477"
"72.45000","6.03751","18726.56250"
"72.60000","6.05007","18730.21484"
"72.75000","6.06253","18732.19141"
"72.90000","6.07509","18737.43945"
"73.05000","6.08765","18741.86328"
"73.20000","6.10020","18745.15430"
"73.35000","6.11267","18749.41797"
"73.50000","6.12513","18753.90820"
"73.65000","6.13759","18757.41602"
"73.80000","6.14996","18760.74023"
"73.95000","6.16252","18766.47070"
"74.10000","6.17498","18770.37109"
"74.25000","6.18754","18773.40234"
"74.40000","6.20010","18778.35742"
"74.55000","6.21265","18781.55078"
"74.70000","6.22512","18785.04688"
"74.85000","6.23758","18789.94727"
"75.00000","6.25004","18794.34375"
"75.15000","6.26260","18797.95703"
"75.30000","6.27506","18800.06250"
"75.45000","6.28762","18804.65820"
"75.60000","6.30017","18807.29102"
"75.75000","6.31264","18811.42773"
"75.90000","6.32510","18814.37305"
"76.05000","6.33756","18817.95898"
"76.20000","6.35012","18822.36133"
"76.35000","6.36258","18825.17969"
"76.50000","6.37514","18829.50586"
"76.65000","6.38760","18832.67773"
"76.80000","6.40016","18835.51172"
"76.95000","6.41262","18839.58398"
"77.10000","6.42509","18843.55273"
"77.25000","6.43755","18846.90430"
"77.40000","6.45011","18850.69922"
"77.55000","6.46257","18853.77734"
"77.70000","6.47503","18857.11133"
"77.85000","6.48749","18860.50977"
"78.00000","6.49996","18862.71875"
"78.15000","6.51251","18866.05664"
"78.30000","6.52507","18869.93945"
"78.45000","6.53753","18872.89648"
"78.60000","6.55009","18877.08008"
"78.75000","6.56255","18879.52148"
"78.90000","6.57502","18884.64258"
"79.05000","6.58748","18886.74414"
"79.20000","6.59994","18889.63672"
"79.35000","6.61250","18893.27539"
"79.50000","6.62505","18894.00195"
"79.65000","6.63752","18897.04297"
"79.80000","6.65007","18900.89844"
"79.95000","6.66254","18903.93945"
"80.10000","6.67500","18906.09766"
"80.25000","6.68756","18909.75586"
"80.40000","6.70011","18913.70898"
"80.55000","6.71258","18915.93750"
"80.70000","6.72504","18918.89844"
"80.85000","6.73760","18921.19922"
"81.00000","6.75015","18924.87500"
"81.15000","6.76262","18926.09961"
"81.30000","6.77508","18929.25000"
"81.45000","6.78754","18932.70312"
"81.60000","6.80010","18935.43945"
"81.75000","6.81256","18938.18945"
"81.90000","6.82502","18941.51367"
"82.05000","6.83758","18944.08008"
"82.20000","6.85014","18944.94727"
"82.35000","6.86260","18948.54102"
"82.50000","6.87516","18950.09961"
"82.65000","6.88762","18952.28516"
"82.80000","6.90008","18954.40234"
"82.95000","6.91255","18958.33789"
"83.10000","6.92501","18961.34180"
"83.25000","6.93757","18961.21484"
"83.40000","6.95003","18966.40430"
"83.55000","6.96259","18967.03516"
"83.70000","6.97505","18969.11719"
"83.85000","6.98751","18971.26953"
"84.00000","7.00007","18973.64648"
"84.15000","7.01253","18977.02148"
"84.30000","7.02509","18978.61719"
"84.45000","7.03755","18981.42578"
"84.60000","7.05001","18983.91016"
"84.75000","7.06257","18985.92188"
"84.90000","7.07513","18988.13867"
"85.05000","7.08768","18990.43750"
"85.20000","7.10015","18991.18555"
"85.35000","7.11261","18994.10547"
"85.50000","7.12517","18996.01758"
"85.65000","7.13754","18998.47461"
"85.80000","7.15000","19000.84375"
"85.95000","7.16246","19003.23633"
"86.10000","7.17502","19005.84961"
"86.25000","7.18758","19008.25586"
"86.40000","7.20013","19008.36328"
"86.55000","7.21269","19010.58203"
"86.70000","7.22515","19011.82812"
"86.85000","7.23762","19012.97656"
"87.00000","7.25008","19015.20117"
"87.15000","7.26254","19018.72852"
"87.30000","7.27510","19021.68359"
"87.45000","7.28756","19021.62891"
"87.60000","7.30012","19023.59961"
"87.75000","7.31258","19026.11328"
"87.90000","7.32504","19027.85938"
"88.05000","7.33760","19028.61914"
"88.20000","7.35016","19030.57422"
"88.35000","7.36271","19033.51758"
"88.50000","7.37518","19033.01562"
"88.65000","7.38764","19035.55664"
"88.80000","7.40010","19037.16211"
"88.95000","7.41257","19038.42773"
"89.10000","7.42503","19040.03320"
"89.25000","7.43758","19041.12891"
"89.40000","7.45014","19045.73633"
"89.55000","7.46270","19045.11328"
"89.70000","7.47516","19047.55078"
"89.85000","7.48753","19049.28125"
"90.00000","7.50009","19050.38086"
"90.15000","7.51255","19051.59570"
"90.30000","7.52501","19054.56836"
"90.45000","7.53757","19055.49609"
"90.60000","7.55013","19055.58398"
"90.75000","7.56259","19057.17383"
"90.90000","7.57505","19057.33008"
"91.05000","7.58752","19059.91797"
"91.20000","7.60007","19060.79883"
"91.35000","7.61254","19064.46875"
"91.50000","7.62509","19065.27539"
"91.65000","7.63755","19065.65820"
"91.80000","7.65002","19066.15234"
"91.95000","7.66257","19067.84570"
"92.10000","7.67504","19069.65234"
"92.25000","7.68759","19070.35352"
"92.40000","7.70015","19072.14844"
"92.55000","7.71261","19073.34180"
"92.70000","7.72508","19074.04883"
"92.85000","7.73754","19075.46484"
"93.00000","7.75010","19077.06836"
"93.15000","7.76256","19077.41797"
"93.30000","7.77512","19078.75000"
"93.45000","7.78758","19079.24023"
"93.60000","7.80004","19080.69336"
"93.75000","7.81260","19082.51367"
"93.90000","7.82506","19083.42188"
"94.05000","7.83752","19085.04492"
"94.20000","7.85008","19086.80469"
"94.35000","7.86254","19087.56445"
"94.50000","7.87510","19087.78320"
"94.65000","7.88766","19088.63281"
"94.80000","7.90012","19088.59961"
"94.95000","7.91258","19088.24219"
"95.10000","7.92514","19090.26953"
"95.25000","7.93760","19091.67969"
"95.40000","7.95007","19091.71289"
"95.55000","7.96253","19093.34375"
"95.70000","7.97499","19094.55273"
"95.85000","7.98755","19096.18555"
"96.00000","8.00010","19096.41211"
"96.15000","8.01257","19096.42188"
"96.30000","8.02512","19098.37500"
"96.45000","8.03759","19097.43164"
"96.60000","8.05014","19099.33789"
"96.75000","8.06261","19100.62891"
"96.90000","8.07516","19101.69922"
"97.05000","8.08763","19100.32031"
"97.20000","8.10009","19100.51367"
"97.35000","8.11265","19103.59180"
"97.50000","8.12511","19101.33594"
"97.65000","8.13757","19102.60352"
"97.80000","8.15004","19104.20117"
"97.95000","8.16250","19105.21484"
"98.10000","8.17515","19104.19531"
"98.25000","8.18761","19105.69727"
"98.40000","8.20007","19106.64062"
"98.55000","8.21263","19106.31445"
"98.70000","8.22509","19105.83984"
"98.85000","8.23765","19106.39062"
"99.00000","8.25011","19106.67383"
"99.15000","8.26258","19106.55859"
"99.30000","8.27504","19109.36914"
"99.45000","8.28760","19109.49609"
"99.60000","8.30006","19109.86133"
"99.75000","8.31243","19110.91602"
"99.90000","8.32499","19111.38086"
"100.05000","8.33754","19112.66797"
"100.20000","8.35010","19111.73242"
"100.35000","8.36266","19112.76758"
"100.50000","8.37512","19113.60352"
"100.65000","8.38758","19112.70898"
"100.80000","8.40004","19112.97070"
"100.95000","8.41251","19113.72656"
"101.10000","8.42506","19113.19922"
"101.25000","8.43753","19113.62500"
"101.40000","8.45008","19113.15234"
"101.55000","8.46264","19114.01953"
"101.70000","8.47510","19114.04688"
"101.85000","8.48757","19114.98242"
"102.00000","8.50003","19115.26562"
"102.15000","8.51259","19115.52930"
"102.30000","8.52505","19116.50000"
"102.45000","8.53761","19116.14453"
"102.60000","8.55007","19115.16406"
"102.75000","8.56253","19115.20117"
"102.90000","8.57509","19114.19727"
"103.05000","8.58755","19113.19922"
"103.20000","8.60011","19114.69336"
"103.35000","8.61257","19115.52539"
"103.50000","8.62513","19115.29688"
"103.65000","8.63759","19114.95117"
"103.80000","8.65005","19114.99023"
"103.95000","8.66252","19114.70898"
"104.10000","8.67498","19115.08008"
"104.25000","8.68754","19114.79297"
"104.40000","8.70009","19114.47266"
"104.55000","8.71265","19114.37305"
"104.70000","8.72511","19113.57422"
"104.85000","8.73758","19113.78320"
"105.00000","8.75013","19112.82812"
"105.15000","8.76250","19111.53906"
"105.30000","8.77506","19113.67383"
"105.45000","8.78761","19110.78320"
"105.60000","8.80008","19111.86133"
"105.75000","8.81264","19112.23438"
"105.90000","8.82510","19112.08008"
"106.05000","8.83765","19111.39844"
"106.20000","8.85012","19111.40039"
"106.35000","8.86258","19111.53320"
"106.50000","8.87504","19109.69531"
"106.65000","8.88760","19109.00391"
"106.80000","8.90006","19108.89844"
"106.95000","8.91262","19108.38477"
"107.10000","8.92508","19105.50391"
"107.25000","8.93755","19107.40820"
"107.40000","8.95010","19106.39648"
"107.55000","8.96257","19106.21289"
"107.70000","8.97503","19105.53516"
"107.85000","8.98749","19104.64258"
"108.00000","8.99995","19104.87500"
"108.15000","9.01251","19103.52344"
"108.30000","9.02497","19103.08203"
"108.45000","9.03753","19104.25195"
"108.60000","9.05018","19102.53125"
"108.75000","9.06264","19101.53711"
"108.90000","9.07511","19101.70703"
"109.05000","9.08766","19100.73438"
"109.20000","9.10013","19099.03125"
"109.35000","9.11250","19097.68359"
"109.50000","9.12505","19097.50586"
"109.65000","9.13752","19096.27344"
"109.80000","9.14998","19095.57617"
"109.95000","9.16253","19094.14062"
"110.10000","9.17509","19093.58594"
"110.25000","9.18765","19093.35156"
"110.40000","9.20011","19092.72070"
"110.55000","9.21257","19091.51758"
"110.70000","9.22504","19089.47070"
"110.85000","9.23759","19088.32422"
"111.00000","9.25006","19086.77148"
"111.15000","9.26252","19085.22852"
"111.30000","9.27508","19085.38477"
"111.45000","9.28763","19083.77734"
"111.60000","9.30010","19082.37695"
"111.75000","9.31256","19081.49219"
"111.90000","9.32502","19080.29688"
"112.05000","9.33758","19079.46094"
"112.20000","9.35004","19078.96680"
"112.35000","9.36260","19076.19141"
"112.50000","9.37506","19075.58789"
"112.65000","9.38762","19073.51562"
"112.80000","9.40008","19072.92969"
"112.95000","9.41255","19071.61523"
"113.10000","9.42510","19069.25781"
"113.25000","9.43756","19070.06836"
"113.40000","9.45003","19066.67773"
"113.55000","9.46258","19064.55859"
"113.70000","9.47505","19063.67188"
"113.85000","9.48751","19061.90430"
"114.00000","9.50007","19059.71680"
"114.15000","9.51262","19058.50391"
"114.30000","9.52509","19056.80078"
"114.45000","9.53764","19054.61914"
"114.60000","9.55011","19053.08594"
"114.75000","9.56257","19051.42578"
"114.90000","9.57503","19050.72656"
"115.05000","9.58749","19046.60156"
"115.20000","9.60005","19045.90820"
"115.35000","9.61261","19043.86914"
"115.50000","9.62516","19040.77734"
"115.65000","9.63763","19038.49219"
"115.80000","9.65009","19036.83594"
"115.95000","9.66255","19034.87500"
"116.10000","9.67502","19031.73828"
"116.25000","9.68757","19031.99219"
"116.40000","9.70013","19029.63672"
"116.55000","9.71259","19024.93945"
"116.70000","9.72515","19022.70117"
"116.85000","9.73761","19021.51953"
"117.00000","9.75008","19019.16797"
"117.15000","9.76254","19016.08594"
"117.30000","9.77500","19014.32812"
"117.45000","9.78756","19011.99023"
"117.60000","9.80002","19008.60156"
"117.75000","9.81258","19006.84180"
"117.90000","9.82513","19003.62891"
"118.05000","9.83760","19000.59180"
"118.20000","9.85006","18997.01172"
"118.35000","9.86262","18993.52930"
"118.50000","9.87508","18991.49414"
"118.65000","9.88764","18987.65625"
"118.80000","9.90001","18985.08008"
"118.95000","9.91256","18980.67383"
"119.10000","9.92503","18977.21094"
"119.25000","9.93758","18973.94141"
"119.40000","9.95014","18969.82031"
"119.55000","9.96260","18966.59180"
"119.70000","9.97507","18963.04688"
"119.85000","9.98753","18958.04102"
"120.00000","10.00008","18955.00195"
"120.15000","10.01255","18952.17969"
"120.30000","10.02501","18946.74805"
"120.45000","10.03766","18943.58398"
"120.60000","10.05012","18938.41406"
"120.75000","10.06268","18933.24805"
"120.90000","10.07514","18928.88281"
"121.05000","10.08761","18924.25195"
"121.20000","10.09998","18922.19922"
"121.35000","10.11253","18915.10742"
"121.50000","10.12500","18912.86523"
"121.65000","10.13746","18908.47070"
"121.80000","10.15001","18903.35742"
"121.95000","10.16257","18897.05273"
"122.10000","10.17504","18891.95508"
"122.25000","10.18759","18886.71094"
"122.40000","10.20015","18879.09375"
"122.55000","10.21261","18873.38867"
"122.70000","10.22507","18867.66016"
"122.85000","10.23754","18861.79688"
"123.00000","10.25009","18854.89453"
"123.15000","10.26256","18849.47266"
"123.30000","10.27502","18840.68750"
"123.45000","10.28758","18833.36133"
"123.60000","10.30004","18827.21094"
"123.75000","10.31260","18820.86914"
"123.90000","10.32515","18813.68359"
"124.05000","10.33762","18804.89844"
"124.20000","10.35008","18798.28906"
"124.35000","10.36264","18789.87891"
"124.50000","10.37510","18779.39844"
"124.65000","10.38756","18771.60547"
"124.80000","10.40012","18764.16406"
"124.95000","10.41258","18755.16016"
"125.10000","10.42504","18746.87891"
"125.25000","10.43760","18738.72461"
"125.40000","10.45016","18729.18555"
"125.55000","10.46262","18718.83984"
"125.70000","10.47499","18709.99414"
"125.85000","10.48755","18700.74609"
"126.00000","10.50010","18690.43164"
"126.15000","10.51266","18679.65234"
"126.30000","10.52512","18669.57812"
"126.45000","10.53768","18658.54297"
"126.60000","10.55014","18646.60742"
"126.75000","10.56260","18636.50586"
"126.90000","10.57507","18626.70898"
"127.05000","10.58753","18614.44727"
"127.20000","10.59999","18604.53711"
"127.35000","10.61255","18592.25391"
"127.50000","10.62511","18580.66992"
"127.65000","10.63757","18566.99219"
"127.80000","10.65013","18555.70898"
"127.95000","10.66259","18543.58984"
"128.10000","10.67515","18531.59961"
"128.25000","10.68770","18519.11719"
"128.40000","10.70017","18506.98242"
"128.55000","10.71263","18493.28125"
"128.70000","10.72509","18479.12695"
"128.85000","10.73756","18466.68359"
"129.00000","10.75002","18451.71875"
"129.15000","10.76258","18440.86719"
"129.30000","10.77513","18424.69922"
"129.45000","10.78759","18411.40625"
"129.60000","10.80006","18397.62891"
"129.75000","10.81252","18381.94922"
"129.90000","10.82498","18367.64844"
"130.05000","10.83754","18352.98828"
"130.20000","10.85010","18339.13086"
"130.35000","10.86265","18322.21484"
"130.50000","10.87512","18306.93750"
"130.65000","10.88758","18292.01758"
"130.80000","10.90014","18275.48633"
"130.95000","10.91251","18258.71680"
"131.10000","10.92497","18243.71875"
"131.25000","10.93752","18226.13867"
"131.40000","10.95008","18207.43359"
"131.55000","10.96264","18192.75391"
"131.70000","10.97510","18176.03320"
"131.85000","10.98757","18159.06250"
"132.00000","11.00012","18140.84961"
"132.15000","11.01258","18123.88281"
"132.30000","11.02514","18107.33789"
"132.45000","11.03770","18087.31055"
"132.60000","11.05007","18068.86328"
"132.75000","11.06262","18051.16211"
"132.90000","11.07509","18032.18164"
"133.05000","11.08755","18011.48438"
"133.20000","11.10001","17996.37305"
"133.35000","11.11257","17976.78125"
"133.50000","11.12503","17956.46289"
"133.65000","11.13750","17937.58789"
"133.80000","11.15005","17918.10156"
"133.95000","11.16251","17898.06055"
"134.10000","11.17507","17876.70508"
"134.25000","11.18763","17855.66602"
"134.40000","11.20009","17834.82617"
"134.55000","11.21265","17811.79102"
"134.70000","11.22511","17790.64453"
"134.85000","11.23757","17770.36719"
"135.00000","11.25013","17747.62891"
"135.15000","11.26259","17726.79297"
"135.30000","11.27506","17703.68359"
"135.45000","11.28752","17681.20898"
"135.60000","11.30008","17657.68164"
"135.75000","11.31254","17634.16602"
"135.90000","11.32510","17612.01172"
"136.05000","11.33765","17588.59570"
"136.20000","11.35021","17563.65430"
"136.35000","11.36267","17540.19141"
"136.50000","11.37513","17515.13672"
"136.65000","11.38760","17489.57812"
"136.80000","11.40006","17466.00781"
"136.95000","11.41262","17439.27539"
"137.10000","11.42517","17414.14453"
"137.25000","11.43764","17386.42188"
"137.40000","11.45010","17361.39453"
"137.55000","11.46256","17335.46094"
"137.70000","11.47503","17308.84766"
"137.85000","11.48758","17282.41211"
"138.00000","11.50005","17254.07812"
"138.15000","11.51260","17227.78711"
"138.30000","11.52516","17198.00586"
"138.45000","11.53762","17168.05664"
"138.60000","11.55009","17139.11523"
"138.75000","11.56255","17110.69141"
"138.90000","11.57510","17079.97656"
"139.05000","11.58757","17049.40625"
"139.20000","11.60012","17019.34180"
"139.35000","11.61259","16987.19141"
"139.50000","11.62505","16957.33789"
"139.65000","11.63751","16927.28125"
"139.80000","11.65007","16895.50781"
"139.95000","11.66253","16862.48633"
"140.10000","11.67509","16830.25586"
"140.25000","11.68765","16796.87891"
"140.40000","11.70020","16762.15820"
"140.55000","11.71267","16728.47852"
"140.70000","11.72513","16692.91016"
"140.85000","11.73759","16657.40234"
"141.00000","11.75006","16620.05859"
"141.15000","11.76261","16585.90039"
"141.30000","11.77517","16549.54297"
"141.45000","11.78763","16511.42383"
"141.60000","11.80009","16476.05273"
"141.75000","11.81256","16439.53906"
"141.90000","11.82511","16400.26367"
"142.05000","11.83758","16361.22949"
"142.20000","11.85004","16322.01855"
"142.35000","11.86260","16281.08301"
"142.50000","11.87506","16239.76562"
"142.65000","11.88762","16198.19727"
"142.80000","11.90008","16156.49023"
"142.95000","11.91254","16113.22168"
"143.10000","11.92510","16071.22559"
"143.25000","11.93765","16026.57129"
"143.40000","11.95003","15982.20020"
"143.55000","11.96258","15936.51074"
"143.70000","11.97504","15891.79492"
"143.85000","11.98760","15844.16895"
"144.00000","12.00006","15796.21777"
"144.15000","12.01262","15748.64648"
"144.30000","12.02527","15699.52832"
"144.45000","12.03773","15648.60059"
"144.60000","12.05020","15597.08008"
"144.75000","12.06257","15545.43066"
"144.90000","12.07503","15492.68555"
"145.05000","12.08749","15439.17090"
"145.20000","12.10005","15383.46973"
"145.35000","12.11261","15328.56055"
"145.50000","12.12507","15271.89648"
"145.65000","12.13753","15214.40625"
"145.80000","12.15009","15155.76855"
"145.95000","12.16264","15094.85645"
"146.10000","12.17511","15031.55078"
"146.25000","12.18766","14963.77148"
"146.40000","12.20013","14862.93652"
"146.44000","12.20472","8909.44531"