File: temper 210C 1hr.is_tens_RawData.csv
Specimen properties : Length,"100.00000",mm
Specimen properties : Thickness,"1.00000",mm
Specimen properties : Width,"10.00000",mm
Test : Rate 1,"5.00000",mm/min

Time,Extension,Load
(s),(mm),(N)
"0.00000","0.00000","-0.15364"
"0.10000","0.00497","2.33737"
"0.20000","0.01424","7.86475"
"0.30000","0.02352","22.63836"
"0.40000","0.03242","30.46108"
"0.50000","0.04123","36.53596"
"0.60000","0.04976","42.27325"
"0.70000","0.05829","52.54973"
"0.80000","0.06672","61.35607"
"0.90000","0.07506","69.22196"
"1.00000","0.08349","87.89869"
"1.10000","0.09174","129.78023"
"1.20000","0.10008","189.44955"
"1.30000","0.10842","256.62231"
"1.40000","0.11676","336.00323"
"1.50000","0.12510","424.20184"
"1.60000","0.13334","526.44653"
"1.70000","0.14178","640.52747"
"1.80000","0.15002","760.07227"
"1.90000","0.15836","881.51123"
"2.00000","0.16670","1001.06226"
"2.10000","0.17495","1120.26050"
"2.20000","0.18348","1241.59033"
"2.30000","0.19182","1358.16699"
"2.40000","0.20016","1469.10217"
"2.50000","0.20850","1579.14111"
"2.60000","0.21674","1685.09387"
"2.70000","0.22518","1782.02466"
"2.80000","0.23342","1870.84521"
"2.90000","0.24176","1951.72107"
"3.00000","0.25010","2031.78259"
"3.10000","0.25835","2109.18091"
"3.20000","0.26669","2184.05273"
"3.30000","0.27503","2259.27856"
"3.40000","0.28337","2334.29272"
"3.50000","0.29171","2409.46753"
"3.60000","0.30005","2484.10083"
"3.70000","0.30839","2557.45972"
"3.80000","0.31673","2630.33691"
"3.90000","0.32507","2703.16016"
"4.00000","0.33341","2776.31665"
"4.10000","0.34175","2848.19019"
"4.20000","0.35009","2919.24951"
"4.30000","0.35833","2988.52026"
"4.40000","0.36677","3058.55664"
"4.50000","0.37501","3128.14526"
"4.60000","0.38335","3198.11206"
"4.70000","0.39179","3269.46704"
"4.80000","0.40003","3339.26270"
"4.90000","0.40847","3409.50562"
"5.00000","0.41671","3480.43896"
"5.10000","0.42505","3549.67407"
"5.20000","0.43349","3618.67578"
"5.30000","0.44173","3686.38379"
"5.40000","0.45007","3755.36279"
"5.50000","0.45841","3822.58154"
"5.60000","0.46675","3889.77271"
"5.70000","0.47509","3951.87036"
"5.80000","0.48334","4012.16187"
"5.90000","0.49177","4075.21997"
"6.00000","0.50011","4140.40088"
"6.10000","0.50836","4203.16699"
"6.20000","0.51679","4267.53467"
"6.30000","0.52504","4330.69141"
"6.40000","0.53338","4394.22998"
"6.50000","0.54172","4458.67334"
"6.60000","0.55006","4522.53516"
"6.70000","0.55840","4587.10107"
"6.80000","0.56674","4650.65381"
"6.90000","0.57517","4714.01123"
"7.00000","0.58342","4779.81885"
"7.10000","0.59176","4844.70068"
"7.20000","0.60019","4910.16943"
"7.30000","0.60844","4974.88770"
"7.40000","0.61678","5039.40918"
"7.50000","0.62502","5105.93750"
"7.60000","0.63346","5171.23926"
"7.70000","0.64170","5237.37842"
"7.80000","0.65004","5302.66211"
"7.90000","0.65838","5368.97949"
"8.00000","0.66672","5439.06543"
"8.10000","0.67506","5506.25342"
"8.20000","0.68350","5573.92334"
"8.30000","0.69174","5642.28418"
"8.40000","0.70008","5708.57959"
"8.50000","0.70833","5776.64990"
"8.60000","0.71667","5844.20508"
"8.70000","0.72501","5914.38086"
"8.80000","0.73344","5983.20215"
"8.90000","0.74178","6051.76270"
"9.00000","0.75003","6120.18652"
"9.10000","0.75846","6190.42285"
"9.20000","0.76680","6261.21387"
"9.30000","0.77505","6330.77197"
"9.40000","0.78339","6400.11279"
"9.50000","0.79173","6468.64404"
"9.60000","0.80007","6539.03564"
"9.70000","0.80841","6610.74170"
"9.80000","0.81665","6681.14502"
"9.90000","0.82509","6750.57373"
"10.00000","0.83333","6805.94092"
"10.10000","0.84177","6885.27881"
"10.20000","0.85011","6959.10303"
"10.30000","0.85845","7030.45557"
"10.40000","0.86669","7104.70898"
"10.50000","0.87503","7177.85205"
"10.60000","0.88337","7248.83838"
"10.70000","0.89171","7324.63086"
"10.80000","0.90005","7397.92139"
"10.90000","0.90839","7472.63232"
"11.00000","0.91673","7546.12402"
"11.10000","0.92507","7619.14404"
"11.20000","0.93341","7695.38281"
"11.30000","0.94175","7769.58105"
"11.40000","0.95009","7844.78613"
"11.50000","0.95834","7919.44482"
"11.60000","0.96677","7992.68262"
"11.70000","0.97502","8066.80029"
"11.80000","0.98336","8141.37012"
"11.90000","0.99170","8215.65039"
"12.00000","0.99994","8293.34668"
"12.10000","1.00838","8368.84473"
"12.20000","1.01672","8443.12305"
"12.30000","1.02506","8520.48438"
"12.40000","1.03340","8597.40234"
"12.50000","1.04164","8674.08691"
"12.60000","1.05008","8750.76660"
"12.70000","1.05832","8825.13379"
"12.80000","1.06676","8903.99902"
"12.90000","1.07510","8981.65723"
"13.00000","1.08344","9058.50195"
"13.10000","1.09178","9136.36914"
"13.20000","1.10002","9213.35254"
"13.30000","1.10836","9289.54590"
"13.40000","1.11670","9368.85840"
"13.50000","1.12504","9445.83496"
"13.60000","1.13338","9523.14551"
"13.70000","1.14163","9601.84766"
"13.80000","1.15006","9677.21289"
"13.90000","1.15831","9755.63867"
"14.00000","1.16674","9835.42090"
"14.10000","1.17517","9915.68848"
"14.20000","1.18342","9993.98242"
"14.30000","1.19185","10070.28516"
"14.40000","1.20010","10151.24902"
"14.50000","1.20853","10230.37402"
"14.60000","1.21687","10310.01172"
"14.70000","1.22512","10389.03320"
"14.80000","1.23346","10465.52148"
"14.90000","1.24171","10545.60840"
"15.00000","1.25005","10623.96289"
"15.10000","1.25839","10703.37988"
"15.20000","1.26673","10782.80664"
"15.30000","1.27507","10857.93457"
"15.40000","1.28331","10937.04980"
"15.50000","1.29175","11017.00488"
"15.60000","1.29999","11096.38477"
"15.70000","1.30833","11175.35059"
"15.80000","1.31676","11252.76074"
"15.90000","1.32501","11331.18848"
"16.00000","1.33344","11409.84570"
"16.10000","1.34178","11490.44824"
"16.20000","1.35003","11570.39355"
"16.30000","1.35837","11648.60156"
"16.40000","1.36671","11726.62793"
"16.50000","1.37505","11806.29004"
"16.60000","1.38339","11886.28809"
"16.70000","1.39173","11965.61816"
"16.80000","1.40007","12045.20020"
"16.90000","1.40841","12122.98633"
"17.00000","1.41675","12201.38477"
"17.10000","1.42509","12281.51270"
"17.20000","1.43334","12359.91406"
"17.30000","1.44177","12439.86914"
"17.40000","1.45002","12518.71777"
"17.50000","1.45836","12596.40430"
"17.60000","1.46670","12676.40723"
"17.70000","1.47504","12756.78418"
"17.80000","1.48338","12837.84375"
"17.90000","1.49171","12917.13965"
"18.00000","1.50005","12996.01758"
"18.10000","1.50839","13076.25781"
"18.20000","1.51673","13156.14160"
"18.30000","1.52507","13236.56250"
"18.40000","1.53332","13316.57910"
"18.50000","1.54175","13395.01758"
"18.60000","1.55000","13477.71582"
"18.70000","1.55843","13557.28613"
"18.80000","1.56677","13638.10938"
"18.90000","1.57511","13718.03906"
"19.00000","1.58345","13797.22852"
"19.10000","1.59179","13877.56934"
"19.20000","1.60013","13957.82520"
"19.30000","1.60838","14037.64648"
"19.40000","1.61672","14116.72266"
"19.50000","1.62506","14195.31738"
"19.60000","1.63331","14274.60645"
"19.70000","1.64174","14354.41113"
"19.80000","1.65008","14434.02637"
"19.90000","1.65833","14514.55469"
"20.00000","1.66676","14593.05762"
"20.10000","1.67510","14672.54297"
"20.20000","1.68334","14753.01270"
"20.30000","1.69168","14832.87695"
"20.40000","1.70002","14914.02246"
"20.50000","1.70836","14994.11328"
"20.60000","1.71670","15074.78809"
"20.70000","1.72514","15155.31836"
"20.80000","1.73338","15237.98535"
"20.90000","1.74172","15321.19531"
"21.00000","1.75016","15401.23535"
"21.10000","1.75840","15482.42090"
"21.20000","1.76674","15561.01562"
"21.30000","1.77508","15640.79395"
"21.40000","1.78342","15720.59277"
"21.50000","1.79176","15801.63965"
"21.60000","1.80001","15881.66016"
"21.70000","1.80835","15960.03223"
"21.80000","1.81669","16042.72852"
"21.90000","1.82503","16124.69238"
"22.00000","1.83346","16207.37793"
"22.10000","1.84180","16288.63770"
"22.20000","1.85005","16368.18945"
"22.30000","1.85839","16450.47656"
"22.40000","1.86673","16532.48438"
"22.50000","1.87507","16615.30078"
"22.60000","1.88331","16697.69336"
"22.70000","1.89175","16777.96680"
"22.80000","1.89999","16861.45898"
"22.90000","1.90843","16942.80859"
"23.00000","1.91677","17025.83789"
"23.10000","1.92511","17108.65625"
"23.20000","1.93345","17189.71289"
"23.30000","1.94179","17271.43359"
"23.40000","1.95013","17351.71094"
"23.50000","1.95837","17433.18359"
"23.60000","1.96671","17514.74219"
"23.70000","1.97505","17596.87305"
"23.80000","1.98330","17677.56250"
"23.90000","1.99173","17759.96094"
"24.00000","1.99998","17842.87695"
"24.10000","2.00841","17924.91602"
"24.20000","2.01675","18008.22266"
"24.30000","2.02500","18088.78320"
"24.40000","2.03334","18172.59766"
"24.50000","2.04168","18255.58789"
"24.60000","2.05002","18339.07227"
"24.70000","2.05845","18422.06445"
"24.80000","2.06670","18503.49219"
"24.90000","2.07513","18586.53516"
"25.00000","2.08338","18669.01758"
"25.10000","2.09181","18751.36523"
"25.20000","2.10006","18833.86523"
"25.30000","2.10840","18915.17578"
"25.40000","2.11674","18996.76367"
"25.50000","2.12498","19079.96094"
"25.60000","2.13342","19162.84375"
"25.70000","2.14166","19245.12891"
"25.80000","2.15000","19326.31055"
"25.90000","2.15844","19410.56641"
"26.00000","2.16678","19494.14453"
"26.10000","2.17521","19577.00781"
"26.20000","2.18346","19659.54492"
"26.30000","2.19180","19741.42578"
"26.40000","2.20014","19823.26758"
"26.50000","2.20838","19907.68359"
"26.60000","2.21672","19990.92578"
"26.70000","2.22506","20074.85742"
"26.80000","2.23331","20157.12695"
"26.90000","2.24174","20240.64453"
"27.00000","2.24999","20322.59180"
"27.10000","2.25842","20405.72852"
"27.20000","2.26676","20488.21289"
"27.30000","2.27501","20570.83594"
"27.40000","2.28344","20653.85938"
"27.50000","2.29169","20735.19727"
"27.60000","2.30003","20818.43555"
"27.70000","2.30837","20901.48828"
"27.80000","2.31671","20984.16992"
"27.90000","2.32505","21069.53320"
"28.00000","2.33339","21149.36914"
"28.10000","2.34173","21232.93359"
"28.20000","2.35007","21316.62891"
"28.30000","2.35841","21399.35938"
"28.40000","2.36675","21484.00391"
"28.50000","2.37499","21566.56055"
"28.60000","2.38333","21650.62305"
"28.70000","2.39167","21733.91992"
"28.80000","2.40011","21817.37305"
"28.90000","2.40845","21904.22656"
"29.00000","2.41669","21986.41992"
"29.10000","2.42513","22069.27930"
"29.20000","2.43337","22151.62109"
"29.30000","2.44171","22235.19141"
"29.40000","2.45005","22319.54102"
"29.50000","2.45839","22402.48828"
"29.60000","2.46673","22485.50781"
"29.70000","2.47498","22567.20703"
"29.80000","2.48341","22649.21484"
"29.90000","2.49175","22737.17578"
"30.00000","2.50009","22817.51758"
"30.10000","2.50843","22901.25195"
"30.20000","2.51668","22986.09766"
"30.30000","2.52502","23068.82812"
"30.40000","2.53336","23153.48047"
"30.50000","2.54170","23236.42188"
"30.60000","2.55013","23321.32617"
"30.70000","2.55838","23404.50000"
"30.80000","2.56672","23487.26172"
"30.90000","2.57506","23572.32227"
"31.00000","2.58340","23655.28320"
"31.10000","2.59174","23738.88867"
"31.20000","2.59998","23820.03125"
"31.30000","2.60842","23902.69531"
"31.40000","2.61666","23986.71094"
"31.50000","2.62500","24068.97461"
"31.60000","2.63344","24151.73438"
"31.70000","2.64168","24233.01562"
"31.80000","2.65002","24315.50195"
"31.90000","2.65836","24399.51562"
"32.00000","2.66670","24480.56836"
"32.10000","2.67514","24563.83594"
"32.20000","2.68338","24643.38477"
"32.30000","2.69172","24725.74414"
"32.40000","2.69997","24808.09766"
"32.50000","2.70840","24890.52930"
"32.60000","2.71674","24973.95898"
"32.70000","2.72508","25055.54883"
"32.80000","2.73342","25137.18945"
"32.90000","2.74167","25218.58789"
"33.00000","2.75010","25301.49219"
"33.10000","2.75844","25384.13477"
"33.20000","2.76669","25464.44922"
"33.30000","2.77512","25544.80664"
"33.40000","2.78337","25624.89453"
"33.50000","2.79171","25705.86133"
"33.60000","2.80005","25787.13867"
"33.70000","2.80839","25866.76562"
"33.80000","2.81673","25946.11328"
"33.90000","2.82507","26027.78711"
"34.00000","2.83341","26106.76562"
"34.10000","2.84175","26187.16602"
"34.20000","2.85009","26266.97461"
"34.30000","2.85843","26346.60547"
"34.40000","2.86667","26425.71094"
"34.50000","2.87501","26503.69141"
"34.60000","2.88335","26585.86523"
"34.70000","2.89169","26665.47852"
"34.80000","2.90003","26746.29102"
"34.90000","2.90837","26823.85156"
"35.00000","2.91680","26903.39453"
"35.10000","2.92505","26983.13086"
"35.20000","2.93339","27061.37305"
"35.30000","2.94173","27140.87891"
"35.40000","2.95007","27217.20312"
"35.50000","2.95841","27295.39844"
"35.60000","2.96666","27371.71289"
"35.70000","2.97500","27448.38086"
"35.80000","2.98334","27528.68555"
"35.90000","2.99177","27605.18750"
"36.00000","3.00011","27681.21094"
"36.10000","3.00836","27755.83789"
"36.20000","3.01670","27831.23633"
"36.30000","3.02504","27907.46094"
"36.40000","3.03338","27983.00977"
"36.50000","3.04172","28057.29297"
"36.60000","3.04996","28133.93750"
"36.70000","3.05840","28208.70898"
"36.80000","3.06674","28284.20117"
"36.90000","3.07508","28358.65625"
"37.00000","3.08341","28433.39062"
"37.10000","3.09175","28508.18359"
"37.20000","3.10009","28580.00977"
"37.30000","3.10834","28654.48047"
"37.40000","3.11668","28727.44141"
"37.50000","3.12502","28800.62695"
"37.60000","3.13327","28872.30273"
"37.70000","3.14170","28944.23828"
"37.80000","3.15004","29019.64258"
"37.90000","3.15847","29093.28125"
"38.00000","3.16681","29165.72070"
"38.10000","3.17515","29238.46289"
"38.20000","3.18349","29309.26758"
"38.30000","3.19174","29379.56250"
"38.40000","3.20017","29450.78516"
"38.50000","3.20842","29520.47266"
"38.60000","3.21676","29590.88672"
"38.70000","3.22510","29660.76758"
"38.80000","3.23335","29731.39648"
"38.90000","3.24169","29800.88281"
"39.00000","3.25003","29871.91016"
"39.10000","3.25836","29940.48828"
"39.20000","3.26671","30008.67969"
"39.30000","3.27504","30079.10938"
"39.40000","3.28338","30147.44531"
"39.50000","3.29172","30216.94141"
"39.60000","3.30006","30281.70508"
"39.70000","3.30840","30348.53906"
"39.80000","3.31665","30415.66406"
"39.90000","3.32508","30482.75195"
"40.00000","3.33342","30549.55859"
"40.10000","3.34176","30613.03125"
"40.20000","3.35001","30677.14648"
"40.30000","3.35835","30741.26758"
"40.40000","3.36669","30806.15430"
"40.50000","3.37503","30872.49609"
"40.60000","3.38337","30935.86914"
"40.70000","3.39171","30999.96484"
"40.80000","3.40005","31063.28516"
"40.90000","3.40839","31126.30469"
"41.00000","3.41673","31190.93555"
"41.10000","3.42507","31254.64258"
"41.20000","3.43341","31316.68945"
"41.30000","3.44175","31378.63281"
"41.40000","3.45009","31440.79102"
"41.50000","3.45833","31502.88672"
"41.60000","3.46677","31564.18750"
"41.70000","3.47501","31625.00781"
"41.80000","3.48335","31685.83008"
"41.90000","3.49169","31745.84766"
"42.00000","3.50003","31806.71875"
"42.10000","3.50847","31867.81055"
"42.20000","3.51671","31927.71289"
"42.30000","3.52505","31986.14062"
"42.40000","3.53339","32044.37500"
"42.50000","3.54173","32104.44531"
"42.60000","3.55007","32162.10547"
"42.70000","3.55841","32222.03516"
"42.80000","3.56675","32281.23828"
"42.90000","3.57509","32339.53125"
"43.00000","3.58343","32397.18750"
"43.10000","3.59177","32454.30859"
"43.20000","3.60002","32509.95898"
"43.30000","3.60845","32565.59766"
"43.40000","3.61670","32622.27148"
"43.50000","3.62504","32679.16992"
"43.60000","3.63338","32733.89648"
"43.70000","3.64172","32788.25781"
"43.80000","3.65006","32844.58984"
"43.90000","3.65840","32898.78516"
"44.00000","3.66674","32952.64062"
"44.10000","3.67508","33007.18359"
"44.20000","3.68332","33062.33203"
"44.30000","3.69176","33114.86719"
"44.40000","3.70000","33169.08594"
"44.50000","3.70844","33223.59766"
"44.60000","3.71678","33276.69531"
"44.70000","3.72512","33329.77734"
"44.80000","3.73346","33382.43750"
"44.90000","3.74180","33433.80859"
"45.00000","3.75014","33485.01562"
"45.10000","3.75838","33536.44141"
"45.20000","3.76672","33587.67188"
"45.30000","3.77506","33638.66406"
"45.40000","3.78340","33688.79688"
"45.50000","3.79174","33739.30469"
"45.60000","3.80008","33789.08203"
"45.70000","3.80842","33839.62109"
"45.80000","3.81676","33892.19531"
"45.90000","3.82510","33939.67578"
"46.00000","3.83344","33988.83984"
"46.10000","3.84178","34038.20312"
"46.20000","3.85003","34086.38672"
"46.30000","3.85837","34134.37500"
"46.40000","3.86671","34181.09766"
"46.50000","3.87505","34229.25781"
"46.60000","3.88339","34277.70703"
"46.70000","3.89173","34323.78906"
"46.80000","3.90007","34373.10938"
"46.90000","3.90850","34419.30078"
"47.00000","3.91684","34465.69141"
"47.10000","3.92509","34512.25000"
"47.20000","3.93343","34557.51953"
"47.30000","3.94177","34603.58203"
"47.40000","3.95001","34647.67578"
"47.50000","3.95835","34691.57031"
"47.60000","3.96669","34735.81641"
"47.70000","3.97503","34778.85156"
"47.80000","3.98337","34824.79297"
"47.90000","3.99171","34867.60156"
"48.00000","4.00015","34912.47656"
"48.10000","4.00839","34955.46875"
"48.20000","4.01673","34996.74609"
"48.30000","4.02498","35039.75000"
"48.40000","4.03341","35080.78125"
"48.50000","4.04175","35123.46875"
"48.60000","4.05009","35164.78125"
"48.70000","4.05843","35205.94531"
"48.80000","4.06677","35247.94141"
"48.90000","4.07511","35288.20312"
"49.00000","4.08345","35330.04688"
"49.10000","4.09179","35368.57422"
"49.20000","4.10013","35409.43359"
"49.30000","4.10828","35448.90234"
"49.40000","4.11672","35487.87500"
"49.50000","4.12506","35527.53125"
"49.60000","4.13340","35564.87109"
"49.70000","4.14183","35606.01953"
"49.80000","4.15008","35646.29688"
"49.90000","4.15851","35681.64844"
"50.00000","4.16685","35721.59766"
"50.10000","4.17519","35758.59375"
"50.20000","4.18353","35796.65234"
"50.30000","4.19178","35833.19531"
"50.40000","4.20012","35869.48828"
"50.50000","4.20836","35907.17578"
"50.60000","4.21670","35942.88672"
"50.70000","4.22514","35979.14062"
"50.80000","4.23338","36016.04297"
"50.90000","4.24182","36052.68750"
"51.00000","4.25006","36088.94141"
"51.10000","4.25840","36122.81250"
"51.20000","4.26674","36158.63281"
"51.30000","4.27508","36193.22656"
"51.40000","4.28342","36227.62891"
"51.50000","4.29167","36261.38672"
"51.60000","4.30010","36293.82422"
"51.70000","4.30844","36327.28906"
"51.80000","4.31669","36360.69922"
"51.90000","4.32512","36393.72266"
"52.00000","4.33337","36427.10938"
"52.10000","4.34171","36460.24609"
"52.20000","4.35005","36492.11719"
"52.30000","4.35839","36523.75781"
"52.40000","4.36673","36554.37109"
"52.50000","4.37497","36587.79688"
"52.60000","4.38341","36619.17578"
"52.70000","4.39175","36650.58203"
"52.80000","4.40009","36679.54297"
"52.90000","4.40852","36710.94531"
"53.00000","4.41677","36742.32031"
"53.10000","4.42511","36771.29297"
"53.20000","4.43345","36802.08203"
"53.30000","4.44179","36830.94531"
"53.40000","4.45013","36860.04688"
"53.50000","4.45837","36888.26953"
"53.60000","4.46680","36915.87891"
"53.70000","4.47505","36944.56641"
"53.80000","4.48339","36972.48438"
"53.90000","4.49173","37000.22656"
"54.00000","4.50007","37027.51562"
"54.10000","4.50841","37055.92578"
"54.20000","4.51666","37085.64062"
"54.30000","4.52509","37112.51562"
"54.40000","4.53343","37140.45703"
"54.50000","4.54168","37166.77734"
"54.60000","4.55011","37193.00781"
"54.70000","4.55836","37219.59766"
"54.80000","4.56679","37245.82812"
"54.90000","4.57513","37273.91406"
"55.00000","4.58347","37299.55859"
"55.10000","4.59181","37323.81641"
"55.20000","4.60006","37349.21094"
"55.30000","4.60840","37375.01172"
"55.40000","4.61674","37399.98047"
"55.50000","4.62508","37422.92969"
"55.60000","4.63342","37447.78516"
"55.70000","4.64166","37472.09766"
"55.80000","4.65009","37495.94922"
"55.90000","4.65843","37518.37500"
"56.00000","4.66678","37542.21094"
"56.10000","4.67502","37567.16016"
"56.20000","4.68336","37590.15234"
"56.30000","4.69170","37613.14844"
"56.40000","4.70004","37636.39844"
"56.50000","4.70847","37657.65625"
"56.60000","4.71681","37681.18750"
"56.70000","4.72515","37702.90234"
"56.80000","4.73349","37726.67969"
"56.90000","4.74183","37749.16016"
"57.00000","4.75017","37769.43750"
"57.10000","4.75842","37790.95312"
"57.20000","4.76676","37810.99219"
"57.30000","4.77510","37833.96094"
"57.40000","4.78335","37856.28125"
"57.50000","4.79178","37875.54688"
"57.60000","4.80012","37896.30469"
"57.70000","4.80846","37917.39453"
"57.80000","4.81680","37938.51953"
"57.90000","4.82514","37956.76562"
"58.00000","4.83348","37977.26953"
"58.10000","4.84172","37996.62891"
"58.20000","4.85006","38016.25781"
"58.30000","4.85840","38036.11328"
"58.40000","4.86674","38055.76172"
"58.50000","4.87508","38074.02734"
"58.60000","4.88342","38092.67188"
"58.70000","4.89176","38110.81250"
"58.80000","4.90010","38130.96094"
"58.90000","4.90854","38149.52734"
"59.00000","4.91688","38167.72266"
"59.10000","4.92512","38184.71094"
"59.20000","4.93346","38202.97266"
"59.30000","4.94171","38221.84766"
"59.40000","4.95005","38239.08984"
"59.50000","4.95839","38257.57422"
"59.60000","4.96673","38272.68750"
"59.70000","4.97507","38293.03516"
"59.80000","4.98341","38309.00781"
"59.90000","4.99175","38324.67188"
"60.00000","5.00009","38343.01172"
"60.10000","5.00843","38358.44531"
"60.20000","5.01677","38374.81250"
"60.30000","5.02502","38390.79297"
"60.40000","5.03345","38407.28516"
"60.50000","5.04179","38422.15625"
"60.60000","5.05013","38437.07031"
"60.70000","5.05847","38454.08203"
"60.80000","5.06681","38470.17969"
"60.90000","5.07515","38486.09375"
"61.00000","5.08349","38500.84375"
"61.10000","5.09183","38515.08203"
"61.20000","5.10017","38529.94922"
"61.30000","5.10841","38545.84375"
"61.40000","5.11675","38561.13672"
"61.50000","5.12509","38575.92578"
"61.60000","5.13343","38589.28906"
"61.70000","5.14187","38605.94141"
"61.80000","5.15021","38616.93359"
"61.90000","5.15864","38631.48438"
"62.00000","5.16679","38645.37500"
"62.10000","5.17513","38658.25781"
"62.20000","5.18347","38672.34375"
"62.30000","5.19172","38685.78906"
"62.40000","5.20006","38699.29297"
"62.50000","5.20840","38712.95703"
"62.60000","5.21674","38724.97656"
"62.70000","5.22508","38740.04297"
"62.80000","5.23342","38752.29688"
"62.90000","5.24185","38765.63672"
"63.00000","5.25010","38778.75000"
"63.10000","5.25844","38790.61719"
"63.20000","5.26678","38803.84375"
"63.30000","5.27512","38816.31641"
"63.40000","5.28346","38828.28906"
"63.50000","5.29170","38839.22656"
"63.60000","5.30004","38849.53125"
"63.70000","5.30838","38865.00781"
"63.80000","5.31682","38874.35938"
"63.90000","5.32516","38887.23438"
"64.00000","5.33340","38897.50391"
"64.10000","5.34174","38909.85938"
"64.20000","5.34999","38922.20703"
"64.30000","5.35842","38932.48828"
"64.40000","5.36676","38943.86719"
"64.50000","5.37510","38953.96484"
"64.60000","5.38344","38963.72656"
"64.70000","5.39169","38975.61719"
"64.80000","5.40012","38986.95703"
"64.90000","5.40846","38998.92188"
"65.00000","5.41680","39007.58594"
"65.10000","5.42514","39019.21875"
"65.20000","5.43339","39030.04688"
"65.30000","5.44182","39040.05469"
"65.40000","5.45016","39050.86328"
"65.50000","5.45850","39058.35156"
"65.60000","5.46684","39068.23828"
"65.70000","5.47509","39079.15625"
"65.80000","5.48343","39086.15625"
"65.90000","5.49177","39098.53125"
"66.00000","5.50011","39107.30859"
"66.10000","5.50845","39117.51562"
"66.20000","5.51669","39127.62109"
"66.30000","5.52513","39136.29688"
"66.40000","5.53337","39147.00391"
"66.50000","5.54181","39154.35938"
"66.60000","5.55015","39163.94141"
"66.70000","5.55839","39172.03516"
"66.80000","5.56683","39180.98047"
"66.90000","5.57507","39190.73828"
"67.00000","5.58341","39199.10156"
"67.10000","5.59185","39209.17969"
"67.20000","5.60009","39217.54688"
"67.30000","5.60843","39227.88281"
"67.40000","5.61677","39235.81641"
"67.50000","5.62511","39242.84766"
"67.60000","5.63345","39250.51953"
"67.70000","5.64179","39258.45312"
"67.80000","5.65013","39265.77734"
"67.90000","5.65847","39272.60938"
"68.00000","5.66681","39280.76172"
"68.10000","5.67515","39288.88672"
"68.20000","5.68340","39295.69922"
"68.30000","5.69174","39304.21875"
"68.40000","5.70008","39311.35156"
"68.50000","5.70851","39318.49219"
"68.60000","5.71676","39324.53516"
"68.70000","5.72519","39330.99219"
"68.80000","5.73353","39339.91016"
"68.90000","5.74178","39346.66406"
"69.00000","5.75012","39353.04688"
"69.10000","5.75836","39359.90625"
"69.20000","5.76680","39366.42969"
"69.30000","5.77504","39374.78125"
"69.40000","5.78338","39382.69141"
"69.50000","5.79182","39389.60547"
"69.60000","5.80006","39396.58203"
"69.70000","5.80850","39403.22266"
"69.80000","5.81684","39409.01172"
"69.90000","5.82518","39414.49609"
"70.00000","5.83352","39421.71094"
"70.10000","5.84176","39426.56250"
"70.20000","5.85010","39432.74219"
"70.30000","5.85844","39439.26953"
"70.40000","5.86669","39444.84375"
"70.50000","5.87512","39450.98828"
"70.60000","5.88346","39456.89844"
"70.70000","5.89189","39463.97656"
"70.80000","5.90014","39469.96484"
"70.90000","5.90848","39473.87500"
"71.00000","5.91682","39479.92188"
"71.10000","5.92507","39486.35938"
"71.20000","5.93341","39492.90234"
"71.30000","5.94165","39498.99609"
"71.40000","5.95009","39503.71484"
"71.50000","5.95833","39508.38281"
"71.60000","5.96677","39514.28906"
"71.70000","5.97511","39520.09766"
"71.80000","5.98345","39523.98438"
"71.90000","5.99179","39529.07422"
"72.00000","6.00003","39533.96484"
"72.10000","6.00837","39537.66406"
"72.20000","6.01671","39543.57031"
"72.30000","6.02505","39549.53516"
"72.40000","6.03349","39553.26562"
"72.50000","6.04173","39557.46875"
"72.60000","6.05017","39560.31250"
"72.70000","6.05851","39565.54688"
"72.80000","6.06684","39571.42578"
"72.90000","6.07518","39575.53125"
"73.00000","6.08343","39579.24219"
"73.10000","6.09177","39583.01562"
"73.20000","6.10002","39587.79688"
"73.30000","6.10836","39592.33984"
"73.40000","6.11679","39598.05859"
"73.50000","6.12513","39600.92188"
"73.60000","6.13347","39606.35547"
"73.70000","6.14181","39609.63672"
"73.80000","6.15024","39611.71484"
"73.90000","6.15858","39616.00391"
"74.00000","6.16683","39618.70312"
"74.10000","6.17508","39622.26172"
"74.20000","6.18342","39626.21094"
"74.30000","6.19166","39629.17969"
"74.40000","6.20010","39632.92969"
"74.50000","6.20834","39636.33203"
"74.60000","6.21677","39639.63281"
"74.70000","6.22502","39644.48438"
"74.80000","6.23346","39648.00000"
"74.90000","6.24180","39651.62500"
"75.00000","6.25013","39653.33984"
"75.10000","6.25848","39656.65234"
"75.20000","6.26672","39661.02734"
"75.30000","6.27506","39663.63281"
"75.40000","6.28340","39666.44531"
"75.50000","6.29174","39667.39062"
"75.60000","6.30017","39672.37891"
"75.70000","6.30842","39673.16016"
"75.80000","6.31676","39674.80078"
"75.90000","6.32510","39680.19531"
"76.00000","6.33344","39681.62500"
"76.10000","6.34178","39683.37109"
"76.20000","6.35003","39686.05469"
"76.30000","6.35846","39688.79297"
"76.40000","6.36671","39690.50000"
"76.50000","6.37514","39691.78516"
"76.60000","6.38348","39695.00000"
"76.70000","6.39173","39695.75391"
"76.80000","6.40016","39698.93359"
"76.90000","6.40850","39700.68359"
"77.00000","6.41684","39701.05469"
"77.10000","6.42518","39702.70312"
"77.20000","6.43342","39703.53906"
"77.30000","6.44176","39704.70312"
"77.40000","6.45011","39707.03125"
"77.50000","6.45845","39707.53125"
"77.60000","6.46678","39711.32812"
"77.70000","6.47512","39709.29297"
"77.80000","6.48346","39712.12109"
"77.90000","6.49171","39713.35547"
"78.00000","6.50014","39714.33203"
"78.10000","6.50848","39716.29297"
"78.20000","6.51673","39715.78125"
"78.30000","6.52516","39716.69531"
"78.40000","6.53341","39717.07031"
"78.50000","6.54184","39716.88281"
"78.60000","6.55018","39718.23438"
"78.70000","6.55852","39716.50391"
"78.80000","6.56686","39716.75000"
"78.90000","6.57511","39715.13672"
"79.00000","6.58345","39714.14062"
"79.10000","6.59179","39715.48047"
"79.20000","6.60013","39715.30078"
"79.30000","6.60847","39715.46484"
"79.40000","6.61671","39713.40625"
"79.50000","6.62505","39712.21484"
"79.60000","6.63339","39712.78906"
"79.70000","6.64183","39709.08203"
"79.80000","6.65017","39708.50781"
"79.90000","6.65841","39705.69922"
"80.00000","6.66675","39703.91016"
"80.10000","6.67509","39701.47266"
"80.20000","6.68343","39698.30859"
"80.30000","6.69177","39696.98438"
"80.40000","6.70011","39693.38281"
"80.50000","6.70855","39689.40234"
"80.60000","6.71679","39684.61328"
"80.70000","6.72523","39681.21094"
"80.80000","6.73347","39676.94531"
"80.90000","6.74181","39671.37500"
"81.00000","6.75015","39668.48828"
"81.10000","6.75840","39664.58594"
"81.20000","6.76683","39661.00781"
"81.30000","6.77517","39657.12500"
"81.40000","6.78351","39649.75391"
"81.50000","6.79176","39644.98047"
"81.60000","6.80010","39640.37109"
"81.70000","6.80853","39632.61328"
"81.80000","6.81678","39626.76953"
"81.90000","6.82512","39618.05469"
"82.00000","6.83346","39610.26953"
"82.10000","6.84170","39602.61719"
"82.20000","6.85004","39596.35156"
"82.30000","6.85838","39587.69531"
"82.40000","6.86682","39577.31250"
"82.50000","6.87516","39568.76172"
"82.60000","6.88350","39558.08984"
"82.70000","6.89193","39548.43750"
"82.80000","6.90018","39537.64453"
"82.90000","6.90852","39524.19141"
"83.00000","6.91676","39512.04297"
"83.10000","6.92510","39500.55078"
"83.20000","6.93344","39489.62109"
"83.30000","6.94169","39477.78906"
"83.40000","6.95012","39463.82812"
"83.50000","6.95837","39451.07031"
"83.60000","6.96680","39437.48828"
"83.70000","6.97514","39422.78516"
"83.80000","6.98348","39408.30078"
"83.90000","6.99182","39393.69922"
"84.00000","7.00007","39378.63281"
"84.10000","7.00841","39362.21094"
"84.20000","7.01675","39347.03125"
"84.30000","7.02509","39330.25000"
"84.40000","7.03352","39313.56250"
"84.50000","7.04177","39294.98828"
"84.60000","7.05020","39276.74609"
"84.70000","7.05845","39259.89453"
"84.80000","7.06679","39238.57812"
"84.90000","7.07513","39221.99219"
"85.00000","7.08347","39203.18750"
"85.10000","7.09181","39184.58594"
"85.20000","7.10005","39166.87500"
"85.30000","7.10849","39147.84375"
"85.40000","7.11683","39127.37891"
"85.50000","7.12517","39106.46875"
"85.60000","7.13360","39085.10938"
"85.70000","7.14185","39062.29297"
"85.80000","7.15019","39038.80078"
"85.90000","7.15843","39016.14062"
"86.00000","7.16677","38993.44922"
"86.10000","7.17511","38970.33203"
"86.20000","7.18336","38947.56250"
"86.30000","7.19170","38923.42188"
"86.40000","7.20013","38899.62891"
"86.50000","7.20847","38875.29297"
"86.60000","7.21681","38851.72656"
"86.70000","7.22515","38828.17188"
"86.80000","7.23349","38801.00391"
"86.90000","7.24183","38774.28516"
"87.00000","7.25017","38746.63672"
"87.10000","7.25851","38721.49219"
"87.20000","7.26676","38694.51562"
"87.30000","7.27519","38667.65625"
"87.40000","7.28344","38639.21875"
"87.50000","7.29178","38611.96875"
"87.60000","7.30012","38585.78125"
"87.70000","7.30846","38554.71484"
"87.80000","7.31680","38527.26562"
"87.90000","7.32504","38497.50781"
"88.00000","7.33348","38466.81250"
"88.10000","7.34182","38436.67969"
"88.20000","7.35006","38405.44922"
"88.30000","7.35850","38373.32812"
"88.40000","7.36674","38342.99219"
"88.50000","7.37518","38311.21484"
"88.60000","7.38352","38281.22656"
"88.70000","7.39186","38248.33203"
"88.80000","7.40020","38214.01953"
"88.90000","7.40844","38179.10156"
"89.00000","7.41678","38147.11719"
"89.10000","7.42512","38115.64453"
"89.20000","7.43346","38081.81250"
"89.30000","7.44190","38046.21875"
"89.40000","7.45014","38009.98047"
"89.50000","7.45848","37976.57812"
"89.60000","7.46682","37940.85547"
"89.70000","7.47516","37905.18359"
"89.80000","7.48350","37868.16797"
"89.90000","7.49175","37830.78906"
"90.00000","7.50009","37794.18750"
"90.10000","7.50843","37756.17188"
"90.20000","7.51677","37719.46875"
"90.30000","7.52520","37680.34375"
"90.40000","7.53354","37640.51562"
"90.50000","7.54188","37601.21875"
"90.60000","7.55013","37562.04688"
"90.70000","7.55856","37521.67969"
"90.80000","7.56681","37480.09766"
"90.90000","7.57515","37436.55078"
"91.00000","7.58349","37395.61328"
"91.10000","7.59173","37354.43359"
"91.20000","7.60017","37311.71094"
"91.30000","7.60851","37269.69531"
"91.40000","7.61685","37223.22656"
"91.50000","7.62519","37182.11328"
"91.60000","7.63343","37134.23438"
"91.70000","7.64186","37088.57031"
"91.80000","7.65011","37042.00000"
"91.90000","7.65855","36993.37109"
"92.00000","7.66679","36946.27344"
"92.10000","7.67513","36898.80078"
"92.20000","7.68347","36848.51172"
"92.30000","7.69181","36796.07031"
"92.40000","7.70024","36740.48047"
"92.50000","7.70858","36683.91016"
"92.60000","7.71683","36612.09375"
"92.70000","7.72751","35823.28906"
"92.71600","7.73004","21851.29883"