File: Lab 5/Polymer Data/G1-2/100924 HDPE 300N creep_1_G12_1.is_trelax_RawData/Specimen_RawData_1.csv
Time,Extension,Load
(s),(mm),(N)
"0.00000","0.00000","0.19651"
"0.30000","0.09155","17.64090"
"0.60000","0.26004","92.38381"
"0.90000","0.33650","132.93697"
"1.20000","0.42224","175.67256"
"1.50000","0.51632","220.09558"
"1.80000","0.61490","265.04980"
"2.03200","0.69408","300.29410"
"2.23400","0.71939","307.66394"
"2.53400","0.73175","302.04556"
"2.83400","0.74300","300.41769"
"3.13400","0.75387","300.34293"
"3.43400","0.76540","300.19882"
"3.73400","0.77523","299.77335"
"4.03400","0.78432","300.62939"
"4.33400","0.79201","300.53555"
"4.63400","0.79875","300.66006"
"4.93400","0.80606","301.06128"
"5.23400","0.81365","300.12000"
"5.53400","0.82021","300.22351"
"5.83400","0.82593","300.01840"
"6.13400","0.83221","300.15042"
"6.43400","0.83802","300.08524"
"6.73400","0.84355","299.31757"
"7.03400","0.84917","299.65747"
"7.33400","0.85395","300.05811"
"7.63400","0.85891","299.96463"
"7.93400","0.86397","300.16943"
"8.23400","0.86885","299.77768"
"8.53400","0.87260","300.29718"
"8.83400","0.87616","300.38330"
"9.13400","0.88037","299.16232"
"9.43400","0.88412","299.90970"
"9.73400","0.88853","300.22739"
"10.03400","0.89284","300.06400"
"10.33400","0.89696","299.96799"
"10.63400","0.89977","300.28424"
"10.93400","0.90408","300.18423"
"11.23400","0.90727","300.32703"
"11.53400","0.91102","300.72369"
"11.83400","0.91514","299.34036"
"12.13400","0.91823","299.45981"
"12.43400","0.92114","299.78143"
"12.73400","0.92404","299.97733"
"13.03400","0.92807","300.04611"
"13.33400","0.93144","300.04474"
"13.63400","0.93425","299.94516"
"13.93400","0.93716","300.16241"
"14.23400","0.94110","299.78064"
"14.53400","0.94409","299.91327"
"14.83400","0.94691","300.38644"
"15.13400","0.94962","301.14117"
"15.43400","0.95225","300.07803"
"15.73400","0.95515","299.98743"
"16.03400","0.95749","299.95065"
"16.33400","0.95993","300.09082"
"16.63400","0.96209","299.58377"
"16.93400","0.96471","300.70053"
"17.23400","0.96743","299.92847"
"17.53400","0.97099","300.35956"
"17.83400","0.97417","299.11121"
"18.13400","0.97567","300.72543"
"18.43400","0.97867","299.50824"
"18.73400","0.98073","300.50436"
"19.03400","0.98261","299.59100"
"19.33400","0.98514","301.10538"
"19.63400","0.98776","300.14996"
"19.93400","0.98964","299.94171"
"20.23400","0.99273","299.32474"
"20.53400","0.99460","300.63919"
"20.83400","0.99638","299.98178"
"21.13400","0.99957","300.10361"
"21.43400","1.00107","300.19855"
"21.73400","1.00285","300.65948"
"22.03400","1.00566","299.69391"
"22.33400","1.00753","300.53244"
"22.63400","1.00950","300.02625"
"22.93400","1.01203","299.82648"
"23.23400","1.01447","299.63065"
"23.53400","1.01662","299.94785"
"23.83400","1.01878","299.99860"
"24.13400","1.02028","299.93301"
"24.43400","1.02243","299.64578"
"24.73400","1.02459","300.24335"
"25.03400","1.02627","299.90512"
"25.33400","1.02815","300.30545"
"25.63400","1.03021","299.90854"
"25.93400","1.03218","300.86557"
"26.23400","1.03461","299.87573"
"26.53400","1.03546","300.65585"
"26.83400","1.03761","300.23499"
"27.13400","1.03892","300.13925"
"27.43400","1.04099","300.38858"
"27.73400","1.04230","300.43097"
"28.03400","1.04417","299.35413"
"28.33400","1.04577","300.97302"
"28.63400","1.04764","299.36923"
"28.93400","1.04942","299.68240"
"29.23400","1.05036","300.59344"
"29.53400","1.05317","300.31979"
"29.83400","1.05485","299.93378"
"30.13400","1.05682","299.53244"
"30.43400","1.05823","300.25058"
"30.73400","1.05945","299.82117"
"31.03400","1.06141","299.19537"
"31.33400","1.06291","300.21857"
"31.63400","1.06432","299.91043"
"31.93400","1.06610","301.56082"
"32.23400","1.06722","299.46817"
"32.53400","1.06910","299.59756"
"32.83400","1.07125","299.54044"
"33.13400","1.07247","299.98734"
"33.43400","1.07425","299.66272"
"33.73400","1.07556","300.88116"
"34.03400","1.07734","299.40472"
"34.33400","1.07828","299.99634"
"34.63400","1.07950","299.55145"
"34.93400","1.08184","300.25864"
"35.23400","1.08306","299.27423"
"35.53400","1.08428","300.46100"
"35.83400","1.08540","300.14728"
"36.13400","1.08700","300.44397"
"36.43400","1.08915","299.60519"
"36.73400","1.09028","299.48355"
"37.03400","1.09149","299.93097"
"37.33400","1.09318","299.60648"
"37.63400","1.09505","299.90509"
"37.93400","1.09637","300.23300"
"38.23400","1.09730","299.62228"
"38.53400","1.09880","300.06241"
"38.83400","1.10021","300.35965"
"39.13400","1.10133","300.38425"
"39.43400","1.10274","299.61938"
"39.73400","1.10433","300.42862"
"40.03400","1.10564","300.08658"
"40.33400","1.10705","300.15195"
"40.63400","1.10911","299.67691"
"40.93400","1.11061","300.16797"
"41.23400","1.11173","300.33014"
"41.53400","1.11295","299.68076"
"41.83400","1.11398","299.76212"
"42.13400","1.11520","300.95117"
"42.43400","1.11670","300.36041"
"42.73400","1.11792","300.79544"
"43.03400","1.11914","299.02545"
"43.33400","1.12045","299.81189"
"43.63400","1.12148","300.08472"
"43.93400","1.12345","299.55798"
"44.23400","1.12354","300.24023"
"44.53400","1.12513","299.43591"
"44.83400","1.12532","300.13501"
"45.13400","1.12729","299.89951"
"45.43400","1.12832","300.75122"
"45.73400","1.12916","300.18301"
"46.03400","1.13113","299.68814"
"46.33400","1.13169","300.42819"
"46.63400","1.13282","300.49875"
"46.93400","1.13488","299.94153"
"47.23400","1.13666","300.15302"
"47.53400","1.13685","299.20145"
"47.83400","1.13807","300.10742"
"48.13400","1.13957","300.21600"
"48.43400","1.14106","300.03748"
"48.73400","1.14191","299.73923"
"49.03400","1.14369","299.70459"
"49.33400","1.14434","301.08694"
"49.63400","1.14519","300.64639"
"49.93400","1.14734","300.07526"
"50.23400","1.14781","299.89523"
"50.53400","1.14931","299.48209"
"50.83400","1.14959","300.12247"
"51.13400","1.15165","300.27130"
"51.43400","1.15278","300.15277"
"51.73400","1.15381","300.43311"
"52.03400","1.15465","300.50812"
"52.33400","1.15550","299.70905"
"52.63400","1.15662","299.79974"
"52.93400","1.15784","299.97748"
"53.23400","1.15878","300.12891"
"53.53400","1.15971","300.02170"
"53.83400","1.16065","299.54984"
"54.13400","1.16234","299.62558"
"54.43400","1.16290","300.75552"
"54.73400","1.16365","300.16232"
"55.03400","1.16487","300.22354"
"55.33400","1.16665","300.26929"
"55.63400","1.16693","299.94052"
"55.93400","1.16815","299.76962"
"56.23400","1.16936","299.57700"
"56.53400","1.16983","301.02734"
"56.83400","1.17105","299.97375"
"57.13400","1.17189","299.84390"
"57.43400","1.17339","300.32581"
"57.73400","1.17499","299.77692"
"58.03400","1.17536","299.86636"
"58.33400","1.17677","300.11780"
"58.63400","1.17686","300.19141"
"58.93400","1.17883","300.21869"
"59.23400","1.17930","299.86658"
"59.53400","1.17986","299.56598"
"59.83400","1.18117","299.73154"
"60.13400","1.18295","300.04501"
"60.43400","1.18333","300.09085"
"60.73400","1.18473","299.89023"
"61.03400","1.18511","299.96448"
"61.33400","1.18614","300.67310"
"61.63400","1.18707","299.65646"
"61.93400","1.18773","299.77985"
"62.23400","1.18923","299.70526"
"62.53400","1.19035","299.58560"
"62.83400","1.19157","299.91284"
"63.13400","1.19223","299.90915"
"63.43400","1.19279","299.72406"
"63.73400","1.19363","300.64877"
"64.03400","1.19485","299.96957"
"64.33400","1.19560","300.02911"
"64.63400","1.19720","299.45169"
"64.93400","1.19720","300.44232"
"65.23400","1.19813","299.29486"
"65.53400","1.19944","299.75351"
"65.83400","1.20029","300.17740"
"66.13400","1.20104","300.13626"
"66.43400","1.20188","300.14059"
"66.73400","1.20263","300.29889"
"67.03400","1.20329","299.81747"
"67.33400","1.20432","300.86819"
"67.63400","1.20507","299.94928"
"67.93400","1.20610","300.63205"
"68.23400","1.20657","299.56271"
"68.53400","1.20769","300.24814"
"68.83400","1.20835","299.59515"
"69.13400","1.20994","299.97372"
"69.43400","1.21031","300.28479"
"69.73400","1.21106","300.45618"
"70.03400","1.21228","299.35208"
"70.33400","1.21303","300.22006"
"70.63400","1.21341","300.35345"
"70.93400","1.21322","300.24216"
"71.23400","1.21453","299.03186"
"71.53400","1.21537","299.44003"
"71.83400","1.21669","299.30273"
"72.13400","1.21753","299.60663"
"72.43400","1.21865","299.37729"
"72.73400","1.21987","299.82544"
"73.03400","1.22062","300.09171"
"73.33400","1.22175","300.17853"
"73.63400","1.22212","299.84653"
"73.93400","1.22315","300.11890"
"74.23400","1.22362","300.45392"
"74.53400","1.22428","299.32355"
"74.83400","1.22540","299.56467"
"75.13400","1.22634","299.47824"
"75.43400","1.22653","300.19229"
"75.73400","1.22737","300.05753"
"76.03400","1.22859","299.41345"
"76.33400","1.22943","300.01044"
"76.63400","1.23009","299.13824"
"76.93400","1.23055","299.87109"
"77.23400","1.23121","300.58298"
"77.53400","1.23215","300.39807"
"77.83400","1.23327","300.83691"
"78.13400","1.23421","299.56097"
"78.43400","1.23515","299.44067"
"78.73400","1.23552","300.79892"
"79.03400","1.23627","299.80399"
"79.33400","1.23674","299.49683"
"79.63400","1.23786","300.01044"
"79.93400","1.23861","299.48300"
"80.23400","1.23899","300.21539"
"80.53400","1.24002","299.98553"
"80.83400","1.24152","300.08649"
"81.13400","1.24161","300.61359"
"81.43400","1.24255","300.04269"
"81.73400","1.24302","299.79022"
"82.03400","1.24424","300.06622"
"82.33400","1.24442","300.03073"
"82.63400","1.24508","299.73224"
"82.93400","1.24602","299.48276"
"83.23400","1.24714","300.03909"
"83.53400","1.24770","300.41760"
"83.83400","1.24845","299.96591"
"84.13400","1.24920","299.64856"
"84.43400","1.24995","300.00302"
"84.73400","1.25051","299.67230"
"85.03400","1.25108","300.50827"
"85.33400","1.25155","301.10117"
"85.63400","1.25314","299.31436"
"85.93400","1.25361","300.57816"
"86.23400","1.25454","299.71637"
"86.53400","1.25482","300.22733"
"86.83400","1.25632","300.03113"
"87.13400","1.25632","299.77325"
"87.43400","1.25726","300.04813"
"87.73400","1.25801","299.35889"
"88.03400","1.25914","300.46265"
"88.33400","1.25942","300.57138"
"88.63400","1.26026","299.74728"
"88.93400","1.26063","299.86926"
"89.23400","1.26157","299.99152"
"89.53400","1.26213","300.20490"
"89.83400","1.26298","300.16547"
"90.13400","1.26420","299.93460"
"90.43400","1.26495","300.26328"
"90.73400","1.26485","300.51062"
"91.03400","1.26569","299.60519"
"91.33400","1.26673","299.98083"
"91.63400","1.26766","300.05417"
"91.93400","1.26748","299.89160"
"92.23400","1.26822","299.59973"
"92.53400","1.26879","299.52753"
"92.83400","1.26963","299.58514"
"93.13400","1.27010","299.68127"
"93.43400","1.27169","300.25146"
"93.73400","1.27207","300.16531"
"94.03400","1.27244","299.98044"
"94.33400","1.27366","299.38254"
"94.63400","1.27422","299.85165"
"94.93400","1.27497","300.41150"
"95.23400","1.27544","299.97934"
"95.53400","1.27666","299.60510"
"95.83400","1.27694","300.44254"
"96.13400","1.27797","300.34055"
"96.43400","1.27853","300.25189"
"96.73400","1.27938","300.31839"
"97.03400","1.28013","300.11746"
"97.33400","1.27994","300.44653"
"97.63400","1.28088","299.57413"
"97.93400","1.28088","300.07678"
"98.23400","1.28237","300.03110"
"98.53400","1.28266","299.54614"
"98.83400","1.28387","300.38852"
"99.13400","1.28425","300.59180"
"99.43400","1.28453","300.02859"
"99.73400","1.28528","299.71417"
"100.03400","1.28603","299.92056"
"100.33400","1.28753","299.71402"
"100.63400","1.28800","299.45221"
"100.93400","1.28809","300.26843"
"101.23400","1.28865","300.82086"
"101.53400","1.28931","299.38565"
"101.83400","1.29043","299.53732"
"102.13400","1.29015","300.26492"
"102.43400","1.29100","299.77185"
"102.73400","1.29146","300.47794"
"103.03400","1.29184","300.40103"
"103.33400","1.29306","300.01089"
"103.63400","1.29343","299.28879"
"103.93400","1.29353","300.07724"
"104.23400","1.29484","299.87201"
"104.53400","1.29549","300.05371"
"104.83400","1.29587","299.72192"
"105.13400","1.29634","299.78210"
"105.43400","1.29718","300.95834"
"105.73400","1.29765","299.21793"
"106.03400","1.29812","299.60013"
"106.33400","1.29812","299.72516"
"106.63400","1.29915","301.16068"
"106.93400","1.29971","300.94382"
"107.23400","1.30046","299.55435"
"107.53400","1.30149","299.69000"
"107.83400","1.30168","300.70013"
"108.13400","1.30215","299.76285"
"108.43400","1.30262","300.19708"
"108.73400","1.30393","300.47073"
"109.03400","1.30393","300.78000"
"109.33400","1.30458","300.40305"
"109.63400","1.30561","299.92749"
"109.93400","1.30636","300.17700"
"110.23400","1.30721","299.41879"
"110.53400","1.30796","299.74567"
"110.83400","1.30908","299.53732"
"111.13400","1.30917","300.69687"
"111.43400","1.30964","299.83194"
"111.73400","1.31039","299.92227"
"112.03400","1.31105","299.70276"
"112.33400","1.31133","299.30127"
"112.63400","1.31142","299.91006"
"112.93400","1.31264","299.81067"
"113.23400","1.31358","300.57010"
"113.53400","1.31386","299.47992"
"113.83400","1.31498","299.53323"
"114.13400","1.31555","299.54126"
"114.43400","1.31620","299.55609"
"114.73400","1.31583","299.80933"
"115.03400","1.31592","299.70148"
"115.33400","1.31667","301.02826"
"115.63400","1.31751","299.33755"
"115.93400","1.31808","299.61029"
"116.23400","1.31958","299.41733"
"116.53400","1.31929","299.87604"
"116.83400","1.31976","300.31778"
"117.13400","1.32061","299.94083"
"117.43400","1.32089","300.14099"
"117.73400","1.32164","299.54266"
"118.03400","1.32136","299.99017"
"118.33400","1.32276","300.08234"
"118.63400","1.32276","299.68625"
"118.93400","1.32304","299.98907"
"119.23400","1.32445","300.02115"
"119.53400","1.32501","300.38409"
"119.83400","1.32492","300.32025"
"120.13400","1.32557","299.99673"
"120.43400","1.32660","299.76624"
"120.73400","1.32698","300.55447"
"121.03400","1.32717","300.09192"
"121.33400","1.32829","300.55270"
"121.63400","1.32932","299.75922"
"121.93400","1.32942","299.73871"
"122.23400","1.32932","299.83066"
"122.53400","1.33026","299.67938"
"122.83400","1.33091","300.42743"
"123.13400","1.33157","299.72498"
"123.43400","1.33129","300.54181"
"123.73400","1.33260","299.80069"
"124.03400","1.33307","300.19128"
"124.33400","1.33363","299.97797"
"124.63400","1.33382","300.26456"
"124.93400","1.33466","299.70111"
"125.23400","1.33513","300.63654"
"125.53400","1.33532","299.50305"
"125.83400","1.33616","299.83975"
"126.13400","1.33672","300.99292"
"126.43400","1.33701","300.34726"
"126.73400","1.33719","299.63574"
"127.03400","1.33785","300.13931"
"127.33400","1.33869","299.69235"
"127.63400","1.33879","300.19003"
"127.93400","1.33963","299.71072"
"128.23400","1.34029","300.02087"
"128.53400","1.34075","300.99390"
"128.83400","1.34085","299.61520"
"129.13400","1.34141","300.59238"
"129.43400","1.34160","299.73462"
"129.73400","1.34300","299.45242"
"130.03400","1.34366","299.84625"
"130.33400","1.34356","300.17627"
"130.63400","1.34403","300.37219"
"130.93400","1.34516","299.78772"
"131.23400","1.34600","299.97223"
"131.53400","1.34628","300.00546"
"131.83400","1.34666","300.04047"
"132.13400","1.34694","299.92062"
"132.43400","1.34816","300.04623"
"132.73400","1.34797","300.57437"
"133.03400","1.34825","300.35718"
"133.33400","1.34881","299.52481"
"133.63400","1.35003","300.79279"
"133.93400","1.34994","300.34351"
"134.23400","1.35022","299.79578"
"134.53400","1.35106","299.93399"
"134.83400","1.35125","300.35294"
"135.13400","1.35256","300.07028"
"135.43400","1.35275","299.98499"
"135.73400","1.35350","299.97324"
"136.03400","1.35350","299.99634"
"136.33400","1.35387","300.13403"
"136.63400","1.35453","299.70822"
"136.93400","1.35500","300.48196"
"137.23400","1.35565","300.14297"
"137.53400","1.35603","300.24936"
"137.83400","1.35565","300.37915"
"138.13400","1.35734","299.75049"
"138.43400","1.35809","299.60437"
"138.73400","1.35809","299.92685"
"139.03400","1.35875","300.03058"
"139.33400","1.35931","299.98349"
"139.63400","1.35987","299.60367"
"139.93400","1.35987","299.53616"
"140.23400","1.36071","299.60974"
"140.53400","1.36128","299.60132"
"140.83400","1.36137","299.83740"
"141.13400","1.36221","299.33041"
"141.43400","1.36221","300.72058"
"141.73400","1.36315","299.32700"
"142.03400","1.36427","299.76315"
"142.33400","1.36474","299.61563"
"142.63400","1.36549","299.65155"
"142.93400","1.36502","300.52286"
"143.23400","1.36577","299.64078"
"143.53400","1.36643","299.54272"
"143.83400","1.36727","299.47919"
"144.13400","1.36680","300.45685"
"144.43400","1.36765","299.52695"
"144.73400","1.36802","299.45435"
"145.03400","1.36868","300.13925"
"145.33400","1.36896","299.57220"
"145.63400","1.36962","299.56348"
"145.93400","1.36999","299.93500"
"146.23400","1.37074","298.78061"
"146.53400","1.37140","299.92026"
"146.83400","1.37149","299.93564"
"147.13400","1.37177","299.66696"
"147.43400","1.37233","300.19717"
"147.73400","1.37243","299.53491"
"148.03400","1.37271","300.00778"
"148.33400","1.37327","299.47229"
"148.63400","1.37364","299.88013"
"148.93400","1.37430","299.93829"
"149.23400","1.37486","300.17825"
"149.53400","1.37514","299.85153"
"149.83400","1.37561","300.13074"
"150.13400","1.37552","299.95938"
"150.43400","1.37636","300.15533"
"150.73400","1.37721","300.46060"
"151.03400","1.37711","300.15854"
"151.33400","1.37730","299.57596"
"151.63400","1.37824","299.95740"
"151.93400","1.37833","300.42535"
"152.23400","1.37852","300.22870"
"152.53400","1.38002","299.46051"
"152.83400","1.37945","300.48761"
"153.13400","1.37945","299.81052"
"153.43400","1.37974","299.77090"
"153.73400","1.38105","300.04333"
"154.03400","1.38124","299.83163"
"154.33400","1.38189","300.76883"
"154.63400","1.38170","301.17993"
"154.93400","1.38198","299.88358"
"155.23400","1.38302","301.11063"
"155.53400","1.38348","300.17960"
"155.83400","1.38451","299.95392"
"156.13400","1.38517","300.26935"
"156.43400","1.38536","300.03653"
"156.73400","1.38545","299.74646"
"157.03400","1.38564","301.06110"
"157.33400","1.38667","300.05899"
"157.63400","1.38751","299.57678"
"157.93400","1.38742","300.53052"
"158.23400","1.38845","299.31732"
"158.53400","1.38873","300.89865"
"158.83400","1.38883","299.52280"
"159.13400","1.38995","299.18085"
"159.43400","1.39004","300.15588"
"159.73400","1.39061","300.16943"
"160.03400","1.39089","299.82809"
"160.33400","1.39173","299.71667"
"160.63400","1.39220","299.93979"
"160.93400","1.39257","299.88599"
"161.23400","1.39257","299.91116"
"161.53400","1.39314","299.99585"
"161.83400","1.39389","299.36826"
"162.13400","1.39445","299.36560"
"162.43400","1.39454","299.88211"
"162.73400","1.39501","299.11240"
"163.03400","1.39520","300.21835"
"163.33400","1.39557","300.08090"
"163.63400","1.39576","299.87857"
"163.93400","1.39642","300.07422"
"164.23400","1.39651","300.58197"
"164.53400","1.39726","299.61243"
"164.83400","1.39745","300.50934"
"165.13400","1.39810","301.19711"
"165.43400","1.39838","299.38168"
"165.73400","1.39866","300.82312"
"166.03400","1.39951","299.70679"
"166.33400","1.39979","300.00665"
"166.63400","1.40091","300.38077"
"166.93400","1.40054","300.95493"
"167.23400","1.40119","299.32071"
"167.53400","1.40129","299.93735"
"167.83400","1.40223","299.92188"
"168.13400","1.40176","300.74716"
"168.43400","1.40260","300.24799"
"168.73400","1.40316","299.58441"
"169.03400","1.40382","301.17471"
"169.33400","1.40372","300.09732"
"169.63400","1.40410","299.52078"
"169.93400","1.40447","300.04373"
"170.23400","1.40466","300.12656"
"170.53400","1.40550","300.90030"
"170.83400","1.40625","300.24313"
"171.13400","1.40700","300.41479"
"171.43400","1.40747","300.08795"
"171.73400","1.40785","300.45117"
"172.03400","1.40794","300.22714"
"172.33400","1.40841","300.25110"
"172.63400","1.40841","299.77090"
"172.93400","1.40878","299.83591"
"173.23400","1.40907","299.79904"
"173.53400","1.40991","300.13391"
"173.83400","1.41028","300.38925"
"174.13400","1.41075","299.47430"
"174.43400","1.41113","300.20435"
"174.73400","1.41141","299.82025"
"175.03400","1.41188","299.74927"
"175.33400","1.41197","300.35150"
"175.63400","1.41216","300.47467"
"175.93400","1.41300","300.51294"
"176.23400","1.41347","299.95932"
"176.53400","1.41366","299.58774"
"176.83400","1.41403","299.70428"
"177.13400","1.41469","300.35019"
"177.43400","1.41506","299.55048"
"177.73400","1.41516","299.82077"
"178.03400","1.41572","299.94507"
"178.33400","1.41609","299.33496"
"178.63400","1.41637","300.10748"
"178.93400","1.41656","300.10483"
"179.23400","1.41712","300.07770"
"179.53400","1.41722","300.13940"
"179.83400","1.41778","300.45648"
"180.13400","1.41872","299.89813"
"180.43400","1.41872","300.21030"
"180.73400","1.41909","301.04459"
"181.03400","1.41881","300.29214"
"181.33400","1.41947","299.99573"
"181.63400","1.42003","299.58112"
"181.93400","1.42059","300.10043"
"182.23400","1.42097","299.62164"
"182.53400","1.42125","299.91705"
"182.83400","1.42218","300.07571"
"183.13400","1.42237","299.95901"
"183.43400","1.42265","299.39423"
"183.73400","1.42247","299.67508"
"184.03400","1.42322","299.53180"
"184.33400","1.42378","299.68961"
"184.63400","1.42471","299.96362"
"184.93400","1.42481","299.74896"
"185.23400","1.42471","299.96906"
"185.53400","1.42509","299.95444"
"185.83400","1.42565","299.65915"
"186.13400","1.42650","300.95773"
"186.43400","1.42650","300.38660"
"186.73400","1.42678","299.82025"
"187.03400","1.42687","300.09888"
"187.33400","1.42734","300.99551"
"187.63400","1.42771","299.78629"
"187.93400","1.42846","300.14471"
"188.23400","1.42940","299.42853"
"188.53400","1.42912","300.48227"
"188.83400","1.42931","299.66406"
"189.13400","1.43024","299.68076"
"189.43400","1.43062","300.56989"
"189.73400","1.43071","299.52039"
"190.03400","1.43127","300.33728"
"190.33400","1.43146","300.15250"
"190.63400","1.43193","299.93091"
"190.93400","1.43221","299.81238"
"191.23400","1.43259","300.11685"
"191.53400","1.43296","300.33295"
"191.83400","1.43343","299.76996"
"192.13400","1.43390","299.72754"
"192.43400","1.43371","300.10254"
"192.73400","1.43418","299.41257"
"193.03400","1.43446","300.65741"
"193.33400","1.43568","299.79449"
"193.63400","1.43587","299.44028"
"193.93400","1.43643","299.22229"
"194.23400","1.43652","299.56796"
"194.53400","1.43680","300.02307"
"194.83400","1.43708","300.86951"
"195.13400","1.43746","299.46548"
"195.43400","1.43774","300.18903"
"195.73400","1.43896","299.86658"
"196.03400","1.43915","299.58975"
"196.33400","1.43924","300.15857"
"196.63400","1.43980","299.72995"
"196.93400","1.44074","299.65945"
"197.23400","1.44027","300.94489"
"197.53400","1.44055","299.41885"
"197.83400","1.44158","299.61499"
"198.13400","1.44158","299.55832"
"198.43400","1.44261","299.87384"
"198.73400","1.44308","299.77936"
"199.03400","1.44299","300.49609"
"199.33400","1.44336","299.71985"
"199.63400","1.44430","300.00430"
"199.93400","1.44430","299.48688"
"200.23400","1.44449","299.88937"
"200.53400","1.44505","300.52982"
"200.83400","1.44524","300.52322"
"201.13400","1.44514","300.23502"
"201.43400","1.44561","299.10333"
"201.73400","1.44571","299.90057"
"202.03400","1.44674","299.40866"
"202.33400","1.44720","300.01215"
"202.63400","1.44767","299.43115"
"202.93400","1.44814","299.85147"
"203.23400","1.44824","300.41653"
"203.53400","1.44795","300.51392"
"203.83400","1.44852","299.87561"
"204.13400","1.44908","299.40280"
"204.43400","1.44983","300.42270"
"204.73400","1.44992","299.99033"
"205.03400","1.45030","299.30353"
"205.33400","1.45039","299.91156"
"205.63400","1.45133","300.62210"
"205.93400","1.45180","301.39301"
"206.23400","1.45236","299.37183"
"206.53400","1.45217","300.63760"
"206.83400","1.45264","299.78238"
"207.13400","1.45330","301.25729"
"207.43400","1.45367","299.59689"
"207.73400","1.45339","299.64288"
"208.03400","1.45330","300.76923"
"208.33400","1.45386","299.52667"
"208.63400","1.45470","299.96219"
"208.93400","1.45554","299.71378"
"209.23400","1.45536","299.95627"
"209.53400","1.45536","300.13995"
"209.83400","1.45573","300.47049"
"210.13400","1.45620","299.86188"
"210.43400","1.45620","299.66287"
"210.73400","1.45695","298.95615"
"211.03400","1.45695","300.79575"
"211.33400","1.45789","300.50531"
"211.63400","1.45807","299.72153"
"211.93400","1.45789","300.29974"
"212.23400","1.45770","300.19702"
"212.53400","1.45882","299.67844"
"212.83400","1.45892","299.11621"
"213.13400","1.45985","299.39401"
"213.43400","1.45957","300.17581"
"213.73400","1.45948","300.71252"
"214.03400","1.46032","299.42911"
"214.33400","1.46070","299.95081"
"214.63400","1.46098","299.52402"
"214.93400","1.46089","300.78409"
"215.23400","1.46173","300.14471"
"215.53400","1.46323","299.39072"
"215.83400","1.46295","300.51465"
"216.13400","1.46257","299.51666"
"216.43400","1.46313","299.46735"
"216.73400","1.46351","299.80844"
"217.03400","1.46388","299.06543"
"217.33400","1.46342","300.86819"
"217.63400","1.46435","300.17307"
"217.93400","1.46407","300.97220"
"218.23400","1.46426","300.49771"
"218.53400","1.46510","299.35687"
"218.83400","1.46548","300.33978"
"219.13400","1.46557","299.78067"
"219.43400","1.46576","299.64380"
"219.73400","1.46716","299.87601"
"220.03400","1.46716","299.67624"
"220.33400","1.46698","300.61572"
"220.63400","1.46744","299.26385"
"220.93400","1.46782","299.14203"
"221.23400","1.46857","301.37891"
"221.53400","1.46885","299.98627"
"221.83400","1.46857","300.35608"
"222.13400","1.46894","299.18616"
"222.43400","1.46894","299.94180"
"222.73400","1.46960","300.24283"
"223.03400","1.47072","300.00195"
"223.33400","1.47157","299.80923"
"223.63400","1.47166","300.51178"
"223.93400","1.47232","300.04907"
"224.23400","1.47185","300.19669"
"224.53400","1.47204","299.91391"
"224.83400","1.47222","299.93127"
"225.13400","1.47344","300.42093"
"225.43400","1.47354","301.20416"
"225.73400","1.47400","299.57352"
"226.03400","1.47419","300.01660"
"226.33400","1.47494","299.93637"
"226.63400","1.47494","300.34302"
"226.93400","1.47532","299.72974"
"227.23400","1.47532","300.99179"
"227.53400","1.47560","299.77161"
"227.83400","1.47635","300.67355"
"228.13400","1.47616","300.34891"
"228.43400","1.47635","299.99258"
"228.73400","1.47653","299.60306"
"229.03400","1.47738","301.50809"
"229.33400","1.47757","300.20642"
"229.63400","1.47803","300.04346"
"229.93400","1.47906","299.96942"
"230.23400","1.47916","299.74927"
"230.53400","1.47925","301.49207"
"230.83400","1.47963","300.16006"
"231.13400","1.48010","299.09607"
"231.43400","1.48028","299.86932"
"231.73400","1.48056","299.90732"
"232.03400","1.48066","299.83975"
"232.33400","1.48122","299.50458"
"232.63400","1.48131","300.76349"
"232.93400","1.48122","300.88046"
"233.23400","1.48169","300.18463"
"233.53400","1.48206","299.98615"
"233.83400","1.48272","300.25635"
"234.13400","1.48281","300.26465"
"234.43400","1.48356","299.30704"
"234.73400","1.48412","301.05038"
"235.03400","1.48403","301.08740"
"235.33400","1.48422","299.99622"
"235.63400","1.48431","299.92935"
"235.93400","1.48497","299.25342"
"236.23400","1.48534","299.87997"
"236.53400","1.48600","299.33749"
"236.83400","1.48628","299.80719"
"237.13400","1.48684","300.44302"
"237.43400","1.48684","300.00800"
"237.73400","1.48731","299.91232"
"238.03400","1.48750","299.31717"
"238.33400","1.48797","300.48080"
"238.63400","1.48778","300.17126"
"238.93400","1.48778","300.14355"
"239.23400","1.48844","299.28131"
"239.53400","1.48909","299.97531"
"239.83400","1.48956","299.17279"
"240.13400","1.48956","300.10507"
"240.43400","1.48975","299.81216"
"240.73400","1.49040","300.46542"
"241.03400","1.49040","299.97290"
"241.33400","1.49068","299.53748"
"241.63400","1.49106","300.48987"
"241.93400","1.49125","299.67957"
"242.23400","1.49125","299.66174"
"242.53400","1.49228","299.27872"
"242.83400","1.49218","299.96173"
"243.13400","1.49284","300.39688"
"243.43400","1.49321","299.60913"
"243.73400","1.49340","299.95212"
"244.03400","1.49387","300.16318"
"244.33400","1.49387","299.64499"
"244.63400","1.49387","299.43231"
"244.93400","1.49434","299.98285"
"245.23400","1.49528","299.86182"
"245.53400","1.49509","299.74811"
"245.83400","1.49518","299.99396"
"246.13400","1.49546","300.37241"
"246.43400","1.49593","299.66635"
"246.73400","1.49678","299.84998"
"247.03400","1.49668","300.61169"
"247.33400","1.49715","300.70792"
"247.63400","1.49752","299.88333"
"247.93400","1.49752","300.31723"
"248.23400","1.49799","300.14822"
"248.53400","1.49799","299.95020"
"248.83400","1.49846","299.48108"
"249.13400","1.49912","299.59174"
"249.43400","1.49931","299.50995"
"249.73400","1.49949","300.05606"
"250.03400","1.49949","299.70560"
"250.33400","1.49987","300.03995"
"250.63400","1.50024","299.46338"
"250.93400","1.50080","299.86993"
"251.23400","1.50099","300.31839"
"251.53400","1.50099","300.40674"
"251.83400","1.50099","300.23459"
"252.13400","1.50184","299.95111"
"252.43400","1.50193","299.59485"
"252.73400","1.50249","300.06464"
"253.03400","1.50268","300.29694"
"253.33400","1.50268","300.48856"
"253.63400","1.50352","299.93661"
"253.93400","1.50437","299.99918"
"254.23400","1.50399","300.58987"
"254.53400","1.50418","299.82224"
"254.83400","1.50437","299.99207"
"255.13400","1.50502","300.17316"
"255.43400","1.50502","300.23196"
"255.73400","1.50483","299.83636"
"256.03400","1.50540","299.69781"
"256.33400","1.50577","299.86795"
"256.63400","1.50615","300.45569"
"256.93400","1.50624","300.32693"
"257.23400","1.50652","299.21021"
"257.53400","1.50718","299.53323"
"257.83400","1.50736","299.65930"
"258.13400","1.50783","299.86569"
"258.43400","1.50830","299.73035"
"258.73400","1.50830","300.25446"
"259.03400","1.50793","300.59808"
"259.33400","1.50858","299.11111"
"259.63400","1.50905","299.79251"
"259.93400","1.50999","300.04480"
"260.23400","1.50980","300.28061"
"260.53400","1.51018","299.75003"
"260.83400","1.51036","300.00504"
"261.13400","1.51121","300.27625"
"261.43400","1.51055","300.53326"
"261.73400","1.51027","299.81787"
"262.03400","1.51083","299.62686"
"262.33400","1.51158","299.75885"
"262.63400","1.51252","299.89343"
"262.93400","1.51233","300.20306"
"263.23400","1.51299","299.99878"
"263.53400","1.51271","300.12970"
"263.83400","1.51308","299.57349"
"264.13400","1.51355","299.57001"
"264.43400","1.51402","300.24118"
"264.73400","1.51477","300.35999"
"265.03400","1.51420","300.86588"
"265.33400","1.51439","299.85406"
"265.63400","1.51505","299.67258"
"265.93400","1.51561","299.32867"
"266.23400","1.51617","300.49033"
"266.53400","1.51617","299.93591"
"266.83400","1.51617","300.04303"
"267.13400","1.51655","300.36774"
"267.43400","1.51673","299.80255"
"267.73400","1.51692","299.66348"
"268.03400","1.51777","299.87823"
"268.33400","1.51777","299.82770"
"268.63400","1.51777","301.01450"
"268.93400","1.51805","300.02921"
"269.23400","1.51861","300.06421"
"269.53400","1.51917","299.89746"
"269.83400","1.51936","300.00717"
"270.13400","1.51955","300.05954"
"270.43400","1.51983","299.66376"
"270.73400","1.52076","300.04996"
"271.03400","1.52067","300.21838"
"271.33400","1.52048","299.86707"
"271.63400","1.52114","299.29849"
"271.93400","1.52142","299.71533"
"272.23400","1.52123","300.51471"
"272.53400","1.52161","300.06485"
"272.83400","1.52170","300.47974"
"273.13400","1.52179","299.99338"
"273.43400","1.52301","300.34396"
"273.73400","1.52301","299.88019"
"274.03400","1.52301","300.04367"
"274.33400","1.52311","300.01645"
"274.63400","1.52404","299.90497"
"274.93400","1.52461","300.73306"
"275.23400","1.52461","300.88632"
"275.53400","1.52526","300.19867"
"275.83400","1.52536","299.92532"
"276.13400","1.52582","299.93494"
"276.43400","1.52545","300.11639"
"276.73400","1.52582","300.56784"
"277.03400","1.52639","299.65930"
"277.33400","1.52667","301.03113"
"277.63400","1.52657","299.67276"
"277.93400","1.52648","299.90475"
"278.23400","1.52667","299.47525"
"278.53400","1.52751","299.78278"
"278.83400","1.52807","299.41672"
"279.13400","1.52760","300.58359"
"279.43400","1.52826","299.65137"
"279.73400","1.52854","299.77292"
"280.03400","1.52864","300.78345"
"280.33400","1.52864","300.09631"
"280.63400","1.52835","300.22302"
"280.93400","1.52948","299.25610"
"281.23400","1.52995","300.71643"
"281.53400","1.53023","299.07721"
"281.83400","1.53135","299.71768"
"282.13400","1.53088","300.26639"
"282.43400","1.53107","299.79517"
"282.73400","1.53079","300.43475"
"283.03400","1.53163","299.81052"
"283.33400","1.53173","299.57614"
"283.63400","1.53248","299.67618"
"283.93400","1.53313","300.63037"
"284.23400","1.53285","300.19162"
"284.53400","1.53266","299.72882"
"284.83400","1.53323","299.48132"
"285.13400","1.53313","300.03827"
"285.43400","1.53379","300.40356"
"285.73400","1.53351","300.60425"
"286.03400","1.53351","300.06326"
"286.33400","1.53435","299.29779"
"286.63400","1.53445","299.92230"
"286.93400","1.53426","300.60822"
"287.23400","1.53482","300.02499"
"287.53400","1.53510","300.04956"
"287.83400","1.53529","299.55298"
"288.13400","1.53529","300.09116"
"288.43400","1.53548","300.29813"
"288.73400","1.53576","299.83142"
"289.03400","1.53594","300.21014"
"289.33400","1.53679","299.51279"
"289.63400","1.53669","299.79517"
"289.93400","1.53651","300.83844"
"290.23400","1.53660","300.17047"
"290.53400","1.53707","300.25986"
"290.83400","1.53744","299.96472"
"291.13400","1.53791","300.23227"
"291.43400","1.53791","300.36130"
"291.73400","1.53801","300.03036"
"292.03400","1.53913","299.94534"
"292.33400","1.53913","300.24237"
"292.63400","1.53904","299.98267"
"292.93400","1.53988","299.53012"
"293.23400","1.54026","300.22311"
"293.53400","1.54035","299.73782"
"293.83400","1.54044","300.17422"
"294.13400","1.54091","299.36877"
"294.43400","1.54119","299.85373"
"294.73400","1.54035","300.28275"
"295.03400","1.54100","299.42325"
"295.33400","1.54147","299.50967"
"295.63400","1.54194","300.24002"
"295.93400","1.54213","300.46869"
"296.23400","1.54222","300.22354"
"296.53400","1.54232","300.09995"
"296.83400","1.54353","300.77994"
"297.13400","1.54325","299.98605"
"297.43400","1.54307","299.49036"
"297.73400","1.54269","300.27551"
"298.03400","1.54344","300.34967"
"298.33400","1.54325","300.66498"
"298.63400","1.54391","299.70026"
"298.93400","1.54363","301.33649"
"299.23400","1.54419","300.05890"
"299.53400","1.54438","299.33456"
"299.83400","1.54503","299.68893"
"300.00000","1.54522","300.42999"