File: Lab 5/Polymer Data/100924 PVC tesnsile test.is_tens_RawData/PVC_TT.csv
Specimen properties : Length,"100.00000",mm
Specimen properties : Thickness,"1.00000",mm
Specimen properties : Width,"10.00000",mm
Test : Rate 1,"5.00000",mm/min

Time,Extension,Load
(s),(mm),(N)
"0.00000","0.00000","-0.12309"
"0.20000","0.01434","0.82915"
"0.40000","0.03252","0.94695"
"0.60000","0.04985","0.79212"
"0.80000","0.06672","1.35208"
"1.00000","0.08349","1.22081"
"1.20000","0.10017","0.53570"
"1.40000","0.11685","2.08860"
"1.60000","0.13353","2.75372"
"1.80000","0.15021","13.38667"
"2.00000","0.16689","21.12536"
"2.20000","0.18357","32.43537"
"2.40000","0.20025","47.99333"
"2.60000","0.21693","63.83346"
"2.80000","0.23352","80.71085"
"3.00000","0.25010","98.39335"
"3.20000","0.26688","114.59823"
"3.40000","0.28346","132.87469"
"3.60000","0.30014","150.85585"
"3.80000","0.31692","167.50909"
"4.00000","0.33350","184.89041"
"4.20000","0.35018","201.99265"
"4.40000","0.36686","220.50606"
"4.60000","0.38354","236.83385"
"4.80000","0.40022","254.46735"
"5.00000","0.41681","270.94421"
"5.20000","0.43349","287.33530"
"5.40000","0.45026","304.50201"
"5.60000","0.46694","321.79819"
"5.80000","0.48353","338.00812"
"6.00000","0.50021","354.20187"
"6.20000","0.51689","370.23184"
"6.40000","0.53357","386.89575"
"6.60000","0.55015","403.18384"
"6.80000","0.56683","419.31198"
"7.00000","0.58351","435.34232"
"7.20000","0.60019","449.77902"
"7.40000","0.61696","465.88184"
"7.60000","0.63364","481.19528"
"7.80000","0.65014","496.61380"
"8.00000","0.66682","511.35080"
"8.20000","0.68350","526.70703"
"8.40000","0.70018","542.24066"
"8.60000","0.71695","557.80054"
"8.80000","0.73354","573.34680"
"9.00000","0.75012","588.02155"
"9.20000","0.76680","602.37146"
"9.40000","0.78348","617.12762"
"9.60000","0.80025","631.95801"
"9.80000","0.81684","648.15814"
"10.00000","0.83343","662.36627"
"10.20000","0.85020","677.28955"
"10.40000","0.86688","692.45013"
"10.60000","0.88365","707.35083"
"10.80000","0.90024","722.51917"
"11.00000","0.91683","737.12036"
"11.20000","0.93341","750.77649"
"11.40000","0.95009","766.17206"
"11.60000","0.96686","779.88959"
"11.80000","0.98354","794.61670"
"12.00000","1.00004","808.31964"
"12.20000","1.01681","821.96307"
"12.40000","1.03349","837.08893"
"12.60000","1.05017","851.78326"
"12.80000","1.06685","866.30804"
"13.00000","1.08344","880.37122"
"13.20000","1.10012","893.09821"
"13.40000","1.11679","908.35925"
"13.60000","1.13357","922.07178"
"13.80000","1.15015","935.99261"
"14.00000","1.16683","949.44800"
"14.20000","1.18351","962.75897"
"14.40000","1.20019","977.35339"
"14.60000","1.21687","990.70660"
"14.80000","1.23355","1004.50861"
"15.00000","1.25014","1018.37061"
"15.20000","1.26673","1030.81189"
"15.40000","1.28350","1044.11816"
"15.60000","1.30018","1056.40515"
"15.80000","1.31686","1070.21472"
"16.00000","1.33354","1082.62976"
"16.20000","1.35012","1095.65234"
"16.40000","1.36680","1108.67749"
"16.60000","1.38358","1121.32825"
"16.80000","1.40016","1134.65771"
"17.00000","1.41684","1146.88635"
"17.20000","1.43343","1159.62744"
"17.40000","1.45011","1172.40247"
"17.60000","1.46688","1184.03503"
"17.80000","1.48347","1196.73975"
"18.00000","1.50015","1208.96191"
"18.20000","1.51683","1221.03394"
"18.40000","1.53341","1234.30493"
"18.60000","1.55019","1245.70850"
"18.80000","1.56687","1257.84631"
"19.00000","1.58355","1269.69727"
"19.20000","1.60023","1281.50122"
"19.40000","1.61681","1293.78015"
"19.60000","1.63359","1304.84729"
"19.80000","1.65017","1316.20325"
"20.00000","1.66685","1327.61560"
"20.20000","1.68353","1339.21765"
"20.40000","1.70012","1351.36804"
"20.60000","1.71689","1362.41919"
"20.80000","1.73348","1374.01758"
"21.00000","1.75016","1386.00464"
"21.20000","1.76684","1397.00269"
"21.40000","1.78342","1408.76440"
"21.60000","1.80020","1419.73438"
"21.80000","1.81688","1430.75903"
"22.00000","1.83346","1442.09668"
"22.20000","1.85024","1453.44543"
"22.40000","1.86692","1465.01831"
"22.60000","1.88360","1475.79675"
"22.80000","1.90018","1486.80188"
"23.00000","1.91686","1498.16675"
"23.20000","1.93345","1508.66150"
"23.40000","1.95013","1520.14172"
"23.60000","1.96681","1530.42029"
"23.80000","1.98349","1540.94849"
"24.00000","2.00017","1551.03906"
"24.20000","2.01685","1561.84729"
"24.40000","2.03353","1572.85852"
"24.60000","2.05021","1582.93188"
"24.80000","2.06689","1593.51025"
"25.00000","2.08347","1603.73389"
"25.20000","2.10015","1613.09192"
"25.40000","2.11683","1624.13049"
"25.60000","2.13351","1634.05518"
"25.80000","2.15019","1643.91418"
"26.00000","2.16687","1653.26526"
"26.20000","2.18355","1663.53748"
"26.40000","2.20023","1673.86621"
"26.60000","2.21691","1683.85132"
"26.80000","2.23340","1693.58960"
"27.00000","2.25018","1702.86914"
"27.20000","2.26676","1711.95789"
"27.40000","2.28344","1722.08813"
"27.60000","2.30022","1731.46619"
"27.80000","2.31680","1740.94604"
"28.00000","2.33348","1749.15759"
"28.20000","2.35025","1758.06653"
"28.40000","2.36684","1767.70972"
"28.60000","2.38352","1777.25549"
"28.80000","2.40011","1786.29138"
"29.00000","2.41679","1794.52417"
"29.20000","2.43356","1803.05615"
"29.40000","2.45015","1812.10449"
"29.60000","2.46683","1821.11206"
"29.80000","2.48341","1829.81848"
"30.00000","2.50009","1837.51782"
"30.20000","2.51687","1845.30371"
"30.40000","2.53345","1854.51672"
"30.60000","2.55022","1863.55042"
"30.80000","2.56690","1871.80737"
"31.00000","2.58349","1879.78430"
"31.20000","2.60017","1887.83447"
"31.40000","2.61685","1895.63354"
"31.60000","2.63353","1904.35254"
"31.80000","2.65012","1912.63281"
"32.00000","2.66680","1920.03833"
"32.20000","2.68348","1927.16638"
"32.40000","2.70025","1935.50195"
"32.60000","2.71693","1943.52881"
"32.80000","2.73351","1950.86841"
"33.00000","2.75010","1958.10107"
"33.20000","2.76678","1965.11499"
"33.40000","2.78355","1972.38843"
"33.60000","2.80014","1980.18005"
"33.80000","2.81673","1987.62585"
"34.00000","2.83341","1994.11096"
"34.20000","2.85018","2000.23914"
"34.40000","2.86695","2008.06873"
"34.60000","2.88363","2014.62305"
"34.80000","2.90022","2021.37195"
"35.00000","2.91671","2027.96423"
"35.20000","2.93339","2034.17517"
"35.40000","2.95016","2040.22363"
"35.60000","2.96694","2046.54675"
"35.80000","2.98343","2053.37061"
"36.00000","3.00011","2058.85303"
"36.20000","3.01679","2064.22461"
"36.40000","3.03356","2070.37207"
"36.60000","3.05024","2076.39160"
"36.80000","3.06683","2082.05420"
"37.00000","3.08351","2087.66162"
"37.20000","3.10019","2092.64404"
"37.40000","3.11687","2097.79004"
"37.60000","3.13364","2102.93726"
"37.80000","3.15023","2107.93213"
"38.00000","3.16681","2113.03613"
"38.20000","3.18349","2116.88965"
"38.40000","3.20017","2121.67798"
"38.60000","3.21685","2125.86621"
"38.80000","3.23353","2129.97290"
"39.00000","3.25012","2134.66504"
"39.20000","3.26680","2138.06519"
"39.40000","3.28348","2142.39014"
"39.60000","3.30025","2146.11768"
"39.80000","3.31693","2149.36597"
"40.00000","3.33352","2152.66431"
"40.20000","3.35010","2155.50562"
"40.40000","3.36688","2158.14014"
"40.60000","3.38356","2161.12427"
"40.80000","3.40014","2163.74878"
"41.00000","3.41682","2166.87109"
"41.20000","3.43350","2169.50342"
"41.40000","3.45018","2171.69214"
"41.60000","3.46686","2173.58276"
"41.80000","3.48354","2175.59985"
"42.00000","3.50013","2177.59351"
"42.20000","3.51681","2178.92676"
"42.40000","3.53349","2180.68018"
"42.60000","3.55026","2182.13550"
"42.80000","3.56694","2183.54956"
"43.00000","3.58353","2184.40674"
"43.20000","3.60011","2185.80664"
"43.40000","3.61689","2187.02148"
"43.60000","3.63347","2187.70605"
"43.80000","3.65015","2187.79102"
"44.00000","3.66683","2188.16089"
"44.20000","3.68351","2189.06641"
"44.40000","3.70019","2188.88623"
"44.60000","3.71687","2189.10938"
"44.80000","3.73355","2188.84253"
"45.00000","3.75023","2188.58447"
"45.20000","3.76682","2188.89453"
"45.40000","3.78350","2189.03882"
"45.60000","3.80018","2187.98584"
"45.80000","3.81686","2187.36035"
"46.00000","3.83354","2186.81421"
"46.20000","3.85031","2185.98706"
"46.40000","3.86690","2185.27881"
"46.60000","3.88358","2184.90649"
"46.80000","3.90016","2183.48950"
"47.00000","3.91675","2182.39185"
"47.20000","3.93352","2181.79517"
"47.40000","3.95020","2180.78345"
"47.60000","3.96688","2179.94800"
"47.80000","3.98347","2178.02246"
"48.00000","4.00024","2176.41797"
"48.20000","4.01692","2175.57690"
"48.40000","4.03360","2174.39062"
"48.60000","4.05019","2173.25562"
"48.80000","4.06687","2171.51538"
"49.00000","4.08345","2170.15283"
"49.20000","4.10013","2168.50537"
"49.40000","4.11690","2167.67163"
"49.60000","4.13349","2166.37524"
"49.80000","4.15017","2164.44727"
"50.00000","4.16685","2162.60205"
"50.20000","4.18353","2160.55835"
"50.40000","4.20021","2158.94653"
"50.60000","4.21680","2157.85156"
"50.80000","4.23348","2155.69238"
"51.00000","4.25016","2153.41064"
"51.20000","4.26684","2152.40649"
"51.40000","4.28351","2150.97925"
"51.60000","4.30019","2149.99585"
"51.80000","4.31678","2148.33862"
"52.00000","4.33346","2145.31470"
"52.20000","4.35023","2143.58838"
"52.40000","4.36691","2141.99390"
"52.60000","4.38350","2141.13501"
"52.80000","4.40018","2139.07446"
"53.00000","4.41677","2137.09985"
"53.20000","4.43345","2135.57764"
"53.40000","4.45022","2134.86377"
"53.60000","4.46690","2133.61035"
"53.80000","4.48348","2132.28516"
"54.00000","4.50016","2130.12061"
"54.20000","4.51675","2128.11865"
"54.40000","4.53362","2126.84790"
"54.60000","4.55020","2125.29126"
"54.80000","4.56688","2124.46582"
"55.00000","4.58347","2121.86377"
"55.20000","4.60015","2120.49194"
"55.40000","4.61683","2119.64844"
"55.60000","4.63351","2118.23657"
"55.80000","4.65009","2117.04907"
"56.00000","4.66678","2114.56323"
"56.20000","4.68355","2112.80273"
"56.40000","4.70023","2111.14136"
"56.60000","4.71691","2110.14722"
"56.80000","4.73349","2108.99243"
"57.00000","4.75008","2106.44580"
"57.20000","4.76685","2105.49805"
"57.40000","4.78353","2104.34131"
"57.60000","4.80021","2103.48096"
"57.80000","4.81689","2102.23975"
"58.00000","4.83357","2100.60449"
"58.20000","4.85025","2098.38403"
"58.40000","4.86693","2097.24561"
"58.60000","4.88352","2096.31787"
"58.80000","4.90010","2095.06372"
"59.00000","4.91669","2093.34668"
"59.20000","4.93346","2092.54834"
"59.40000","4.95024","2091.44727"
"59.60000","4.96682","2090.69849"
"59.80000","4.98350","2089.22607"
"60.00000","5.00018","2087.88013"
"60.20000","5.01686","2086.18042"
"60.40000","5.03364","2084.56641"
"60.60000","5.05022","2083.37354"
"60.80000","5.06681","2082.71118"
"61.00000","5.08349","2080.47632"
"61.20000","5.10017","2080.04688"
"61.40000","5.11694","2079.25391"
"61.60000","5.13353","2078.07324"
"61.80000","5.15021","2077.17065"
"62.00000","5.16689","2075.50171"
"62.20000","5.18357","2074.41577"
"62.40000","5.20025","2072.13794"
"62.60000","5.21683","2071.10303"
"62.80000","5.23351","2069.74683"
"63.00000","5.25010","2068.37964"
"63.20000","5.26678","2067.80200"
"63.40000","5.28355","2066.50098"
"63.60000","5.30014","2065.82275"
"63.80000","5.31682","2064.29150"
"64.00000","5.33350","2062.56982"
"64.20000","5.35018","2061.44873"
"64.40000","5.36686","2060.71094"
"64.60000","5.38354","2058.71753"
"64.80000","5.40022","2058.32227"
"65.00000","5.41680","2056.61890"
"65.20000","5.43348","2056.12280"
"65.40000","5.45016","2055.76587"
"65.60000","5.46684","2054.60693"
"65.80000","5.48343","2053.09082"
"66.00000","5.50011","2051.76172"
"66.20000","5.51688","2051.76172"
"66.40000","5.53356","2050.16235"
"66.60000","5.55024","2048.78564"
"66.80000","5.56683","2047.47742"
"67.00000","5.58351","2046.12708"
"67.20000","5.60019","2046.09937"
"67.40000","5.61677","2045.35132"
"67.60000","5.63345","2044.69873"
"67.80000","5.65013","2043.01099"
"68.00000","5.66681","2041.52319"
"68.20000","5.68349","2040.95728"
"68.40000","5.70026","2039.88892"
"68.60000","5.71685","2038.44385"
"68.80000","5.73353","2036.48669"
"69.00000","5.75021","2034.91150"
"69.20000","5.76680","2034.83862"
"69.40000","5.78348","2035.11731"
"69.60000","5.80016","2034.03687"
"69.80000","5.81684","2032.42249"
"70.00000","5.83361","2031.21008"
"70.20000","5.85020","2031.41272"
"70.40000","5.86697","2030.12598"
"70.60000","5.88337","2028.89502"
"70.80000","5.90014","2027.83386"
"71.00000","5.91682","2025.24512"
"71.20000","5.93359","2025.93127"
"71.40000","5.95027","2025.18481"
"71.60000","5.96686","2024.27539"
"71.80000","5.98345","2022.69092"
"72.00000","6.00022","2020.99329"
"72.20000","6.01690","2020.27405"
"72.40000","6.03358","2019.06897"
"72.60000","6.05017","2018.17822"
"72.80000","6.06684","2016.56311"
"73.00000","6.08390","2014.29761"
"73.20000","6.10030","2013.96497"
"73.40000","6.11698","2012.81458"
"73.60000","6.13328","2012.66016"
"73.80000","6.15015","2011.21643"
"74.00000","6.16683","2009.99231"
"74.20000","6.18351","2010.08374"
"74.40000","6.20019","2008.56177"
"74.60000","6.21677","2008.16467"
"74.80000","6.23346","2006.29761"
"75.00000","6.25013","2004.66101"
"75.20000","6.26681","2004.59473"
"75.40000","6.28359","2003.98718"
"75.60000","6.29999","2003.74512"
"75.80000","6.31685","2002.80579"
"76.00000","6.33344","2001.38403"
"76.20000","6.35021","2000.25122"
"76.40000","6.36699","1999.77759"
"76.60000","6.38357","1998.88867"
"76.80000","6.40016","1997.21814"
"77.00000","6.41675","1996.91370"
"77.20000","6.43352","1996.57153"
"77.40000","6.45020","1995.33313"
"77.60000","6.46678","1995.28687"
"77.80000","6.48346","1993.72681"
"78.00000","6.50014","1992.64441"
"78.20000","6.51692","1992.01111"
"78.40000","6.53360","1991.61438"
"78.60000","6.55028","1990.92529"
"78.80000","6.56686","1989.54846"
"79.00000","6.58345","1987.38513"
"79.20000","6.59985","1986.63757"
"79.40000","6.61671","1986.37207"
"79.60000","6.63349","1986.34717"
"79.80000","6.65017","1985.31287"
"80.00000","6.66685","1984.22913"
"80.20000","6.68353","1983.22314"
"80.40000","6.70021","1982.22607"
"80.60000","6.71679","1981.66541"
"80.80000","6.73338","1980.36267"
"81.00000","6.74987","1979.08325"
"81.20000","6.76674","1980.41150"
"81.40000","6.78351","1978.82056"
"81.60000","6.80019","1978.15247"
"81.80000","6.81687","1977.50073"
"82.00000","6.83355","1976.04358"
"82.20000","6.85023","1975.50500"
"82.40000","6.86682","1974.28857"
"82.60000","6.88340","1973.39258"
"82.80000","6.90008","1972.59631"
"83.00000","6.91686","1970.96094"
"83.20000","6.93344","1970.54651"
"83.40000","6.95012","1970.45410"
"83.60000","6.96680","1969.42017"
"83.80000","6.98358","1968.95435"
"84.00000","7.00016","1967.96875"
"84.20000","7.01694","1967.46814"
"84.40000","7.03352","1965.83240"
"84.60000","7.05020","1965.17627"
"84.80000","7.06679","1964.03284"
"85.00000","7.08366","1963.31311"
"85.20000","7.10015","1963.06763"
"85.40000","7.11683","1961.61462"
"85.60000","7.13360","1960.97180"
"85.80000","7.15028","1959.30542"
"86.00000","7.16687","1959.60315"
"86.20000","7.18345","1959.17212"
"86.40000","7.20023","1958.38416"
"86.60000","7.21681","1957.89490"
"86.80000","7.23359","1956.14661"
"87.00000","7.25036","1954.68945"
"87.20000","7.26685","1954.45886"
"87.40000","7.28353","1953.77893"
"87.60000","7.30012","1953.88416"
"87.80000","7.31680","1952.14929"
"88.00000","7.33357","1952.56531"
"88.20000","7.35016","1952.27942"
"88.40000","7.36693","1950.93579"
"88.60000","7.38352","1949.63684"
"88.80000","7.40010","1948.21826"
"89.00000","7.41706","1947.20532"
"89.20000","7.43356","1948.23633"
"89.40000","7.45014","1947.31116"
"89.60000","7.46692","1946.78564"
"89.80000","7.48378","1944.93384"
"90.00000","7.50027","1944.25842"
"90.20000","7.51695","1944.13367"
"90.40000","7.53354","1943.45801"
"90.60000","7.55013","1942.01038"
"90.80000","7.56690","1940.89209"
"91.00000","7.58358","1940.05151"
"91.20000","7.60026","1939.81030"
"91.40000","7.61703","1938.56299"
"91.60000","7.63343","1938.29236"
"91.80000","7.65021","1937.23779"
"92.00000","7.66688","1936.52454"
"92.20000","7.68366","1936.59888"
"92.40000","7.70024","1936.00232"
"92.60000","7.71683","1934.38733"
"92.80000","7.73360","1933.28857"
"93.00000","7.74972","1931.80493"
"93.20000","7.76706","1931.97656"
"93.40000","7.78364","1931.48987"
"93.60000","7.80023","1930.96191"
"93.80000","7.81681","1929.21106"
"94.00000","7.83349","1928.44177"
"94.20000","7.85027","1928.18384"
"94.40000","7.86676","1927.50378"
"94.60000","7.88335","1926.38733"
"94.80000","7.90012","1924.94043"
"95.00000","7.91689","1923.67419"
"95.20000","7.93339","1922.64453"
"95.40000","7.95025","1922.93054"
"95.60000","7.96684","1921.49890"
"95.80000","7.98361","1921.38513"
"96.00000","8.00020","1920.70068"
"96.20000","8.01697","1919.69019"
"96.40000","8.03356","1919.49011"
"96.60000","8.05014","1918.85229"
"96.80000","8.06682","1917.37732"
"97.00000","8.08332","1915.58997"
"97.20000","8.09990","1915.27136"
"97.40000","8.11686","1915.88965"
"97.60000","8.13354","1915.11768"
"97.80000","8.15004","1914.01062"
"98.00000","8.16681","1912.70825"
"98.20000","8.18349","1912.57385"
"98.40000","8.20017","1912.01514"
"98.60000","8.21685","1911.64001"
"98.80000","8.23353","1910.71204"
"99.00000","8.25030","1908.82800"
"99.20000","8.26689","1908.84412"
"99.40000","8.28366","1908.03674"
"99.60000","8.30006","1908.25293"
"99.80000","8.31683","1908.18030"
"100.00000","8.33351","1907.13513"
"100.20000","8.35019","1905.90625"
"100.40000","8.36687","1905.71216"
"100.60000","8.38355","1904.67419"
"100.80000","8.40023","1903.86438"
"101.00000","8.41682","1902.30847"
"101.20000","8.43350","1901.71082"
"101.40000","8.45027","1902.27759"
"101.60000","8.46667","1900.79456"
"101.80000","8.48354","1900.58521"
"102.00000","8.50022","1899.74658"
"102.20000","8.51690","1899.09094"
"102.40000","8.53358","1898.92310"
"102.60000","8.55016","1898.25916"
"102.80000","8.56675","1897.55518"
"103.00000","8.58333","1896.03845"
"103.20000","8.60020","1895.34204"
"103.40000","8.61679","1894.64526"
"103.60000","8.63309","1895.16418"
"103.80000","8.65024","1894.48279"
"104.00000","8.66683","1892.83228"
"104.20000","8.68351","1892.35010"
"104.40000","8.70019","1892.26758"
"104.60000","8.71677","1891.57837"
"104.80000","8.73345","1890.62976"
"105.00000","8.75004","1889.65540"
"105.20000","8.76700","1887.49097"
"105.40000","8.78359","1887.91589"
"105.60000","8.80008","1887.00317"
"105.80000","8.81685","1886.66663"
"106.00000","8.83334","1884.97437"
"106.20000","8.85002","1884.86682"
"106.40000","8.86680","1884.63123"
"106.60000","8.88348","1883.68396"
"106.80000","8.90016","1882.90808"
"107.00000","8.91684","1882.27747"
"107.20000","8.93352","1881.36060"
"107.40000","8.95020","1880.22083"
"107.60000","8.96725","1880.06250"
"107.80000","8.98337","1880.32483"
"108.00000","9.00024","1879.12207"
"108.20000","9.01682","1878.92371"
"108.40000","9.03360","1878.25415"
"108.60000","9.05018","1877.16797"
"108.80000","9.06686","1876.15356"
"109.00000","9.08354","1875.31287"
"109.20000","9.10022","1874.19666"
"109.40000","9.11718","1874.50232"
"109.60000","9.13349","1874.55432"
"109.80000","9.15007","1874.21741"
"110.00000","9.16647","1872.53186"
"110.20000","9.18353","1872.86511"
"110.40000","9.20011","1872.24988"
"110.60000","9.21688","1870.84302"
"110.80000","9.23347","1870.12585"
"111.00000","9.25015","1869.95618"
"111.20000","9.26674","1868.46533"
"111.40000","9.28342","1868.57996"
"111.60000","9.30019","1867.85852"
"111.80000","9.31687","1867.71216"
"112.00000","9.33346","1866.76965"
"112.20000","9.35023","1866.43323"
"112.40000","9.36682","1865.92993"
"112.60000","9.38350","1864.43140"
"112.80000","9.40018","1863.29834"
"113.00000","9.41704","1861.94922"
"113.20000","9.43353","1861.44043"
"113.40000","9.45012","1861.69165"
"113.60000","9.46671","1861.75903"
"113.80000","9.48376","1860.37830"
"114.00000","9.50054","1859.76343"
"114.20000","9.51693","1859.45850"
"114.40000","9.53352","1859.13403"
"114.60000","9.55011","1858.44897"
"114.80000","9.56679","1856.37830"
"115.00000","9.58356","1856.21082"
"115.20000","9.60014","1855.92029"
"115.40000","9.61683","1854.97998"
"115.60000","9.63341","1853.53662"
"115.80000","9.65018","1853.03088"
"116.00000","9.66686","1853.20972"
"116.20000","9.68354","1852.35278"
"116.40000","9.70022","1851.08386"
"116.60000","9.71681","1850.12488"
"116.80000","9.73349","1848.36499"
"117.00000","9.75017","1847.85632"
"117.20000","9.76694","1847.31665"
"117.40000","9.78353","1845.88391"
"117.60000","9.79993","1846.43591"
"117.80000","9.81679","1845.26221"
"118.00000","9.83310","1845.20032"
"118.20000","9.85025","1843.92737"
"118.40000","9.86683","1844.10730"
"118.60000","9.88342","1843.56702"
"118.80000","9.90010","1841.39111"
"119.00000","9.91687","1841.35461"
"119.20000","9.93346","1839.77356"
"119.40000","9.95014","1839.78552"
"119.60000","9.96682","1839.28809"
"119.80000","9.98378","1839.09753"
"120.00000","10.00008","1838.29419"
"120.20000","10.01676","1837.50720"
"120.40000","10.03344","1837.48267"
"120.60000","10.05012","1836.67395"
"120.80000","10.06680","1835.30505"
"121.00000","10.08348","1834.44116"
"121.20000","10.10026","1834.25916"
"121.40000","10.11684","1833.75977"
"121.60000","10.13352","1832.77087"
"121.80000","10.15011","1832.05249"
"122.00000","10.16670","1831.45251"
"122.20000","10.18337","1830.66821"
"122.40000","10.20024","1830.17236"
"122.60000","10.21683","1829.69958"
"122.80000","10.23351","1828.12976"
"123.00000","10.25019","1828.04443"
"123.20000","10.26677","1826.72388"
"123.40000","10.28345","1826.48767"
"123.60000","10.30013","1826.02161"
"123.80000","10.31738","1825.01599"
"124.00000","10.33359","1825.11694"
"124.20000","10.35045","1823.91296"
"124.40000","10.36676","1822.93799"
"124.60000","10.38353","1823.13232"
"124.80000","10.40012","1821.70349"
"125.00000","10.41680","1821.57812"
"125.20000","10.43338","1819.22729"
"125.40000","10.45006","1819.67932"
"125.60000","10.46674","1819.08984"
"125.80000","10.48352","1818.86353"
"126.00000","10.50020","1818.58130"
"126.20000","10.51669","1817.55737"
"126.40000","10.53356","1816.81555"
"126.60000","10.55005","1816.28894"
"126.80000","10.56682","1814.85400"
"127.00000","10.58341","1814.93494"
"127.20000","10.60018","1813.89148"
"127.40000","10.61696","1812.89502"
"127.60000","10.63345","1812.22388"
"127.80000","10.65050","1811.05151"
"128.00000","10.66699","1811.06946"
"128.20000","10.68358","1810.73120"
"128.40000","10.70026","1810.36243"
"128.60000","10.71685","1808.80896"
"128.80000","10.73353","1807.96741"
"129.00000","10.75021","1808.16003"
"129.20000","10.76688","1806.54211"
"129.40000","10.78357","1805.81885"
"129.60000","10.80015","1805.66980"
"129.80000","10.81711","1804.92554"
"130.00000","10.83370","1804.53943"
"130.20000","10.85038","1803.53333"
"130.40000","10.86687","1802.76489"
"130.60000","10.88346","1802.19128"
"130.80000","10.90014","1801.64502"
"131.00000","10.91682","1802.68176"
"131.20000","10.93350","1801.47070"
"131.40000","10.95008","1800.35156"
"131.60000","10.96686","1799.73303"
"131.80000","10.98363","1798.55249"
"132.00000","11.00003","1799.30688"
"132.20000","11.01690","1798.77039"
"132.40000","11.03348","1798.03223"
"132.60000","11.05016","1796.86328"
"132.80000","11.06693","1795.34534"
"133.00000","11.08352","1795.72327"
"133.20000","11.10029","1795.20642"
"133.40000","11.11679","1793.06458"
"133.60000","11.13347","1792.28503"
"133.80000","11.15015","1791.54346"
"134.00000","11.16692","1791.08997"
"134.20000","11.18369","1790.35962"
"134.40000","11.20018","1790.60718"
"134.60000","11.21686","1789.12207"
"134.80000","11.23345","1788.05591"
"135.00000","11.25022","1788.89795"
"135.20000","11.26681","1788.32678"
"135.40000","11.28340","1787.32202"
"135.60000","11.30008","1785.61829"
"135.80000","11.31685","1785.13623"
"136.00000","11.33344","1785.33179"
"136.20000","11.35021","1784.22363"
"136.40000","11.36679","1784.20825"
"136.60000","11.38347","1783.18359"
"136.80000","11.40016","1781.49170"
"137.00000","11.41683","1781.03186"
"137.20000","11.43351","1780.35852"
"137.40000","11.45019","1778.97974"
"137.60000","11.46687","1777.91699"
"137.80000","11.48355","1777.43701"
"138.00000","11.50023","1776.80530"
"138.20000","11.51701","1776.54553"
"138.40000","11.53341","1774.86768"
"138.60000","11.55009","1774.42456"
"138.80000","11.56686","1773.15283"
"139.00000","11.58354","1773.18469"
"139.20000","11.60012","1772.79041"
"139.40000","11.61690","1771.88904"
"139.60000","11.63330","1769.97913"
"139.80000","11.65026","1769.20520"
"140.00000","11.66675","1769.32275"
"140.20000","11.68371","1767.54346"
"140.40000","11.70030","1767.18030"
"140.60000","11.71679","1767.21741"
"140.80000","11.73347","1765.16064"
"141.00000","11.75024","1765.48230"
"141.20000","11.76702","1764.26355"
"141.40000","11.78332","1764.14160"
"141.60000","11.80009","1762.70581"
"141.80000","11.81640","1761.72839"
"142.00000","11.83355","1761.54187"
"142.20000","11.85023","1761.29492"
"142.40000","11.86681","1761.00244"
"142.60000","11.88349","1759.84924"
"142.80000","11.90008","1758.17725"
"143.00000","11.91685","1757.93689"
"143.20000","11.93353","1756.92444"
"143.40000","11.95021","1756.29700"
"143.60000","11.96680","1755.26855"
"143.80000","11.98348","1754.29932"
"144.00000","12.00016","1754.09192"
"144.20000","12.01703","1752.91467"
"144.40000","12.03380","1753.07336"
"144.60000","12.05010","1752.26184"
"144.80000","12.06678","1750.88098"
"145.00000","12.08346","1750.15234"
"145.20000","12.10014","1749.08252"
"145.40000","12.11682","1748.86548"
"145.60000","12.13341","1746.88403"
"145.80000","12.15018","1746.30530"
"146.00000","12.16742","1746.81433"
"146.20000","12.18354","1745.46021"
"146.40000","12.20032","1744.47498"
"146.60000","12.21681","1744.22009"
"146.80000","12.23349","1742.66772"
"147.00000","12.25017","1742.07898"
"147.20000","12.26685","1740.65601"
"147.40000","12.28353","1740.66064"
"147.60000","12.30021","1739.77283"
"147.80000","12.31679","1738.69617"
"148.00000","12.33347","1737.75366"
"148.20000","12.34987","1736.34998"
"148.40000","12.36683","1737.23340"
"148.60000","12.38351","1735.68433"
"148.80000","12.40010","1734.67139"
"149.00000","12.41678","1733.86304"
"149.20000","12.43346","1732.48999"
"149.40000","12.45014","1731.29126"
"149.60000","12.46691","1730.65173"
"149.80000","12.48359","1729.70837"
"150.00000","12.50074","1730.20581"
"150.20000","12.51676","1728.25256"
"150.40000","12.53372","1727.02917"
"150.60000","12.55012","1726.33118"
"150.80000","12.56680","1725.07776"
"151.00000","12.58348","1724.89233"
"151.20000","12.60016","1723.84753"
"151.40000","12.61684","1722.87427"
"151.60000","12.63371","1721.91150"
"151.80000","12.65039","1720.26697"
"152.00000","12.66688","1720.49231"
"152.20000","12.68347","1720.34351"
"152.40000","12.70014","1719.80481"
"152.60000","12.71683","1717.84351"
"152.80000","12.73360","1717.65649"
"153.00000","12.75019","1717.18835"
"153.20000","12.76686","1715.74805"
"153.40000","12.78355","1714.51648"
"153.60000","12.80013","1713.16248"
"153.80000","12.81681","1711.98840"
"154.00000","12.83396","1711.54761"
"154.20000","12.85045","1710.55554"
"154.40000","12.86676","1709.17078"
"154.60000","12.88353","1708.56396"
"154.80000","12.90021","1707.42798"
"155.00000","12.91689","1707.18188"
"155.20000","12.93357","1705.71948"
"155.40000","12.95016","1704.19250"
"155.60000","12.96693","1702.65991"
"155.80000","12.98370","1701.60547"
"156.00000","13.00019","1701.65039"
"156.20000","13.01622","1700.45178"
"156.40000","13.03365","1699.92578"
"156.60000","13.05005","1698.35706"
"156.80000","13.06691","1698.02344"
"157.00000","13.08350","1698.15332"
"157.20000","13.10018","1696.65454"
"157.40000","13.11677","1695.06836"
"157.60000","13.13344","1693.90588"
"157.80000","13.15022","1692.73572"
"158.00000","13.16690","1692.68884"
"158.20000","13.18386","1691.10657"
"158.40000","13.20016","1690.48584"
"158.60000","13.21684","1688.75769"
"158.80000","13.23352","1687.15442"
"159.00000","13.25020","1686.46606"
"159.20000","13.26688","1685.05103"
"159.40000","13.28347","1684.54053"
"159.60000","13.30015","1682.72522"
"159.80000","13.31711","1680.64905"
"160.00000","13.33379","1680.24915"
"160.20000","13.35038","1680.13831"
"160.40000","13.36640","1677.81006"
"160.60000","13.38355","1677.74207"
"160.80000","13.40014","1675.76807"
"161.00000","13.41681","1674.53125"
"161.20000","13.43349","1673.58411"
"161.40000","13.45017","1672.36853"
"161.60000","13.46685","1670.57983"
"161.80000","13.48353","1669.17542"
"162.00000","13.50021","1668.86548"
"162.20000","13.51642","1668.08044"
"162.40000","13.53329","1666.54419"
"162.60000","13.55034","1665.96973"
"162.80000","13.56684","1663.98413"
"163.00000","13.58352","1663.04285"
"163.20000","13.60020","1661.84814"
"163.40000","13.61688","1660.87708"
"163.60000","13.63346","1659.19885"
"163.80000","13.65024","1657.43848"
"164.00000","13.66692","1656.62341"
"164.20000","13.68332","1655.59998"
"164.40000","13.69999","1653.96216"
"164.60000","13.71677","1653.77649"
"164.80000","13.73345","1651.50134"
"165.00000","13.75031","1650.14551"
"165.20000","13.76690","1648.68201"
"165.40000","13.78349","1648.14404"
"165.60000","13.79998","1645.27039"
"165.80000","13.81685","1643.93127"
"166.00000","13.83353","1642.79065"
"166.20000","13.85049","1641.25415"
"166.40000","13.86689","1640.28857"
"166.60000","13.88347","1638.84717"
"166.80000","13.90015","1636.84546"
"167.00000","13.91683","1635.51660"
"167.20000","13.93361","1634.08740"
"167.40000","13.95010","1633.10474"
"167.60000","13.96687","1631.31018"
"167.80000","13.98355","1629.49243"
"168.00000","14.00023","1626.43958"
"168.20000","14.01682","1626.36414"
"168.40000","14.03397","1624.43274"
"168.60000","14.05018","1623.43250"
"168.80000","14.06686","1621.49255"
"169.00000","14.08354","1619.43640"
"169.20000","14.10022","1617.50244"
"169.40000","14.11680","1615.75305"
"169.60000","14.13348","1613.22302"
"169.80000","14.14997","1610.26770"
"170.00000","14.16693","1608.22632"
"170.20000","14.18352","1606.20508"
"170.40000","14.20001","1604.05359"
"170.60000","14.21697","1601.79248"
"170.80000","14.23347","1600.05396"
"171.00000","14.25015","1597.34314"
"171.20000","14.26683","1594.55054"
"171.40000","14.28351","1592.32324"
"171.60000","14.30019","1589.00562"
"171.80000","14.31696","1585.83447"
"172.00000","14.33336","1582.16882"
"172.20000","14.35022","1579.55554"
"172.40000","14.36690","1576.70325"
"172.60000","14.38396","1573.84644"
"172.80000","14.40017","1569.87781"
"173.00000","14.41685","1567.68091"
"173.20000","14.43362","1563.97632"
"173.40000","14.45021","1559.79810"
"173.60000","14.46689","1555.15747"
"173.80000","14.48348","1550.28137"
"174.00000","14.50016","1545.43506"
"174.20000","14.51684","1540.32581"
"174.40000","14.53370","1534.81641"
"174.60000","14.54991","1529.27148"
"174.80000","14.56687","1522.64343"
"175.00000","14.58346","1515.16541"
"175.20000","14.60023","1506.33020"
"175.40000","14.61691","1497.86597"
"175.60000","14.63341","1488.51660"
"175.80000","14.65027","1478.44666"
"176.00000","14.66677","1468.37341"
"176.20000","14.68326","1457.97156"
"176.40000","14.70013","1446.09106"
"176.60000","14.71699","1435.66895"
"176.80000","14.73339","1423.64197"
"177.00000","14.75026","1410.79639"
"177.20000","14.76684","1398.22363"
"177.40000","14.78343","1384.15845"
"177.60000","14.80011","1370.67627"
"177.80000","14.81679","1356.29395"
"178.00000","14.83347","1342.75012"
"178.20000","14.85024","1328.76538"
"178.40000","14.86730","1314.85376"
"178.60000","14.88351","1300.42712"
"178.80000","14.90056","1285.60144"
"179.00000","14.91687","1272.39343"
"179.20000","14.93355","1257.52002"
"179.40000","14.95023","1241.96753"
"179.60000","14.96691","1227.00415"
"179.80000","14.98349","1211.27722"
"180.00000","15.00045","1195.78088"
"180.20000","15.01685","1180.62720"
"180.40000","15.03325","1165.33813"
"180.60000","15.04974","1149.58362"
"180.80000","15.06680","1133.92627"
"181.00000","15.08357","1119.45874"
"181.20000","15.10016","1104.59326"
"181.40000","15.11675","1088.56787"
"181.60000","15.13343","1072.92419"
"181.80000","15.15038","1057.50720"
"182.00000","15.16678","1043.00403"
"182.20000","15.18356","1028.97571"
"182.40000","15.20014","1014.71002"
"182.60000","15.21692","999.97064"
"182.80000","15.23369","986.27069"
"183.00000","15.25018","972.38281"
"183.20000","15.26686","959.81250"
"183.40000","15.28354","946.10797"
"183.60000","15.30022","932.56348"
"183.80000","15.31690","919.72034"
"184.00000","15.33368","907.12848"
"184.20000","15.35017","894.99512"
"184.40000","15.36675","882.86951"
"184.60000","15.38315","871.30133"
"184.80000","15.40021","859.86584"
"185.00000","15.41698","849.35382"
"185.20000","15.43357","839.23962"
"185.40000","15.45025","829.00922"
"185.60000","15.46683","818.26819"
"185.80000","15.48351","807.87390"
"186.00000","15.50019","798.73175"
"186.20000","15.51678","790.53033"
"186.40000","15.53402","781.21454"
"186.60000","15.55023","772.44800"
"186.80000","15.56691","764.10144"
"187.00000","15.58359","755.97656"
"187.20000","15.60018","748.99860"
"187.40000","15.61686","741.02863"
"187.60000","15.63354","732.18121"
"187.80000","15.65031","724.92926"
"188.00000","15.66690","717.60925"
"188.20000","15.68348","711.24609"
"188.40000","15.70016","704.03082"
"188.60000","15.71637","696.91138"
"188.80000","15.73352","691.73004"
"189.00000","15.75020","684.81567"
"189.20000","15.76679","679.22980"
"189.40000","15.78337","673.38727"
"189.60000","15.80005","667.20221"
"189.80000","15.81683","660.59113"
"190.00000","15.83360","655.18610"
"190.20000","15.85019","649.54919"
"190.40000","15.86696","644.90326"
"190.60000","15.88364","639.41095"
"190.80000","15.90004","635.02698"
"191.00000","15.91690","629.04034"
"191.20000","15.93349","625.07495"
"191.40000","15.95017","620.66382"
"191.60000","15.96685","615.72925"
"191.80000","15.98353","610.74738"
"192.00000","16.00031","606.25916"
"192.20000","16.01689","601.32764"
"192.40000","16.03348","598.02228"
"192.60000","16.04997","593.56079"
"192.80000","16.06684","590.50769"
"193.00000","16.08323","585.42236"
"193.20000","16.10019","581.32947"
"193.40000","16.11678","578.17426"
"193.60000","16.13346","573.42059"
"193.80000","16.15023","570.24567"
"194.00000","16.16691","566.14374"
"194.20000","16.18359","562.21967"
"194.40000","16.20009","559.22931"
"194.60000","16.21667","555.45654"
"194.80000","16.23345","552.72260"
"195.00000","16.25031","549.45953"
"195.20000","16.26681","546.02887"
"195.40000","16.28348","542.50098"
"195.60000","16.30016","539.49139"
"195.80000","16.31684","536.56866"
"196.00000","16.33352","533.37756"
"196.20000","16.35030","530.05084"
"196.40000","16.36679","526.94672"
"196.60000","16.38319","523.37848"
"196.80000","16.39968","520.66797"
"197.00000","16.41692","517.30389"
"197.20000","16.43351","515.36218"
"197.40000","16.45019","512.15607"
"197.60000","16.46687","509.88901"
"197.80000","16.48355","507.22919"
"198.00000","16.50023","504.24780"
"198.20000","16.51691","501.18100"
"198.40000","16.53349","498.99350"
"198.60000","16.55036","496.04266"
"198.80000","16.56676","494.32941"
"199.00000","16.58307","491.54678"
"199.20000","16.60012","489.48508"
"199.40000","16.61680","486.97507"
"199.60000","16.63357","484.29510"
"199.80000","16.65016","482.95505"
"200.00000","16.66684","479.96347"
"200.20000","16.68389","477.71991"
"200.40000","16.70020","475.48419"
"200.60000","16.71688","472.65912"
"200.80000","16.73412","471.12164"
"201.00000","16.75014","469.30817"
"201.20000","16.76673","467.38586"
"201.40000","16.78341","464.46100"
"201.60000","16.80018","462.20435"
"201.80000","16.81686","460.27112"
"202.00000","16.83345","457.67532"
"202.20000","16.85022","454.92755"
"202.40000","16.86681","452.67233"
"202.60000","16.88339","450.49368"
"202.80000","16.90026","449.39584"
"203.00000","16.91685","447.12735"
"203.20000","16.93343","445.12665"
"203.40000","16.95011","443.09256"
"203.60000","16.96679","441.11969"
"203.80000","16.98357","440.16187"
"204.00000","17.00034","438.07077"
"204.20000","17.01683","436.51355"
"204.40000","17.03351","434.00098"
"204.60000","17.05019","431.99280"
"204.80000","17.06678","431.13968"
"205.00000","17.08355","429.36322"
"205.20000","17.10014","427.99701"
"205.40000","17.11672","425.86508"
"205.60000","17.13350","423.84042"
"205.80000","17.15018","422.52145"
"206.00000","17.16686","420.46564"
"206.20000","17.18344","419.32751"
"206.40000","17.20012","416.30807"
"206.60000","17.21699","414.67227"
"206.80000","17.23358","414.35986"
"207.00000","17.25016","411.89563"
"207.20000","17.26675","410.86838"
"207.40000","17.28343","408.68707"
"207.60000","17.30020","406.51910"
"207.80000","17.31688","405.29160"
"208.00000","17.33356","403.82288"
"208.20000","17.35015","402.43408"
"208.40000","17.36673","400.03406"
"208.60000","17.38351","397.86920"
"208.80000","17.40028","397.71222"
"209.00000","17.41724","395.64151"
"209.20000","17.43364","394.37540"
"209.40000","17.45004","392.58505"
"209.60000","17.46681","390.53412"
"209.80000","17.48349","389.29062"
"210.00000","17.50017","387.16440"
"210.20000","17.51666","385.96854"
"210.40000","17.53344","384.78995"
"210.60000","17.55021","382.75964"
"210.80000","17.56717","382.74478"
"211.00000","17.58348","381.11319"
"211.20000","17.60044","379.67896"
"211.40000","17.61674","378.26804"
"211.60000","17.63342","375.99072"
"211.80000","17.65020","374.76291"
"212.00000","17.66687","373.39505"
"212.20000","17.68355","372.03299"
"212.40000","17.70005","370.35312"
"212.60000","17.71682","368.10104"
"212.80000","17.73331","366.59616"
"213.00000","17.75018","365.96121"
"213.20000","17.76686","364.45096"
"213.40000","17.78345","363.71292"
"213.60000","17.80013","361.36938"
"213.80000","17.81690","360.15665"
"214.00000","17.83358","358.16840"
"214.20000","17.85026","356.69989"
"214.40000","17.86684","355.70557"
"214.60000","17.88352","352.71606"
"214.80000","17.90030","352.57275"
"215.00000","17.91688","351.22083"
"215.20000","17.93375","350.24741"
"215.40000","17.95015","348.28128"
"215.60000","17.96683","346.93982"
"215.80000","17.98351","346.31604"
"216.00000","18.00028","344.33286"
"216.20000","18.01687","343.22421"
"216.40000","18.03346","341.64340"
"216.60000","18.05014","339.80240"
"216.80000","18.06691","339.14902"
"217.00000","18.08331","337.81668"
"217.20000","18.10017","336.88504"
"217.40000","18.11685","335.83881"
"217.60000","18.13353","334.19916"
"217.80000","18.15021","333.69989"
"218.00000","18.16699","331.81979"
"218.20000","18.18357","330.39368"
"218.40000","18.20016","328.65576"
"218.60000","18.21684","327.40201"
"218.80000","18.23343","327.16895"
"219.00000","18.25039","324.22128"
"219.20000","18.26707","323.68716"
"219.40000","18.28346","322.65756"
"219.60000","18.30014","321.45874"
"219.80000","18.31682","320.42520"
"220.00000","18.33350","318.93240"
"220.20000","18.35018","317.63718"
"220.40000","18.36677","315.66800"
"220.60000","18.38354","314.25626"
"220.80000","18.40022","313.71317"
"221.00000","18.41709","311.61542"
"221.20000","18.43321","311.21243"
"221.40000","18.45017","309.63550"
"221.60000","18.46675","309.17157"
"221.80000","18.48343","307.85565"
"222.00000","18.50021","306.41599"
"222.20000","18.51679","304.77811"
"222.40000","18.53338","302.98990"
"222.60000","18.55015","301.65842"
"222.80000","18.56674","300.48260"
"223.00000","18.58342","299.17386"
"223.20000","18.60038","297.53717"
"223.40000","18.61697","295.64084"
"223.60000","18.63355","294.50754"
"223.80000","18.65023","293.66663"
"224.00000","18.66691","292.09979"
"224.20000","18.68359","290.38068"
"224.40000","18.70018","288.00360"
"224.60000","18.71676","286.29626"
"224.80000","18.73344","284.83224"
"225.00000","18.74965","282.68384"
"225.07400","18.75696","283.11014"