File: Lab 5/Polymer Data/G1-2/100924 HDPE 600N creep_1_G1_2.is_trelax_RawData/Specimen_RawData_1.csv
Time,Extension,Load
(s),(mm),(N)
"0.00000","0.00000","-1.24303"
"0.30000","0.05107","35.77483"
"0.60000","0.12678","84.12370"
"0.90000","0.40725","114.59245"
"1.20000","0.51511","187.68761"
"1.50000","0.59138","223.48732"
"1.80000","0.67806","266.47672"
"2.10000","0.77195","311.86096"
"2.40000","0.87007","356.02554"
"2.70000","0.97680","400.65109"
"3.00000","1.08953","445.49005"
"3.30000","1.20835","490.59787"
"3.60000","1.33635","535.94611"
"3.90000","1.47325","580.74908"
"4.03200","1.53604","600.53986"
"4.33200","1.59695","606.98901"
"4.63200","1.62675","603.21710"
"4.93200","1.65336","600.77264"
"5.23200","1.67810","600.01318"
"5.53200","1.70124","600.43848"
"5.83200","1.72298","600.12390"
"6.13200","1.74388","599.81042"
"6.43200","1.76215","599.98358"
"6.73200","1.77968","600.25476"
"7.03200","1.79720","599.51074"
"7.33200","1.81257","600.06549"
"7.63200","1.82859","599.92505"
"7.93200","1.84283","599.77411"
"8.23200","1.85717","600.25964"
"8.53200","1.87066","600.13647"
"8.83200","1.88519","599.48035"
"9.13200","1.89681","599.78662"
"9.43200","1.90983","600.16260"
"9.73200","1.92136","599.92761"
"10.03200","1.93307","600.36340"
"10.33200","1.94422","599.77875"
"10.63200","1.95519","599.94415"
"10.93200","1.96578","600.20245"
"11.23200","1.97543","600.88654"
"11.53200","1.98583","600.40778"
"11.83200","1.99483","600.35974"
"12.13200","2.00504","600.32043"
"12.43200","2.01450","599.56726"
"12.73200","2.02387","600.70251"
"13.03200","2.03287","600.08191"
"13.33200","2.04196","599.58014"
"13.63200","2.05124","599.66107"
"13.93200","2.05911","600.08142"
"14.23200","2.06576","599.96686"
"14.53200","2.07579","600.00110"
"14.83200","2.08282","600.18256"
"15.13200","2.09134","600.47858"
"15.43200","2.09931","600.00543"
"15.73200","2.10634","599.67053"
"16.03200","2.11365","599.82831"
"16.33200","2.12142","600.13641"
"16.63200","2.12948","600.32465"
"16.93200","2.13660","599.63403"
"17.23200","2.14335","600.20135"
"17.53200","2.14925","600.32184"
"17.83200","2.15675","599.75848"
"18.13200","2.16340","600.31854"
"18.43200","2.16996","599.98785"
"18.73200","2.17605","600.38873"
"19.03200","2.18280","600.85541"
"19.33200","2.18927","600.13440"
"19.63200","2.19639","600.28339"
"19.93200","2.20220","599.86371"
"20.23200","2.20866","600.19025"
"20.53200","2.21588","600.43066"
"20.83200","2.22150","600.12231"
"21.13200","2.22619","599.79810"
"21.43200","2.23228","599.17688"
"21.73200","2.23846","600.37280"
"22.03200","2.24474","600.13922"
"22.33200","2.25027","600.07495"
"22.63200","2.25561","600.22174"
"22.93200","2.26058","599.91724"
"23.23200","2.26639","599.90698"
"23.53200","2.27173","600.26556"
"23.83200","2.27744","600.01190"
"24.13200","2.28288","600.06659"
"24.43200","2.28794","600.20941"
"24.73200","2.29347","599.92371"
"25.03200","2.29834","600.21460"
"25.33200","2.30321","600.09613"
"25.63200","2.30752","599.78876"
"25.93200","2.31305","599.83649"
"26.23200","2.31830","600.30811"
"26.53200","2.32299","599.88416"
"26.83200","2.32776","600.14545"
"27.13200","2.33311","599.98590"
"27.43200","2.33807","599.35205"
"27.73200","2.34238","599.74377"
"28.03200","2.34735","600.46918"
"28.33200","2.35194","600.11816"
"28.63200","2.35681","599.41083"
"28.93200","2.36112","600.25415"
"29.23200","2.36572","600.18982"
"29.53200","2.37021","599.81250"
"29.83200","2.37602","599.67969"
"30.13200","2.38005","600.55096"
"30.43200","2.38427","600.40430"
"30.73200","2.38896","599.56952"
"31.03200","2.39195","599.50385"
"31.33200","2.39655","599.72974"
"31.63200","2.40114","600.85858"
"31.93200","2.40601","599.68481"
"32.23200","2.41079","600.04962"
"32.53200","2.41472","598.77979"
"32.83200","2.41810","600.00116"
"33.13200","2.42213","600.62036"
"33.43200","2.42625","599.68097"
"33.73200","2.43094","599.94830"
"34.03200","2.43487","600.39307"
"34.33200","2.43825","599.96356"
"34.63200","2.44256","600.05255"
"34.93200","2.44668","600.04254"
"35.23200","2.45099","599.83716"
"35.53200","2.45483","600.33783"
"35.83200","2.45839","599.50555"
"36.13200","2.46242","600.48505"
"36.43200","2.46617","599.81744"
"36.73200","2.46917","600.46521"
"37.03200","2.47273","600.40625"
"37.33200","2.47629","600.10736"
"37.63200","2.47994","600.05615"
"37.93200","2.48454","600.18414"
"38.23200","2.48725","600.13019"
"38.53200","2.49091","601.02386"
"38.83200","2.49475","599.95398"
"39.13200","2.49831","600.36707"
"39.43200","2.50225","599.78754"
"39.73200","2.50506","599.87677"
"40.03200","2.50899","600.16357"
"40.33200","2.51218","600.11346"
"40.63200","2.51574","599.63751"
"40.93200","2.51865","600.15607"
"41.23200","2.52267","600.07062"
"41.53200","2.52595","600.38000"
"41.83200","2.52914","599.56268"
"42.13200","2.53233","599.63416"
"42.43200","2.53598","599.75452"
"42.73200","2.53964","600.19391"
"43.03200","2.54282","600.15961"
"43.33200","2.54620","600.24670"
"43.63200","2.54976","598.97491"
"43.93200","2.55313","600.75653"
"44.23200","2.55538","599.73547"
"44.53200","2.55819","600.68292"
"44.83200","2.56100","600.40912"
"45.13200","2.56428","599.71814"
"45.43200","2.56822","600.80511"
"45.73200","2.57168","599.83228"
"46.03200","2.57365","600.49750"
"46.33200","2.57749","600.58813"
"46.63200","2.58049","599.77411"
"46.93200","2.58377","600.31342"
"47.23200","2.58668","600.07977"
"47.53200","2.58921","599.60126"
"47.83200","2.59221","599.80328"
"48.13200","2.59520","599.95703"
"48.43200","2.59811","599.86957"
"48.73200","2.60120","600.30798"
"49.03200","2.60439","599.53339"
"49.33200","2.60748","600.05298"
"49.63200","2.61020","599.94293"
"49.93200","2.61282","599.85535"
"50.23200","2.61591","600.58630"
"50.53200","2.61882","599.55597"
"50.83200","2.62172","600.66724"
"51.13200","2.62500","600.28528"
"51.43200","2.62791","600.33020"
"51.73200","2.63044","599.51550"
"52.03200","2.63372","600.49634"
"52.33200","2.63597","600.66223"
"52.63200","2.63896","599.88403"
"52.93200","2.64112","599.56110"
"53.23200","2.64365","599.75122"
"53.53200","2.64571","600.09552"
"53.83200","2.64918","600.11682"
"54.13200","2.65274","599.37549"
"54.43200","2.65508","599.90015"
"54.73200","2.65686","600.74823"
"55.03200","2.66042","600.07562"
"55.33200","2.66295","599.90802"
"55.63200","2.66548","600.29327"
"55.93200","2.66801","600.09790"
"56.23200","2.67064","600.19678"
"56.53200","2.67382","599.72931"
"56.83200","2.67607","599.80121"
"57.13200","2.67916","600.66779"
"57.43200","2.68151","599.90588"
"57.73200","2.68366","599.92957"
"58.03200","2.68694","600.49860"
"58.33200","2.68947","599.99127"
"58.63200","2.69228","599.62378"
"58.93200","2.69425","599.74988"
"59.23200","2.69753","599.91364"
"59.53200","2.69931","599.89990"
"59.83200","2.70194","599.75696"
"60.13200","2.70484","600.39044"
"60.43200","2.70775","599.98120"
"60.73200","2.71046","600.36981"
"61.03200","2.71234","599.67065"
"61.33200","2.71496","599.88855"
"61.63200","2.71740","600.19415"
"61.93200","2.71983","600.72278"
"62.23200","2.72086","601.10742"
"62.53200","2.72396","600.29358"
"62.83200","2.72611","600.51477"
"63.13200","2.72827","599.61804"
"63.43200","2.73089","599.60052"
"63.73200","2.73398","601.03333"
"64.03200","2.73661","600.85034"
"64.33200","2.73876","599.96808"
"64.63200","2.74129","600.62708"
"64.93200","2.74326","599.85443"
"65.23200","2.74663","599.67944"
"65.53200","2.74785","600.32599"
"65.83200","2.75048","600.03333"
"66.13200","2.75272","600.31519"
"66.43200","2.75497","600.41821"
"66.73200","2.75685","599.95575"
"67.03200","2.75938","600.70135"
"67.33200","2.76181","599.55695"
"67.63200","2.76350","599.44623"
"67.93200","2.76575","599.99664"
"68.23200","2.76790","599.55157"
"68.53200","2.76987","600.05511"
"68.83200","2.77193","600.50262"
"69.13200","2.77456","599.94415"
"69.43200","2.77709","600.56329"
"69.73200","2.77943","600.11462"
"70.03200","2.78121","599.99359"
"70.33200","2.78299","600.50281"
"70.63200","2.78590","599.77905"
"70.93200","2.78833","600.29138"
"71.23200","2.79002","599.74231"
"71.53200","2.79246","600.59180"
"71.83200","2.79470","600.14691"
"72.13200","2.79695","599.38232"
"72.43200","2.79930","599.69202"
"72.73200","2.80108","599.89246"
"73.03200","2.80314","599.62665"
"73.33200","2.80529","599.94586"
"73.63200","2.80745","599.59723"
"73.93200","2.80904","600.04083"
"74.23200","2.81092","599.90509"
"74.53200","2.81279","599.94476"
"74.83200","2.81607","599.40436"
"75.13200","2.81682","600.00531"
"75.43200","2.81944","599.77008"
"75.73200","2.82160","600.32220"
"76.03200","2.82338","599.97791"
"76.33200","2.82563","600.13190"
"76.63200","2.82788","600.04022"
"76.93200","2.82966","599.22656"
"77.23200","2.83163","599.85803"
"77.53200","2.83387","600.12830"
"77.83200","2.83584","599.64044"
"78.13200","2.83762","600.00275"
"78.43200","2.84025","599.35370"
"78.73200","2.84184","599.77911"
"79.03200","2.84409","599.46246"
"79.33200","2.84559","599.37244"
"79.63200","2.84774","599.68500"
"79.93200","2.84980","599.55640"
"80.23200","2.85177","600.43329"
"80.53200","2.85290","600.13470"
"80.83200","2.85543","599.75555"
"81.13200","2.85749","600.07361"
"81.43200","2.85918","600.18475"
"81.73200","2.86152","600.23175"
"82.03200","2.86330","600.11389"
"82.33200","2.86508","600.05475"
"82.63200","2.86695","599.55908"
"82.93200","2.86995","600.00763"
"83.23200","2.87079","600.11877"
"83.53200","2.87304","599.88654"
"83.83200","2.87539","600.26666"
"84.13200","2.87792","600.07373"
"84.43200","2.87895","600.45551"
"84.73200","2.88110","599.97382"
"85.03200","2.88288","599.97662"
"85.33200","2.88391","600.16150"
"85.63200","2.88551","599.94714"
"85.93200","2.88738","600.23016"
"86.23200","2.88860","600.57227"
"86.53200","2.89075","599.81177"
"86.83200","2.89253","600.67664"
"87.13200","2.89497","599.70209"
"87.43200","2.89666","599.80347"
"87.73200","2.89844","601.48297"
"88.03200","2.90041","599.46893"
"88.33200","2.90172","599.54657"
"88.63200","2.90425","599.83215"
"88.93200","2.90603","600.02869"
"89.23200","2.90753","600.21893"
"89.53200","2.90968","600.45264"
"89.83200","2.91118","600.40594"
"90.13200","2.91296","599.71643"
"90.43200","2.91437","600.90491"
"90.73200","2.91652","600.56860"
"91.03200","2.91793","599.70459"
"91.33200","2.92008","599.41278"
"91.63200","2.92149","600.87299"
"91.93200","2.92327","599.85663"
"92.23200","2.92571","599.11090"
"92.53200","2.92692","600.07404"
"92.83200","2.92880","600.09290"
"93.13200","2.93002","600.28943"
"93.43200","2.93142","599.52100"
"93.73200","2.93330","600.03925"
"94.03200","2.93536","600.19312"
"94.33200","2.93630","600.01318"
"94.63200","2.93808","599.75421"
"94.93200","2.94014","599.89746"
"95.23200","2.94164","600.30634"
"95.53200","2.94342","600.09796"
"95.83200","2.94473","599.78717"
"96.13200","2.94707","599.74860"
"96.43200","2.94838","600.15570"
"96.73200","2.94988","599.41290"
"97.03200","2.95148","599.75421"
"97.33200","2.95326","599.97778"
"97.63200","2.95504","599.65265"
"97.93200","2.95625","600.16541"
"98.23200","2.95841","600.15125"
"98.53200","2.96047","600.11151"
"98.83200","2.96188","599.95251"
"99.13200","2.96319","599.34473"
"99.43200","2.96534","599.72021"
"99.73200","2.96647","599.75470"
"100.03200","2.96787","600.63147"
"100.33200","2.96984","600.19244"
"100.63200","2.97078","600.80511"
"100.93200","2.97172","599.64685"
"101.23200","2.97387","599.03503"
"101.53200","2.97565","600.54962"
"101.83200","2.97668","599.90088"
"102.13200","2.97734","599.75952"
"102.43200","2.98099","599.77539"
"102.73200","2.98249","600.56427"
"103.03200","2.98465","599.61066"
"103.33200","2.98549","599.88715"
"103.63200","2.98746","599.30310"
"103.93200","2.98868","600.39905"
"104.23200","2.99046","600.72455"
"104.53200","2.99186","600.82776"
"104.83200","2.99364","599.72668"
"105.13200","2.99496","599.97754"
"105.43200","2.99655","599.97266"
"105.73200","2.99852","599.69312"
"106.03200","2.99983","599.92035"
"106.33200","3.00105","600.50629"
"106.63200","3.00358","600.16333"
"106.93200","3.00461","600.34558"
"107.23200","3.00611","599.71405"
"107.53200","3.00704","599.99542"
"107.83200","3.00911","599.98132"
"108.13200","3.01089","600.16333"
"108.43200","3.01192","601.12738"
"108.73200","3.01351","600.60419"
"109.03200","3.01463","600.49823"
"109.33200","3.01651","599.84772"
"109.63200","3.01791","599.94812"
"109.93200","3.01969","600.63538"
"110.23200","3.02138","600.00439"
"110.53200","3.02251","599.93219"
"110.83200","3.02391","599.92578"
"111.13200","3.02550","599.94342"
"111.43200","3.02747","600.28705"
"111.73200","3.02860","599.95355"
"112.03200","3.02953","600.58539"
"112.33200","3.03066","600.37036"
"112.63200","3.03234","600.46118"
"112.93200","3.03403","600.35229"
"113.23200","3.03562","600.22742"
"113.53200","3.03778","600.00958"
"113.83200","3.03872","600.30353"
"114.13200","3.04003","600.03113"
"114.43200","3.04172","600.52747"
"114.73200","3.04265","600.33191"
"115.03200","3.04453","599.89966"
"115.33200","3.04500","600.34778"
"115.63200","3.04715","600.57739"
"115.93200","3.04902","599.33521"
"116.23200","3.04987","600.56293"
"116.53200","3.05137","600.15356"
"116.83200","3.05240","599.84949"
"117.13200","3.05343","600.76855"
"117.43200","3.05427","600.92236"
"117.73200","3.05540","600.22443"
"118.03200","3.05727","599.75012"
"118.33200","3.05849","600.23914"
"118.63200","3.06102","599.60724"
"118.93200","3.06139","599.92078"
"119.23200","3.06336","598.70953"
"119.53200","3.06458","599.75220"
"119.83200","3.06533","599.58990"
"120.13200","3.06730","600.49939"
"120.43200","3.06823","599.80603"
"120.73200","3.06983","599.62738"
"121.03200","3.07133","600.15979"
"121.33200","3.07264","599.88116"
"121.63200","3.07376","599.54712"
"121.93200","3.07554","599.63739"
"122.23200","3.07714","600.25604"
"122.53200","3.07723","600.52490"
"122.83200","3.07920","600.78455"
"123.13200","3.08098","599.86139"
"123.43200","3.08229","599.70746"
"123.73200","3.08351","599.93750"
"124.03200","3.08473","600.52509"
"124.33200","3.08566","600.06152"
"124.63200","3.08688","599.51410"
"124.93200","3.08847","599.87439"
"125.23200","3.08979","599.29510"
"125.53200","3.09026","600.41132"
"125.83200","3.09194","599.34186"
"126.13200","3.09325","600.30737"
"126.43200","3.09475","600.29803"
"126.73200","3.09513","600.16309"
"127.03200","3.09635","600.03961"
"127.33200","3.09860","599.57697"
"127.63200","3.09972","599.72260"
"127.93200","3.10066","600.01062"
"128.23200","3.10244","599.79370"
"128.53200","3.10309","599.46130"
"128.83200","3.10431","599.88641"
"129.13200","3.10609","599.79443"
"129.43200","3.10768","599.84137"
"129.73200","3.10872","600.32343"
"130.03200","3.10993","599.91821"
"130.33200","3.11143","600.06268"
"130.63200","3.11293","599.67279"
"130.93200","3.11378","600.01685"
"131.23200","3.11490","599.84937"
"131.53200","3.11574","600.08539"
"131.83200","3.11752","600.02643"
"132.13200","3.11846","600.29535"
"132.43200","3.11987","600.43610"
"132.73200","3.12118","600.09705"
"133.03200","3.12296","600.42413"
"133.33200","3.12446","600.50519"
"133.63200","3.12465","600.26526"
"133.93200","3.12624","600.46698"
"134.23200","3.12708","600.59705"
"134.53200","3.12858","600.46497"
"134.83200","3.13017","600.17810"
"135.13200","3.13167","599.75189"
"135.43200","3.13252","599.36523"
"135.73200","3.13392","599.22900"
"136.03200","3.13523","600.92859"
"136.33200","3.13655","599.16614"
"136.63200","3.13692","599.36328"
"136.93200","3.13851","599.61993"
"137.23200","3.13898","599.91162"
"137.53200","3.14058","600.28931"
"137.83200","3.14151","600.12207"
"138.13200","3.14311","598.80182"
"138.43200","3.14367","599.48846"
"138.73200","3.14582","600.30042"
"139.03200","3.14695","600.96204"
"139.33200","3.14798","600.33832"
"139.63200","3.14957","599.62085"
"139.93200","3.15145","599.89807"
"140.23200","3.15210","599.89581"
"140.53200","3.15341","600.33197"
"140.83200","3.15416","600.17590"
"141.13200","3.15557","599.44403"
"141.43200","3.15697","599.59283"
"141.73200","3.15810","599.92047"
"142.03200","3.15904","600.08875"
"142.33200","3.16007","599.74731"
"142.63200","3.16175","599.76996"
"142.93200","3.16260","599.25262"
"143.23200","3.16391","600.18475"
"143.53200","3.16485","600.49396"
"143.83200","3.16653","599.68683"
"144.13200","3.16803","600.03876"
"144.43200","3.16944","600.51245"
"144.73200","3.16963","599.41968"
"145.03200","3.17122","599.76044"
"145.33200","3.17309","600.01703"
"145.63200","3.17412","600.41724"
"145.93200","3.17543","598.99506"
"146.23200","3.17618","600.22089"
"146.53200","3.17750","600.15747"
"146.83200","3.17834","599.91272"
"147.13200","3.17965","599.76215"
"147.43200","3.18115","599.42126"
"147.73200","3.18246","600.90289"
"148.03200","3.18331","600.72681"
"148.33200","3.18443","600.18170"
"148.63200","3.18574","599.77130"
"148.93200","3.18649","599.81683"
"149.23200","3.18762","600.06683"
"149.53200","3.18930","599.62317"
"149.83200","3.19052","599.83112"
"150.13200","3.19108","600.26416"
"150.43200","3.19286","599.97687"
"150.73200","3.19399","600.47247"
"151.03200","3.19483","600.01331"
"151.33200","3.19633","601.32678"
"151.63200","3.19699","600.11597"
"151.93200","3.19858","599.60150"
"152.23200","3.19914","600.35211"
"152.53200","3.20055","599.96979"
"152.83200","3.20186","599.92236"
"153.13200","3.20317","600.54596"
"153.43200","3.20467","600.06604"
"153.73200","3.20580","600.08478"
"154.03200","3.20701","600.29932"
"154.33200","3.20851","600.31360"
"154.63200","3.20879","600.24097"
"154.93200","3.21039","600.33533"
"155.23200","3.21132","600.19391"
"155.53200","3.21264","600.29694"
"155.83200","3.21357","600.71191"
"156.13200","3.21385","600.07477"
"156.43200","3.21601","599.63153"
"156.73200","3.21638","600.26630"
"157.03200","3.21760","598.93091"
"157.33200","3.21807","599.93701"
"157.63200","3.21948","600.18512"
"157.93200","3.21995","600.26416"
"158.23200","3.22135","600.61877"
"158.53200","3.22238","600.40485"
"158.83200","3.22323","599.05725"
"159.13200","3.22454","599.62695"
"159.43200","3.22510","599.83002"
"159.73200","3.22641","600.27301"
"160.03200","3.22735","599.91699"
"160.33200","3.22922","599.75684"
"160.63200","3.22969","600.41833"
"160.93200","3.23119","600.24976"
"161.23200","3.23222","600.48474"
"161.53200","3.23316","599.02130"
"161.83200","3.23428","600.23090"
"162.13200","3.23597","600.21362"
"162.43200","3.23719","600.60608"
"162.73200","3.23784","600.10480"
"163.03200","3.23897","599.62189"
"163.33200","3.24056","599.54852"
"163.63200","3.24103","600.41791"
"163.93200","3.24234","599.66156"
"164.23200","3.24318","600.74237"
"164.53200","3.24422","599.57758"
"164.83200","3.24543","599.92981"
"165.13200","3.24637","599.38385"
"165.43200","3.24768","600.42609"
"165.73200","3.24871","599.90723"
"166.03200","3.24956","600.09247"
"166.33200","3.25087","601.45667"
"166.63200","3.25087","600.39984"
"166.93200","3.25209","599.00464"
"167.23200","3.25405","599.28455"
"167.53200","3.25462","600.14551"
"167.83200","3.25574","599.72479"
"168.13200","3.25668","599.77808"
"168.43200","3.25724","600.63104"
"168.73200","3.25865","599.69354"
"169.03200","3.26052","600.06158"
"169.33200","3.26118","600.22388"
"169.63200","3.26193","599.64771"
"169.93200","3.26230","600.27838"
"170.23200","3.26436","599.51361"
"170.53200","3.26483","600.33563"
"170.83200","3.26577","599.88361"
"171.13200","3.26727","600.30951"
"171.43200","3.26839","599.45422"
"171.73200","3.26858","600.49036"
"172.03200","3.26923","600.11365"
"172.33200","3.27102","599.50604"
"172.63200","3.27148","600.04193"
"172.93200","3.27345","600.33032"
"173.23200","3.27439","600.37537"
"173.53200","3.27542","599.68701"
"173.83200","3.27570","599.79565"
"174.13200","3.27701","600.31366"
"174.43200","3.27814","600.22919"
"174.73200","3.27898","600.65552"
"175.03200","3.27964","600.43549"
"175.33200","3.28085","599.55322"
"175.63200","3.28207","599.87067"
"175.93200","3.28254","599.72980"
"176.23200","3.28357","599.48206"
"176.53200","3.28460","599.75439"
"176.83200","3.28657","600.41992"
"177.13200","3.28704","599.81744"
"177.43200","3.28760","600.16693"
"177.73200","3.28910","599.99695"
"178.03200","3.28938","600.82141"
"178.33200","3.29088","599.94800"
"178.63200","3.29219","599.77197"
"178.93200","3.29276","599.70844"
"179.23200","3.29397","599.69641"
"179.53200","3.29510","600.13214"
"179.83200","3.29641","600.55090"
"180.13200","3.29716","599.66638"
"180.43200","3.29735","600.01105"
"180.73200","3.29838","599.92346"
"181.03200","3.29960","600.08209"
"181.33200","3.30006","600.05768"
"181.63200","3.30081","599.43750"
"181.93200","3.30213","598.94550"
"182.23200","3.30213","601.37909"
"182.53200","3.30363","600.38983"
"182.83200","3.30456","599.77863"
"183.13200","3.30512","599.63867"
"183.43200","3.30634","598.92316"
"183.73200","3.30700","600.60828"
"184.03200","3.30869","600.44781"
"184.33200","3.30944","600.32861"
"184.63200","3.30934","599.54797"
"184.93200","3.31103","599.53143"
"185.23200","3.31075","599.33655"
"185.53200","3.31215","600.25665"
"185.83200","3.31421","599.39166"
"186.13200","3.31440","599.71106"
"186.43200","3.31524","599.83905"
"186.73200","3.31684","599.75763"
"187.03200","3.31768","599.99536"
"187.33200","3.31918","599.85455"
"187.63200","3.31974","599.64893"
"187.93200","3.32105","599.90063"
"188.23200","3.32246","600.30951"
"188.53200","3.32340","599.58813"
"188.83200","3.32387","599.78522"
"189.13200","3.32415","600.01001"
"189.43200","3.32527","600.51123"
"189.73200","3.32658","599.49622"
"190.03200","3.32724","600.39349"
"190.33200","3.32818","600.03369"
"190.63200","3.32911","599.55328"
"190.93200","3.33071","599.50409"
"191.23200","3.33080","600.48370"
"191.53200","3.33183","599.39069"
"191.83200","3.33296","599.79871"
"192.13200","3.33370","600.47131"
"192.43200","3.33445","600.00769"
"192.73200","3.33586","600.41772"
"193.03200","3.33698","600.94043"
"193.33200","3.33783","600.28723"
"193.63200","3.33839","600.39709"
"193.93200","3.33933","600.57520"
"194.23200","3.33989","599.52277"
"194.53200","3.34148","599.58832"
"194.83200","3.34223","599.98242"
"195.13200","3.34289","599.97833"
"195.43200","3.34373","599.94092"
"195.73200","3.34532","599.62964"
"196.03200","3.34589","599.72424"
"196.33200","3.34598","599.73218"
"196.63200","3.34804","600.25134"
"196.93200","3.34860","599.22931"
"197.23200","3.34907","599.80560"
"197.53200","3.35048","600.63690"
"197.83200","3.35076","600.41437"
"198.13200","3.35207","599.66101"
"198.43200","3.35338","600.03333"
"198.73200","3.35338","600.61346"
"199.03200","3.35526","600.49274"
"199.33200","3.35582","599.65619"
"199.63200","3.35638","599.99048"
"199.93200","3.35760","599.71057"
"200.23200","3.35826","599.94275"
"200.53200","3.35947","600.31378"
"200.83200","3.36051","600.53149"
"201.13200","3.36191","599.93018"
"201.43200","3.36266","600.64008"
"201.73200","3.36341","599.65894"
"202.03200","3.36378","600.30896"
"202.33200","3.36528","599.92432"
"202.63200","3.36632","599.87952"
"202.93200","3.36744","599.85339"
"203.23200","3.36800","600.08282"
"203.53200","3.36885","599.59503"
"203.83200","3.37016","600.72864"
"204.13200","3.37072","600.89825"
"204.43200","3.37156","600.39551"
"204.73200","3.37287","599.75336"
"205.03200","3.37381","599.72302"
"205.33200","3.37503","599.43970"
"205.63200","3.37522","600.52893"
"205.93200","3.37569","600.03784"
"206.23200","3.37672","599.26715"
"206.53200","3.37803","599.64673"
"206.83200","3.37887","600.29718"
"207.13200","3.38028","600.54443"
"207.43200","3.38093","600.43805"
"207.73200","3.38121","600.02118"
"208.03200","3.38215","600.45685"
"208.33200","3.38346","600.02563"
"208.63200","3.38346","600.37512"
"208.93200","3.38403","599.58911"
"209.23200","3.38487","601.17084"
"209.53200","3.38524","600.16058"
"209.83200","3.38656","600.03198"
"210.13200","3.38768","600.05963"
"210.43200","3.38796","599.86041"
"210.73200","3.38862","599.90839"
"211.03200","3.39040","599.79553"
"211.33200","3.39059","600.49817"
"211.63200","3.39152","599.88477"
"211.93200","3.39237","599.26160"
"212.23200","3.39302","601.22876"
"212.53200","3.39358","600.30609"
"212.83200","3.39536","600.30579"
"213.13200","3.39602","600.44708"
"213.43200","3.39733","600.46039"
"213.73200","3.39771","599.33759"
"214.03200","3.39883","600.76208"
"214.33200","3.39939","599.59961"
"214.63200","3.40127","599.55640"
"214.93200","3.40127","600.28314"
"215.23200","3.40249","599.17963"
"215.53200","3.40277","600.03595"
"215.83200","3.40399","598.85883"
"216.13200","3.40548","599.67365"
"216.43200","3.40567","600.01691"
"216.73200","3.40661","600.67834"
"217.03200","3.40736","599.73944"
"217.33200","3.40858","600.13214"
"217.63200","3.40904","600.04395"
"217.93200","3.40951","600.47351"
"218.23200","3.41036","599.58759"
"218.53200","3.41101","601.05438"
"218.83200","3.41129","599.68903"
"219.13200","3.41345","599.70673"
"219.43200","3.41439","599.49371"
"219.73200","3.41476","600.14783"
"220.03200","3.41504","601.05780"
"220.33200","3.41579","599.67181"
"220.63200","3.41739","599.48596"
"220.93200","3.41776","600.55756"
"221.23200","3.41823","599.66089"
"221.53200","3.41870","599.53113"
"221.83200","3.42020","599.86920"
"222.13200","3.42067","599.85223"
"222.43200","3.42113","599.65216"
"222.73200","3.42235","599.76184"
"223.03200","3.42348","600.16510"
"223.33200","3.42348","599.47778"
"223.63200","3.42451","600.07281"
"223.93200","3.42610","600.43140"
"224.23200","3.42601","599.74585"
"224.53200","3.42704","599.56677"
"224.83200","3.42760","599.69452"
"225.13200","3.42900","600.27014"
"225.43200","3.42891","599.93683"
"225.73200","3.42919","600.12311"
"226.03200","3.43032","599.66003"
"226.33200","3.43135","599.72937"
"226.63200","3.43285","599.82489"
"226.93200","3.43266","600.31836"
"227.23200","3.43369","600.29163"
"227.53200","3.43444","599.67511"
"227.83200","3.43491","600.67517"
"228.13200","3.43566","599.36670"
"228.43200","3.43669","599.99066"
"228.73200","3.43781","599.94513"
"229.03200","3.43819","600.90497"
"229.33200","3.43959","599.84045"
"229.63200","3.43969","599.57898"
"229.93200","3.44081","599.92114"
"230.23200","3.44203","599.86597"
"230.53200","3.44297","599.68329"
"230.83200","3.44344","600.49011"
"231.13200","3.44409","599.80957"
"231.43200","3.44475","600.34894"
"231.73200","3.44578","599.73724"
"232.03200","3.44653","599.91553"
"232.33200","3.44672","599.78070"
"232.63200","3.44821","599.89154"
"232.93200","3.44896","600.39233"
"233.23200","3.44962","599.87518"
"233.53200","3.45037","599.72882"
"233.83200","3.45159","600.78369"
"234.13200","3.45196","600.46490"
"234.43200","3.45271","599.77063"
"234.73200","3.45374","600.29065"
"235.03200","3.45431","599.97711"
"235.33200","3.45496","601.30115"
"235.63200","3.45524","599.64966"
"235.93200","3.45627","600.34625"
"236.23200","3.45730","600.26575"
"236.53200","3.45805","599.95544"
"236.83200","3.45899","600.63641"
"237.13200","3.46002","599.86090"
"237.43200","3.46002","600.57117"
"237.73200","3.46171","600.11035"
"238.03200","3.46255","600.22540"
"238.33200","3.46265","600.52441"
"238.63200","3.46311","600.26587"
"238.93200","3.46433","600.20380"
"239.23200","3.46536","599.23956"
"239.53200","3.46583","600.30750"
"239.83200","3.46602","599.40234"
"240.13200","3.46714","599.72864"
"240.43200","3.46761","600.57935"
"240.73200","3.46836","599.60297"
"241.03200","3.46958","599.77203"
"241.33200","3.47014","599.31396"
"241.63200","3.47024","599.18530"
"241.93200","3.47164","600.25842"
"242.23200","3.47230","599.55402"
"242.53200","3.47248","599.88123"
"242.83200","3.47352","601.04614"
"243.13200","3.47389","599.40436"
"243.43200","3.47511","600.11621"
"243.73200","3.47520","599.83240"
"244.03200","3.47595","600.74335"
"244.33200","3.47708","600.86169"
"244.63200","3.47867","599.58746"
"244.93200","3.47801","599.92816"
"245.23200","3.47989","599.87067"
"245.53200","3.48045","599.52692"
"245.83200","3.48157","599.60785"
"246.13200","3.48279","599.16876"
"246.43200","3.48289","599.54651"
"246.73200","3.48382","599.54810"
"247.03200","3.48504","600.19348"
"247.33200","3.48560","599.96399"
"247.63200","3.48588","599.94415"
"247.93200","3.48673","600.16333"
"248.23200","3.48729","600.47839"
"248.53200","3.48841","600.06201"
"248.83200","3.48841","600.78131"
"249.13200","3.48954","599.28699"
"249.43200","3.49066","599.91284"
"249.73200","3.49132","599.50018"
"250.03200","3.49188","599.56525"
"250.33200","3.49235","599.53186"
"250.63200","3.49301","599.83405"
"250.93200","3.49451","599.78296"
"251.23200","3.49441","600.53723"
"251.53200","3.49526","600.06366"
"251.83200","3.49638","599.81396"
"252.13200","3.49666","600.04254"
"252.43200","3.49722","600.20245"
"252.73200","3.49797","600.27039"
"253.03200","3.49816","599.50262"
"253.33200","3.49910","600.52618"
"253.63200","3.49994","599.70239"
"253.93200","3.50116","599.77966"
"254.23200","3.50181","599.68640"
"254.53200","3.50294","599.77991"
"254.83200","3.50303","600.19147"
"255.13200","3.50360","600.93695"
"255.43200","3.50463","599.70386"
"255.73200","3.50584","599.58020"
"256.03200","3.50697","600.52734"
"256.33200","3.50697","600.04297"
"256.63200","3.50762","599.95752"
"256.93200","3.50884","600.15784"
"257.23200","3.50959","600.04883"
"257.53200","3.50969","600.74518"
"257.83200","3.51044","600.46234"
"258.13200","3.51156","598.81287"
"258.43200","3.51184","600.21851"
"258.73200","3.51268","600.24573"
"259.03200","3.51362","599.78351"
"259.33200","3.51456","599.47388"
"259.63200","3.51475","599.70526"
"259.93200","3.51531","600.18170"
"260.23200","3.51587","600.38025"
"260.53200","3.51643","599.70184"
"260.83200","3.51746","600.59979"
"261.13200","3.51756","600.68787"
"261.43200","3.51868","599.83203"
"261.73200","3.51990","599.68048"
"262.03200","3.52112","600.03296"
"262.33200","3.52131","599.93573"
"262.63200","3.52215","599.59314"
"262.93200","3.52309","599.80933"
"263.23200","3.52327","600.20679"
"263.53200","3.52412","600.06299"
"263.83200","3.52487","600.58209"
"264.13200","3.52590","599.93506"
"264.43200","3.52590","599.74927"
"264.73200","3.52702","599.96716"
"265.03200","3.52758","600.54108"
"265.33200","3.52852","600.21564"
"265.63200","3.52899","600.14130"
"265.93200","3.52965","599.48883"
"266.23200","3.53058","600.33453"
"266.53200","3.53124","600.34338"
"266.83200","3.53208","599.64368"
"267.13200","3.53236","599.80231"
"267.43200","3.53367","600.79156"
"267.73200","3.53377","600.38159"
"268.03200","3.53452","599.61499"
"268.33200","3.53555","599.57336"
"268.63200","3.53705","599.78632"
"268.93200","3.53761","599.94086"
"269.23200","3.53817","599.78784"
"269.53200","3.53911","600.43951"
"269.83200","3.53967","599.63141"
"270.13200","3.54033","600.77301"
"270.43200","3.54098","599.14600"
"270.73200","3.54173","599.47919"
"271.03200","3.54258","599.79761"
"271.33200","3.54295","600.15924"
"271.63200","3.54351","600.21228"
"271.93200","3.54483","599.64850"
"272.23200","3.54511","600.63361"
"272.53200","3.54586","599.28412"
"272.83200","3.54623","600.61407"
"273.13200","3.54717","598.78455"
"273.43200","3.54801","600.00995"
"273.73200","3.54792","599.28979"
"274.03200","3.54839","599.64709"
"274.33200","3.54886","600.72180"
"274.63200","3.55035","600.95996"
"274.93200","3.55101","601.49164"
"275.23200","3.55139","599.72284"
"275.53200","3.55148","599.76947"
"275.83200","3.55223","600.06769"
"276.13200","3.55335","600.53094"
"276.43200","3.55373","599.84058"
"276.73200","3.55401","599.79846"
"277.03200","3.55570","600.07379"
"277.33200","3.55570","600.21918"
"277.63200","3.55626","599.74799"
"277.93200","3.55701","599.75903"
"278.23200","3.55776","599.74585"
"278.53200","3.55813","599.60681"
"278.83200","3.55898","599.95581"
"279.13200","3.55935","600.32080"
"279.43200","3.56048","598.91394"
"279.73200","3.56132","600.18927"
"280.03200","3.56235","600.20245"
"280.33200","3.56310","600.21875"
"280.63200","3.56329","600.24176"
"280.93200","3.56385","599.91742"
"281.23200","3.56479","600.14264"
"281.53200","3.56554","601.05945"
"281.83200","3.56610","600.05536"
"282.13200","3.56600","600.39258"
"282.43200","3.56816","598.95935"
"282.73200","3.56881","600.92853"
"283.03200","3.56891","600.98053"
"283.33200","3.57022","599.53107"
"283.63200","3.57060","600.09149"
"283.93200","3.57116","600.63342"
"284.23200","3.57228","600.14691"
"284.53200","3.57406","599.53888"
"284.83200","3.57416","600.78107"
"285.13200","3.57537","600.39435"
"285.43200","3.57575","600.31598"
"285.73200","3.57650","600.02631"
"286.03200","3.57790","599.37994"
"286.33200","3.57819","599.74670"
"286.63200","3.57940","599.38684"
"286.93200","3.57950","600.25085"
"287.23200","3.58062","599.63440"
"287.53200","3.58118","600.27246"
"287.83200","3.58118","600.03870"
"288.13200","3.58165","599.34821"
"288.43200","3.58268","600.06635"
"288.73200","3.58296","599.93481"
"289.03200","3.58353","600.30664"
"289.33200","3.58446","600.67957"
"289.63200","3.58475","600.26007"
"289.93200","3.58512","600.68311"
"290.23200","3.58568","600.88739"
"290.53200","3.58718","599.39087"
"290.83200","3.58756","599.48718"
"291.13200","3.58784","599.89240"
"291.43200","3.58868","599.20142"
"291.73200","3.58915","599.74298"
"292.03200","3.58971","600.36566"
"292.33200","3.59065","599.45728"
"292.63200","3.59084","600.20648"
"292.93200","3.59196","599.93964"
"293.23200","3.59271","600.08990"
"293.53200","3.59299","600.10205"
"293.83200","3.59365","599.68158"
"294.13200","3.59393","600.90802"
"294.43200","3.59458","600.04626"
"294.73200","3.59515","600.51990"
"295.03200","3.59618","599.63861"
"295.33200","3.59655","600.81989"
"295.63200","3.59768","600.24664"
"295.93200","3.59786","600.12115"
"296.23200","3.59852","599.91089"
"296.53200","3.59974","599.69092"
"296.83200","3.59946","600.21863"
"297.13200","3.60030","600.59222"
"297.43200","3.60114","600.45660"
"297.73200","3.60124","600.49847"
"298.03200","3.60171","599.54260"
"298.33200","3.60311","599.80292"
"298.63200","3.60292","600.10889"
"298.93200","3.60424","600.64905"
"299.23200","3.60433","599.63733"
"299.53200","3.60545","599.98401"
"299.83200","3.60602","600.37756"
"300.00000","3.60602","600.17084"