File: Lab 5/Polymer Data/100924 HDPE tensile test.is_tens_RawData/HDPE_TT.csv
Specimen properties : Length,"100.00000",mm
Specimen properties : Thickness,"1.00000",mm
Specimen properties : Width,"10.00000",mm
Test : Rate 1,"10.00000",mm/min

Time,Extension,Load
(s),(mm),(N)
"0.00000","0.00000","0.08183"
"0.25000","0.03833","26.67267"
"0.50000","0.08265","57.89977"
"0.75000","0.12500","63.54865"
"1.00000","0.16708","63.38015"
"1.25000","0.20868","63.52427"
"1.50000","0.25029","64.37840"
"1.75000","0.29208","65.02709"
"2.00000","0.33378","78.56490"
"2.25000","0.37539","104.53143"
"2.50000","0.41709","129.45473"
"2.75000","0.45879","152.75775"
"3.00000","0.50039","175.15254"
"3.25000","0.54200","196.90288"
"3.50000","0.58370","217.77200"
"3.75000","0.62540","238.30679"
"4.00000","0.66710","258.07651"
"4.25000","0.70870","276.20340"
"4.50000","0.75040","294.22662"
"4.75000","0.79201","312.70740"
"5.00000","0.83371","329.71030"
"5.25000","0.87531","346.24713"
"5.50000","0.91701","362.43634"
"5.75000","0.95862","378.54196"
"6.00000","1.00032","393.82321"
"6.25000","1.04192","408.57474"
"6.50000","1.08362","423.38278"
"6.75000","1.12532","438.13278"
"7.00000","1.16712","451.95273"
"7.25000","1.20863","465.58487"
"7.50000","1.25033","478.95493"
"7.75000","1.29203","492.13516"
"8.00000","1.33363","504.01086"
"8.25000","1.37524","516.06189"
"8.50000","1.41694","527.81885"
"8.75000","1.45864","539.70984"
"9.00000","1.50034","550.53064"
"9.25000","1.54194","561.34528"
"9.50000","1.58364","572.43335"
"9.75000","1.62515","583.47913"
"10.00000","1.66704","593.79199"
"10.25000","1.70865","603.89337"
"10.50000","1.75035","613.63367"
"10.75000","1.79204","624.42914"
"11.00000","1.83365","633.66510"
"11.25000","1.87535","642.40729"
"11.50000","1.91705","651.84473"
"11.75000","1.95865","660.15283"
"12.00000","2.00035","668.84790"
"12.25000","2.04196","677.50153"
"12.50000","2.08366","685.57880"
"12.75000","2.12536","693.42462"
"13.00000","2.16706","701.46277"
"13.25000","2.20866","708.61475"
"13.50000","2.25036","715.90698"
"13.75000","2.29197","723.65930"
"14.00000","2.33367","730.91437"
"14.25000","2.37527","737.32605"
"14.50000","2.41707","745.02576"
"14.75000","2.45867","751.79602"
"15.00000","2.50028","758.30023"
"15.25000","2.54198","764.86346"
"15.50000","2.58368","771.40607"
"15.75000","2.62528","777.59210"
"16.00000","2.66708","784.39691"
"16.25000","2.70868","789.94733"
"16.50000","2.75038","795.57935"
"16.75000","2.79199","801.74646"
"17.00000","2.83369","807.40491"
"17.25000","2.87529","812.91235"
"17.50000","2.91699","818.41431"
"17.75000","2.95860","824.78094"
"18.00000","3.00030","830.03333"
"18.25000","3.04200","834.78418"
"18.50000","3.08360","839.23303"
"18.75000","3.12530","844.94409"
"19.00000","3.16700","849.61456"
"19.25000","3.20861","854.75214"
"19.50000","3.25031","859.25366"
"19.75000","3.29210","863.46899"
"20.00000","3.33370","868.88031"
"20.25000","3.37522","873.00446"
"20.50000","3.41701","877.44745"
"20.75000","3.45871","882.62634"
"21.00000","3.50032","886.45776"
"21.25000","3.54201","891.01074"
"21.50000","3.58371","894.84967"
"21.75000","3.62523","899.14526"
"22.00000","3.66702","903.62421"
"22.25000","3.70872","907.71637"
"22.50000","3.75032","912.06042"
"22.75000","3.79202","915.97961"
"23.00000","3.83372","920.45135"
"23.25000","3.87533","924.41608"
"23.50000","3.91703","927.78400"
"23.75000","3.95863","931.58905"
"24.00000","4.00033","935.24304"
"24.25000","4.04203","938.51111"
"24.50000","4.08364","941.56256"
"24.75000","4.12543","945.15735"
"25.00000","4.16704","948.99200"
"25.25000","4.20864","952.22882"
"25.50000","4.25034","955.55115"
"25.75000","4.29195","959.10468"
"26.00000","4.33374","962.41913"
"26.25000","4.37535","965.61621"
"26.50000","4.41705","968.64514"
"26.75000","4.45856","971.47522"
"27.00000","4.50035","974.71851"
"27.25000","4.54196","977.75702"
"27.50000","4.58375","980.53815"
"27.75000","4.62526","983.68115"
"28.00000","4.66706","986.83972"
"28.25000","4.70866","989.64136"
"28.50000","4.75045","992.06592"
"28.75000","4.79197","995.06415"
"29.00000","4.83376","998.37909"
"29.25000","4.87537","1001.32965"
"29.50000","4.91707","1003.60791"
"29.75000","4.95867","1005.37317"
"30.00000","5.00037","1008.78577"
"30.25000","5.04198","1011.06866"
"30.50000","5.08368","1012.96735"
"30.75000","5.12537","1015.43225"
"31.00000","5.16698","1018.22925"
"31.25000","5.20859","1020.21368"
"31.50000","5.25038","1022.74738"
"31.75000","5.29199","1024.66284"
"32.00000","5.33368","1027.29932"
"32.25000","5.37529","1029.80737"
"32.50000","5.41708","1032.20740"
"32.75000","5.45869","1034.03674"
"33.00000","5.50029","1036.60046"
"33.25000","5.54199","1038.36975"
"33.50000","5.58369","1040.04614"
"33.75000","5.62530","1042.40161"
"34.00000","5.66709","1045.01965"
"34.25000","5.70870","1046.74292"
"34.50000","5.75040","1048.10815"
"34.75000","5.79200","1049.91467"
"35.00000","5.83370","1052.04163"
"35.25000","5.87531","1053.57361"
"35.50000","5.91701","1055.17981"
"35.75000","5.95861","1056.38647"
"36.00000","6.00041","1058.57410"
"36.25000","6.04192","1060.20593"
"36.50000","6.08371","1061.66931"
"36.75000","6.12541","1063.20264"
"37.00000","6.16711","1065.48254"
"37.25000","6.20862","1066.24243"
"37.50000","6.25042","1067.72998"
"37.75000","6.29202","1068.49658"
"38.00000","6.33372","1070.62012"
"38.25000","6.37533","1072.22656"
"38.50000","6.41712","1073.45020"
"38.75000","6.45863","1074.52942"
"39.00000","6.50033","1076.31531"
"39.25000","6.54203","1077.18384"
"39.50000","6.58373","1078.47388"
"39.75000","6.62534","1080.04858"
"40.00000","6.66713","1081.76111"
"40.25000","6.70864","1082.44373"
"40.50000","6.75034","1083.57336"
"40.75000","6.79195","1084.17126"
"41.00000","6.83374","1085.95471"
"41.25000","6.87535","1086.63062"
"41.50000","6.91704","1087.94971"
"41.75000","6.95865","1088.73254"
"42.00000","7.00035","1090.08752"
"42.25000","7.04196","1091.52148"
"42.50000","7.08375","1092.29871"
"42.75000","7.12535","1092.47571"
"43.00000","7.16705","1094.07715"
"43.25000","7.20866","1094.69995"
"43.50000","7.25036","1095.77808"
"43.75000","7.29196","1096.06531"
"44.00000","7.33366","1097.60767"
"44.25000","7.37536","1098.45691"
"44.50000","7.41706","1099.08923"
"44.75000","7.45858","1099.42505"
"45.00000","7.50037","1100.97998"
"45.25000","7.54197","1101.70801"
"45.50000","7.58377","1102.34204"
"45.75000","7.62528","1102.75818"
"46.00000","7.66707","1103.96069"
"46.25000","7.70868","1104.30994"
"46.50000","7.75038","1104.38684"
"46.75000","7.79198","1104.63196"
"47.00000","7.83387","1106.21436"
"47.25000","7.87529","1106.04944"
"47.50000","7.91699","1107.54382"
"47.75000","7.95859","1107.59119"
"48.00000","8.00029","1108.35400"
"48.25000","8.04199","1108.05457"
"48.50000","8.08369","1108.79639"
"48.75000","8.12530","1108.65161"
"49.00000","8.16690","1109.57056"
"49.25000","8.20870","1109.42383"
"49.50000","8.25039","1110.49060"
"49.75000","8.29200","1110.79126"
"50.00000","8.33370","1111.61499"
"50.25000","8.37540","1112.17102"
"50.50000","8.41701","1112.31750"
"50.75000","8.45861","1112.56274"
"51.00000","8.50022","1113.48047"
"51.25000","8.54220","1113.22107"
"51.50000","8.58371","1113.52942"
"51.75000","8.62541","1113.41687"
"52.00000","8.66711","1114.31201"
"52.25000","8.70899","1113.69727"
"52.50000","8.75041","1114.10889"
"52.75000","8.79211","1114.40857"
"53.00000","8.83428","1115.63733"
"53.25000","8.87542","1114.71558"
"53.50000","8.91702","1115.36597"
"53.75000","8.95882","1115.27563"
"54.00000","9.00033","1116.11975"
"54.25000","9.04203","1115.40735"
"54.50000","9.08382","1116.07129"
"54.75000","9.12533","1115.73560"
"55.00000","9.16778","1116.24268"
"55.25000","9.20892","1115.62927"
"55.50000","9.25034","1116.20312"
"55.75000","9.29213","1116.51184"
"56.00000","9.33374","1116.60046"
"56.25000","9.37515","1116.76086"
"56.50000","9.41685","1117.21814"
"56.75000","9.45865","1116.51611"
"57.00000","9.50035","1116.93164"
"57.25000","9.54205","1116.55713"
"57.50000","9.58365","1116.83496"
"57.75000","9.62526","1116.53625"
"58.00000","9.66705","1116.61243"
"58.25000","9.70856","1116.88550"
"58.50000","9.75036","1117.20752"
"58.75000","9.79196","1115.99097"
"59.00000","9.83366","1116.34021"
"59.25000","9.87536","1115.97302"
"59.50000","9.91706","1116.14209"
"59.75000","9.95857","1115.49902"
"60.00000","10.00037","1115.63635"
"60.25000","10.04216","1115.14978"
"60.50000","10.08377","1115.86096"
"60.75000","10.12546","1115.23279"
"61.00000","10.16698","1115.35876"
"61.25000","10.20868","1115.42908"
"61.50000","10.25028","1115.70361"
"61.75000","10.29207","1114.77576"
"62.00000","10.33396","1114.70520"
"62.25000","10.37547","1114.10498"
"62.50000","10.41699","1114.93958"
"62.75000","10.45859","1113.90601"
"63.00000","10.50029","1113.28503"
"63.25000","10.54208","1113.31763"
"63.50000","10.58369","1113.31677"
"63.75000","10.62530","1113.82642"
"64.00000","10.66690","1112.89099"
"64.25000","10.70841","1112.25977"
"64.50000","10.75039","1113.05066"
"64.75000","10.79200","1112.32324"
"65.00000","10.83398","1112.04102"
"65.25000","10.87521","1111.46594"
"65.50000","10.91710","1111.63867"
"65.75000","10.95870","1110.67896"
"66.00000","11.00040","1110.86499"
"66.25000","11.04191","1110.03198"
"66.50000","11.08371","1110.93872"
"66.75000","11.12531","1110.15332"
"67.00000","11.16683","1109.59863"
"67.25000","11.20890","1108.79834"
"67.50000","11.25032","1109.65002"
"67.75000","11.29202","1108.77930"
"68.00000","11.33372","1108.54810"
"68.25000","11.37560","1108.05408"
"68.50000","11.41674","1108.70410"
"68.75000","11.45872","1107.27722"
"69.00000","11.50033","1107.21936"
"69.25000","11.54175","1106.90564"
"69.50000","11.58382","1106.97827"
"69.75000","11.62533","1105.90833"
"70.00000","11.66694","1105.42786"
"70.25000","11.70864","1103.86548"
"70.50000","11.75071","1104.41016"
"70.75000","11.79204","1103.74255"
"71.00000","11.83355","1104.08630"
"71.25000","11.87534","1103.32812"
"71.50000","11.91695","1103.24365"
"71.75000","11.95865","1102.54138"
"72.00000","12.00016","1102.46033"
"72.25000","12.04195","1101.45850"
"72.50000","12.08403","1102.37317"
"72.75000","12.12526","1101.49622"
"73.00000","12.16686","1100.86865"
"73.25000","12.20903","1099.22595"
"73.50000","12.25045","1099.44153"
"73.75000","12.29196","1098.90686"
"74.00000","12.33366","1099.17029"
"74.25000","12.37536","1097.55042"
"74.50000","12.41697","1098.17285"
"74.75000","12.45866","1096.81018"
"75.00000","12.50036","1096.78015"
"75.25000","12.54197","1095.84998"
"75.50000","12.58367","1096.08118"
"75.75000","12.62537","1095.10022"
"76.00000","12.66707","1095.10547"
"76.25000","12.70867","1093.85388"
"76.50000","12.75028","1093.81091"
"76.75000","12.79207","1093.02271"
"77.00000","12.83368","1092.60742"
"77.25000","12.87528","1091.67188"
"77.50000","12.91698","1092.49097"
"77.75000","12.95868","1091.00061"
"78.00000","13.00038","1091.19519"
"78.25000","13.04208","1090.14380"
"78.50000","13.08369","1090.19568"
"78.75000","13.12539","1089.49414"
"79.00000","13.16708","1089.32507"
"79.25000","13.20869","1087.94873"
"79.50000","13.25030","1088.02527"
"79.75000","13.29209","1087.12012"
"80.00000","13.33370","1087.05261"
"80.25000","13.37530","1085.91052"
"80.50000","13.41653","1086.64062"
"80.75000","13.45870","1085.00269"
"81.00000","13.50040","1084.49573"
"81.25000","13.54201","1083.56873"
"81.50000","13.58361","1083.49390"
"81.75000","13.62540","1082.75012"
"82.00000","13.66701","1082.56860"
"82.25000","13.70862","1081.47302"
"82.50000","13.75031","1081.48315"
"82.75000","13.79202","1080.88525"
"83.00000","13.83362","1079.72961"
"83.25000","13.87532","1079.07361"
"83.50000","13.91702","1079.16553"
"83.75000","13.95863","1078.16309"
"84.00000","14.00042","1077.68787"
"84.25000","14.04212","1076.47559"
"84.50000","14.08363","1076.15454"
"84.75000","14.12533","1075.46082"
"85.00000","14.16703","1074.92310"
"85.25000","14.20864","1073.57227"
"85.50000","14.25024","1073.81543"
"85.75000","14.29203","1073.16760"
"86.00000","14.33373","1072.74683"
"86.25000","14.37525","1072.04236"
"86.50000","14.41694","1071.96558"
"86.75000","14.45864","1071.11963"
"87.00000","14.50034","1070.43896"
"87.25000","14.54195","1069.02173"
"87.50000","14.58365","1068.47583"
"87.75000","14.62535","1068.35754"
"88.00000","14.66705","1068.11304"
"88.25000","14.70875","1066.90381"
"88.50000","14.75016","1066.80176"
"88.75000","14.79196","1066.22754"
"89.00000","14.83366","1065.73755"
"89.25000","14.87536","1064.39343"
"89.50000","14.91715","1064.83630"
"89.75000","14.95857","1064.36829"
"90.00000","15.00036","1063.01050"
"90.25000","15.04206","1062.29700"
"90.50000","15.08339","1061.39502"
"90.75000","15.12527","1061.45410"
"91.00000","15.16697","1060.82507"
"91.25000","15.20867","1059.89868"
"91.50000","15.25009","1058.87659"
"91.75000","15.29207","1058.47607"
"92.00000","15.33377","1057.50073"
"92.25000","15.37528","1057.05200"
"92.50000","15.41698","1056.18323"
"92.75000","15.45868","1055.63794"
"93.00000","15.50038","1055.24878"
"93.25000","15.54208","1053.82849"
"93.50000","15.58472","1053.75256"
"93.75000","15.62538","1053.04773"
"94.00000","15.66699","1052.95874"
"94.25000","15.70869","1051.97461"
"94.50000","15.75039","1051.41406"
"94.75000","15.79209","1050.64124"
"95.00000","15.83369","1049.88623"
"95.25000","15.87539","1049.05151"
"95.50000","15.91681","1047.90417"
"95.75000","15.95860","1047.74194"
"96.00000","16.00040","1046.93005"
"96.25000","16.04200","1045.87903"
"96.50000","16.08361","1045.70312"
"96.75000","16.12540","1044.94299"
"97.00000","16.16701","1044.75671"
"97.25000","16.20871","1043.56970"
"97.50000","16.25031","1042.94434"
"97.75000","16.29211","1042.57178"
"98.00000","16.33362","1041.54846"
"98.25000","16.37532","1040.77051"
"98.50000","16.41692","1040.47388"
"98.75000","16.45872","1040.40649"
"99.00000","16.50032","1038.80835"
"99.25000","16.54193","1038.73450"
"99.50000","16.58363","1037.60254"
"99.75000","16.62533","1037.70789"
"100.00000","16.66693","1036.49939"
"100.25000","16.70863","1036.10632"
"100.50000","16.75043","1035.09729"
"100.75000","16.79203","1034.50696"
"101.00000","16.83364","1033.58997"
"101.25000","16.87543","1032.97351"
"101.50000","16.91694","1032.04443"
"101.75000","16.95855","1031.05042"
"102.00000","17.00043","1030.20093"
"102.25000","17.04204","1029.91992"
"102.50000","17.08402","1029.25012"
"102.75000","17.12581","1027.94067"
"103.00000","17.16695","1027.30920"
"103.25000","17.20865","1026.26514"
"103.50000","17.25035","1025.88904"
"103.75000","17.29196","1025.53357"
"104.00000","17.33356","1024.28882"
"104.25000","17.37526","1023.60834"
"104.50000","17.41687","1022.78638"
"104.75000","17.45838","1022.76147"
"105.00000","17.50027","1021.82709"
"105.25000","17.54206","1021.35669"
"105.50000","17.58366","1020.05524"
"105.75000","17.62527","1019.57794"
"106.00000","17.66697","1018.60034"
"106.25000","17.70867","1017.80640"
"106.50000","17.75037","1016.97772"
"106.75000","17.79226","1016.26257"
"107.00000","17.83377","1016.22876"
"107.25000","17.87528","1014.96362"
"107.50000","17.91717","1014.06055"
"107.75000","17.95868","1013.41046"
"108.00000","18.00038","1012.94952"
"108.25000","18.04198","1011.83466"
"108.50000","18.08368","1011.00635"
"108.75000","18.12482","1010.05157"
"109.00000","18.16699","1009.50525"
"109.25000","18.20859","1008.97064"
"109.50000","18.25011","1008.29303"
"109.75000","18.29209","1007.75922"
"110.00000","18.33341","1007.14545"
"110.25000","18.37530","1006.21014"
"110.50000","18.41709","1005.71234"
"110.75000","18.45888","1004.80383"
"111.00000","18.50030","1004.40399"
"111.25000","18.54191","1003.64490"
"111.50000","18.58361","1001.81494"
"111.75000","18.62540","1002.37585"
"112.00000","18.66719","1001.39624"
"112.25000","18.70871","1000.05341"
"112.50000","18.75012","999.78680"
"112.75000","18.79182","998.69519"
"113.00000","18.83371","997.74121"
"113.25000","18.87532","996.70868"
"113.50000","18.91692","996.16333"
"113.75000","18.95862","994.37262"
"114.00000","18.99985","993.69519"
"114.25000","19.04193","993.14160"
"114.50000","19.08353","992.77350"
"114.75000","19.12542","991.87445"
"115.00000","19.16740","991.16125"
"115.25000","19.20863","990.70862"
"115.50000","19.25024","989.74451"
"115.75000","19.29175","988.77075"
"116.00000","19.33364","988.21948"
"116.25000","19.37533","987.17529"
"116.50000","19.41703","986.56177"
"116.75000","19.45873","985.42572"
"117.00000","19.50062","985.06940"
"117.25000","19.54204","983.97394"
"117.50000","19.58364","982.97333"
"117.75000","19.62534","982.48187"
"118.00000","19.66695","981.54883"
"118.25000","19.70874","981.11664"
"118.50000","19.75035","980.06183"
"118.75000","19.79205","979.34967"
"119.00000","19.83375","978.47656"
"119.25000","19.87535","977.68866"
"119.50000","19.91705","976.45734"
"119.75000","19.95885","975.90137"
"120.00000","20.00026","974.98291"
"120.25000","20.04196","973.91077"
"120.50000","20.08366","973.31061"
"120.75000","20.12536","972.78467"
"121.00000","20.16687","972.46661"
"121.25000","20.20867","971.41211"
"121.50000","20.25046","970.74377"
"121.75000","20.29207","969.26849"
"122.00000","20.33358","968.99902"
"122.25000","20.37537","968.01605"
"122.50000","20.41698","967.18536"
"122.75000","20.45868","966.41510"
"123.00000","20.50038","965.86298"
"123.25000","20.54207","964.30231"
"123.50000","20.58368","963.46747"
"123.75000","20.62538","962.16461"
"124.00000","20.66698","961.95184"
"124.25000","20.70868","960.47803"
"124.50000","20.75039","959.82440"
"124.75000","20.79199","958.98767"
"125.00000","20.83360","957.69971"
"125.25000","20.87530","957.05353"
"125.50000","20.91699","956.22241"
"125.75000","20.95879","955.21967"
"126.00000","21.00030","954.88208"
"126.25000","21.04200","953.95239"
"126.50000","21.08360","952.98340"
"126.75000","21.12540","952.51251"
"127.00000","21.16729","951.97205"
"127.25000","21.20870","950.00171"
"127.50000","21.25040","949.39899"
"127.75000","21.29201","948.34528"
"128.00000","21.33380","947.66364"
"128.25000","21.37541","946.90491"
"128.50000","21.41701","945.64966"
"128.75000","21.45871","945.01825"
"129.00000","21.50032","944.58862"
"129.25000","21.54211","943.21350"
"129.50000","21.58372","942.36639"
"129.75000","21.62532","940.88965"
"130.00000","21.66702","940.58893"
"130.25000","21.70872","939.24103"
"130.50000","21.75033","938.14948"
"130.75000","21.79203","937.39191"
"131.00000","21.83372","936.58527"
"131.25000","21.87533","935.43176"
"131.50000","21.91694","934.57709"
"131.75000","21.95892","933.20001"
"132.00000","22.00024","932.99945"
"132.25000","22.04213","931.59064"
"132.50000","22.08364","930.77850"
"132.75000","22.12543","930.16553"
"133.00000","22.16676","929.05426"
"133.25000","22.20883","928.83203"
"133.50000","22.25035","926.57489"
"133.75000","22.29195","925.74384"
"134.00000","22.33346","924.87402"
"134.25000","22.37535","923.79877"
"134.50000","22.41705","922.74518"
"134.75000","22.45884","921.93109"
"135.00000","22.50017","920.72534"
"135.25000","22.54205","919.33990"
"135.50000","22.58366","918.44751"
"135.75000","22.62527","917.11011"
"136.00000","22.66753","916.09491"
"136.25000","22.70866","915.40924"
"136.50000","22.75027","914.41309"
"136.75000","22.79197","913.23822"
"137.00000","22.83367","911.86304"
"137.25000","22.87537","911.43127"
"137.50000","22.91698","910.53772"
"137.75000","22.95867","909.49854"
"138.00000","23.00009","907.68878"
"138.25000","23.04198","906.94360"
"138.50000","23.08368","906.03949"
"138.75000","23.12538","905.12970"
"139.00000","23.16698","903.35785"
"139.25000","23.20878","902.65491"
"139.50000","23.25038","901.98901"
"139.75000","23.29189","900.72229"
"140.00000","23.33359","899.17493"
"140.25000","23.37539","898.45441"
"140.50000","23.41699","897.54144"
"140.75000","23.45869","896.35040"
"141.00000","23.50030","895.03442"
"141.25000","23.54209","894.53503"
"141.50000","23.58370","892.75183"
"141.75000","23.62530","892.32196"
"142.00000","23.66709","890.54926"
"142.25000","23.70889","889.90106"
"142.50000","23.75031","888.23706"
"142.75000","23.79200","887.67090"
"143.00000","23.83380","885.73376"
"143.25000","23.87569","885.23340"
"143.50000","23.91710","884.11768"
"143.75000","23.95880","882.95227"
"144.00000","24.00032","881.04565"
"144.25000","24.04201","880.83978"
"144.50000","24.08372","879.42651"
"144.75000","24.12541","878.51501"
"145.00000","24.16683","876.73578"
"145.25000","24.20835","876.73541"
"145.50000","24.25032","874.30829"
"145.75000","24.29202","873.45941"
"146.00000","24.33354","871.62518"
"146.25000","24.37533","871.03192"
"146.50000","24.41703","869.21722"
"146.75000","24.45873","868.69586"
"147.00000","24.50033","866.77356"
"147.25000","24.54175","866.30658"
"147.50000","24.58364","865.38580"
"147.75000","24.62543","864.20386"
"148.00000","24.66704","862.63959"
"148.25000","24.70864","861.72626"
"148.50000","24.75025","860.40057"
"148.75000","24.79195","859.41077"
"149.00000","24.83346","858.02057"
"149.25000","24.87525","857.23663"
"149.50000","24.91705","855.54114"
"149.75000","24.95865","854.70630"
"150.00000","25.00035","852.77594"
"150.25000","25.04205","852.63818"
"150.50000","25.08366","850.89392"
"150.75000","25.12536","849.86377"
"151.00000","25.16715","847.96399"
"151.25000","25.20866","847.30109"
"151.50000","25.25027","846.00189"
"151.75000","25.29206","844.84180"
"152.00000","25.33357","842.64874"
"152.25000","25.37593","842.87189"
"152.50000","25.41697","840.55273"
"152.75000","25.45867","839.76050"
"153.00000","25.50027","837.82471"
"153.25000","25.54198","837.53839"
"153.50000","25.58368","835.88214"
"153.75000","25.62537","834.82385"
"154.00000","25.66698","833.36774"
"154.25000","25.70831","832.18439"
"154.50000","25.75038","831.41113"
"154.75000","25.79208","830.10944"
"155.00000","25.83368","828.36450"
"155.25000","25.87539","827.51056"
"155.50000","25.91662","826.11963"
"155.75000","25.95869","825.21692"
"156.00000","26.00039","823.01825"
"156.25000","26.04162","822.75781"
"156.50000","26.08435","820.64941"
"156.75000","26.12539","819.26801"
"157.00000","26.16709","817.41528"
"157.25000","26.20870","816.46387"
"157.50000","26.25040","815.56036"
"157.75000","26.29200","814.38245"
"158.00000","26.33361","812.20343"
"158.25000","26.37587","811.83521"
"158.50000","26.41701","810.66357"
"158.75000","26.45871","809.51459"
"159.00000","26.50041","808.06342"
"159.25000","26.54201","806.86163"
"159.50000","26.58362","805.75531"
"159.75000","26.62541","804.40118"
"160.00000","26.66692","802.58258"
"160.25000","26.70853","801.30420"
"160.50000","26.75042","800.28259"
"160.75000","26.79202","799.17212"
"161.00000","26.83353","797.50323"
"161.25000","26.87542","796.77264"
"161.50000","26.91721","795.35504"
"161.75000","26.95854","794.25073"
"162.00000","27.00033","792.38739"
"162.25000","27.04203","791.49054"
"162.50000","27.08392","790.60449"
"162.75000","27.12534","789.23108"
"163.00000","27.16704","787.54510"
"163.25000","27.20864","786.30438"
"163.50000","27.25025","785.30536"
"163.75000","27.29204","784.36798"
"164.00000","27.33365","782.39526"
"164.25000","27.37525","782.14075"
"164.50000","27.41714","780.50952"
"164.75000","27.45875","779.63385"
"165.00000","27.50035","777.65942"
"165.25000","27.54158","776.34735"
"165.50000","27.58356","775.59656"
"165.75000","27.62536","774.42743"
"166.00000","27.66696","772.21478"
"166.25000","27.70819","771.66565"
"166.50000","27.75036","770.40533"
"166.75000","27.79206","768.84949"
"167.00000","27.83357","767.51245"
"167.25000","27.87564","766.36707"
"167.50000","27.91735","765.31836"
"167.75000","27.95867","764.26807"
"168.00000","28.00028","762.32745"
"168.25000","28.04198","761.19299"
"168.50000","28.08367","760.35718"
"168.75000","28.12537","759.09467"
"169.00000","28.16707","757.92102"
"169.25000","28.20849","756.29755"
"169.50000","28.25056","756.07635"
"169.75000","28.29208","754.84167"
"170.00000","28.33378","752.56702"
"170.25000","28.37585","752.16364"
"170.50000","28.41746","750.76831"
"170.75000","28.45869","749.30859"
"171.00000","28.50029","747.09796"
"171.25000","28.54190","746.50079"
"171.50000","28.58360","745.55554"
"171.75000","28.62530","744.81030"
"172.00000","28.66690","742.89801"
"172.25000","28.70870","741.49866"
"172.50000","28.75011","740.49414"
"172.75000","28.79200","739.30200"
"173.00000","28.83370","737.50189"
"173.25000","28.87512","736.40259"
"173.50000","28.91710","734.86658"
"173.75000","28.95870","734.12299"
"174.00000","29.00031","732.06567"
"174.25000","29.04201","730.84271"
"174.50000","29.08362","730.57837"
"174.75000","29.12532","728.62994"
"175.00000","29.16702","727.55713"
"175.25000","29.20871","726.50177"
"175.50000","29.25023","724.83679"
"175.75000","29.29211","723.83911"
"176.00000","29.33363","722.47961"
"176.25000","29.37532","721.78009"
"176.50000","29.41693","720.53387"
"176.75000","29.45872","719.54443"
"177.00000","29.50033","717.39044"
"177.25000","29.54193","716.69043"
"177.50000","29.58373","715.33331"
"177.75000","29.62533","714.59625"
"178.00000","29.66694","712.93793"
"178.25000","29.70864","711.55133"
"178.50000","29.75025","709.81696"
"178.75000","29.79204","708.82587"
"179.00000","29.83364","707.63348"
"179.25000","29.87534","706.57355"
"179.50000","29.91704","705.27441"
"179.75000","29.95874","704.63831"
"180.00000","30.00035","703.14288"
"180.25000","30.04195","701.45819"
"180.50000","30.08365","700.00903"
"180.75000","30.12535","699.55902"
"181.00000","30.16705","698.28320"
"181.25000","30.20856","696.82965"
"181.50000","30.25035","695.38660"
"181.75000","30.29206","694.72742"
"182.00000","30.33366","693.34271"
"182.25000","30.37536","692.13000"
"182.50000","30.41706","690.52765"
"182.75000","30.45867","690.01855"
"183.00000","30.50037","688.78906"
"183.25000","30.54197","687.06219"
"183.50000","30.58377","686.33014"
"183.75000","30.62537","685.25165"
"184.00000","30.66707","683.84668"
"184.25000","30.70868","682.00311"
"184.50000","30.75038","681.30603"
"184.75000","30.79264","680.26483"
"185.00000","30.83368","679.37982"
"185.25000","30.87529","678.33844"
"185.50000","30.91698","676.61322"
"185.75000","30.95887","676.18512"
"186.00000","31.00039","675.27112"
"186.25000","31.04208","673.33350"
"186.50000","31.08369","672.59204"
"186.75000","31.12530","671.51599"
"187.00000","31.16709","670.06073"
"187.25000","31.20860","669.56927"
"187.50000","31.25030","668.12823"
"187.75000","31.29256","667.90198"
"188.00000","31.33370","666.04193"
"188.25000","31.37530","664.98584"
"188.50000","31.41700","663.74506"
"188.75000","31.45861","662.69531"
"189.00000","31.50031","661.83478"
"189.25000","31.54191","660.29407"
"189.50000","31.58361","658.81458"
"189.75000","31.62531","657.77771"
"190.00000","31.66701","656.94794"
"190.25000","31.70862","656.51233"
"190.50000","31.75032","654.78082"
"190.75000","31.79183","654.20203"
"191.00000","31.83372","653.27112"
"191.25000","31.87532","652.19293"
"191.50000","31.91711","650.93585"
"191.75000","31.95872","650.17120"
"192.00000","32.00042","649.14935"
"192.25000","32.04203","647.81219"
"192.50000","32.08363","646.39722"
"192.75000","32.12542","644.87958"
"193.00000","32.16703","644.67639"
"193.25000","32.20864","643.88123"
"193.50000","32.25052","642.63245"
"193.75000","32.29203","642.04468"
"194.00000","32.33374","641.29297"
"194.25000","32.37534","639.88690"
"194.50000","32.41704","639.08624"
"194.75000","32.45874","638.19299"
"195.00000","32.50025","636.80334"
"195.25000","32.54195","635.67468"
"195.50000","32.58365","635.16351"
"195.75000","32.62507","633.87567"
"196.00000","32.66705","633.47894"
"196.25000","32.70866","631.96460"
"196.50000","32.75045","631.29584"
"196.75000","32.79205","630.21863"
"197.00000","32.83375","629.77454"
"197.25000","32.87536","628.88214"
"197.50000","32.91706","628.17358"
"197.75000","32.95866","627.53961"
"198.00000","33.00036","627.08838"
"198.25000","33.04197","625.85889"
"198.50000","33.08376","625.22650"
"198.75000","33.12518","624.71631"
"199.00000","33.16697","624.22498"
"199.25000","33.20858","623.65265"
"199.50000","33.25047","622.62701"
"199.75000","33.29198","622.14526"
"200.00000","33.33368","621.59265"
"200.25000","33.37528","620.75751"
"200.50000","33.41708","619.41602"
"200.75000","33.45859","619.24255"
"201.00000","33.50066","619.65137"
"201.25000","33.54199","618.47736"
"201.50000","33.58369","617.62573"
"201.75000","33.62529","616.55206"
"202.00000","33.66774","617.11981"
"202.25000","33.70869","615.88837"
"202.50000","33.75048","615.21185"
"202.75000","33.79200","614.28528"
"203.00000","33.83369","613.85327"
"203.25000","33.87521","613.61914"
"203.50000","33.91700","613.11292"
"203.75000","33.95861","612.57983"
"204.00000","34.00031","612.07623"
"204.25000","34.04191","611.62457"
"204.50000","34.08371","611.48431"
"204.75000","34.12531","610.79602"
"205.00000","34.16729","610.57446"
"205.25000","34.20861","610.33179"
"205.50000","34.25032","609.62488"
"205.75000","34.29202","608.82635"
"206.00000","34.33353","608.45789"
"206.25000","34.37532","608.03851"
"206.50000","34.41702","607.78180"
"206.75000","34.45863","607.25354"
"207.00000","34.50032","606.88324"
"207.25000","34.54202","606.02777"
"207.50000","34.58372","606.09369"
"207.75000","34.62533","605.98566"
"208.00000","34.66693","606.23938"
"208.25000","34.70873","605.68262"
"208.50000","34.75034","605.04523"
"208.75000","34.79203","604.59515"
"209.00000","34.83373","604.63922"
"209.25000","34.87534","604.17389"
"209.50000","34.91713","603.84943"
"209.75000","34.95874","603.58795"
"210.00000","35.00100","603.49799"
"210.25000","35.04205","603.61877"
"210.50000","35.08384","602.91656"
"210.75000","35.12535","602.65552"
"211.00000","35.16695","602.22266"
"211.25000","35.20865","601.82202"
"211.50000","35.25044","602.00269"
"211.75000","35.29214","601.67493"
"212.00000","35.33366","601.41925"
"212.25000","35.37536","600.96997"
"212.50000","35.41706","601.09937"
"212.75000","35.45885","600.63184"
"213.00000","35.50027","600.65967"
"213.25000","35.54197","600.19263"
"213.50000","35.58367","600.56689"
"213.75000","35.62527","600.24615"
"214.00000","35.66744","599.93524"
"214.25000","35.70867","600.07324"
"214.50000","35.75028","599.81470"
"214.75000","35.79207","599.66479"
"215.00000","35.83339","599.13995"
"215.25000","35.87528","599.46533"
"215.50000","35.91707","599.48468"
"215.75000","35.95868","599.53595"
"216.00000","36.00038","598.96075"
"216.25000","36.04198","599.15881"
"216.50000","36.08378","599.04071"
"216.75000","36.12529","598.79352"
"217.00000","36.16680","599.16058"
"217.25000","36.20869","598.04932"
"217.50000","36.25039","598.19122"
"217.75000","36.29190","598.09418"
"218.00000","36.33369","598.09583"
"218.25000","36.37539","598.00970"
"218.50000","36.41709","598.25739"
"218.75000","36.45860","598.23700"
"219.00000","36.50058","597.47168"
"219.25000","36.54200","598.04352"
"219.50000","36.58370","597.90240"
"219.75000","36.62531","597.72742"
"220.00000","36.66701","597.70209"
"220.25000","36.70871","597.69531"
"220.50000","36.75040","597.90735"
"220.75000","36.79211","597.63379"
"221.00000","36.83371","597.75983"
"221.25000","36.87532","597.15857"
"221.50000","36.91711","597.36664"
"221.75000","36.95862","597.36597"
"222.00000","37.00042","596.56256"
"222.25000","37.04202","596.44342"
"222.50000","37.08382","596.74567"
"222.75000","37.12523","596.41064"
"223.00000","37.16703","596.39960"
"223.25000","37.20872","596.60846"
"223.50000","37.25043","596.44885"
"223.75000","37.29203","596.31403"
"224.00000","37.33373","596.51086"
"224.25000","37.37534","596.83160"
"224.50000","37.41713","596.78119"
"224.75000","37.45864","596.60309"
"225.00000","37.50043","596.59454"
"225.25000","37.54195","596.77148"
"225.50000","37.58374","597.09747"
"225.75000","37.62525","596.97876"
"226.00000","37.66704","597.04840"
"226.25000","37.70865","597.35693"
"226.50000","37.75045","597.91168"
"226.75000","37.79196","597.22986"
"227.00000","37.83365","597.72644"
"227.25000","37.87535","597.75488"
"227.50000","37.91706","597.50153"
"227.75000","37.95866","597.71631"
"228.00000","38.00036","597.38220"
"228.25000","38.04197","597.44489"
"228.50000","38.08376","598.12146"
"228.75000","38.12527","597.25317"
"229.00000","38.16706","597.60541"
"229.25000","38.20867","597.90790"
"229.50000","38.25037","598.42218"
"229.75000","38.29197","598.12518"
"230.00000","38.33377","597.63226"
"230.25000","38.37528","598.18585"
"230.50000","38.41698","598.42847"
"230.75000","38.45868","598.18024"
"231.00000","38.50038","597.98755"
"231.25000","38.54198","598.29596"
"231.50000","38.58368","599.07001"
"231.75000","38.62538","598.48309"
"232.00000","38.66708","598.08026"
"232.25000","38.70869","598.42102"
"232.50000","38.75048","598.46930"
"232.75000","38.79199","597.91455"
"233.00000","38.83369","597.44519"
"233.25000","38.87539","598.07281"
"233.50000","38.91709","598.56421"
"233.75000","38.95869","597.91077"
"234.00000","39.00021","598.50879"
"234.25000","39.04210","598.66779"
"234.50000","39.08379","598.69635"
"234.75000","39.12531","598.14099"
"235.00000","39.16701","598.15759"
"235.25000","39.20861","598.30646"
"235.50000","39.25040","598.99091"
"235.75000","39.29201","597.94153"
"236.00000","39.33371","598.33557"
"236.25000","39.37541","598.52472"
"236.50000","39.41711","599.38361"
"236.75000","39.45871","598.35852"
"237.00000","39.50042","598.90405"
"237.25000","39.54211","598.89081"
"237.50000","39.58372","599.34363"
"237.75000","39.62532","599.24585"
"238.00000","39.66712","599.49353"
"238.25000","39.70853","599.39862"
"238.50000","39.75042","599.74219"
"238.75000","39.79193","599.07452"
"239.00000","39.83373","599.04236"
"239.25000","39.87496","599.54816"
"239.50000","39.91703","599.80548"
"239.75000","39.95864","599.31708"
"240.00000","40.00034","599.96771"
"240.25000","40.04195","599.83148"
"240.50000","40.08364","600.96283"
"240.75000","40.12525","599.91846"
"241.00000","40.16685","600.02411"
"241.25000","40.20940","600.18494"
"241.50000","40.24997","602.52722"
"241.75000","40.29195","600.07611"
"242.00000","40.33366","600.78583"
"242.25000","40.37535","600.13324"
"242.50000","40.41696","601.13422"
"242.75000","40.45866","600.92847"
"243.00000","40.50026","600.90155"
"243.25000","40.54187","600.18549"
"243.50000","40.58441","600.82874"
"243.75000","40.62527","599.99438"
"244.00000","40.66697","600.57758"
"244.25000","40.70857","600.38776"
"244.50000","40.75046","600.95581"
"244.75000","40.79188","600.40967"
"245.00000","40.83358","600.61731"
"245.25000","40.87537","600.89819"
"245.50000","40.91641","601.17462"
"245.75000","40.95858","600.76825"
"246.00000","41.00037","600.57062"
"246.25000","41.04208","600.57385"
"246.50000","41.08358","600.63617"
"246.75000","41.12538","600.15674"
"247.00000","41.16699","600.83569"
"247.25000","41.20868","600.22180"
"247.50000","41.25085","600.91888"
"247.75000","41.29199","600.42468"
"248.00000","41.33369","601.61322"
"248.25000","41.37539","600.59845"
"248.50000","41.41700","600.93439"
"248.75000","41.45869","600.82208"
"249.00000","41.50030","601.15216"
"249.25000","41.54200","600.26697"
"249.50000","41.58370","600.82196"
"249.75000","41.62531","600.38184"
"250.00000","41.66700","600.89484"
"250.25000","41.70861","600.05688"
"250.50000","41.75040","601.14355"
"250.75000","41.79201","600.50641"
"251.00000","41.83371","600.55450"
"251.25000","41.87541","600.63019"
"251.50000","41.91702","601.11096"
"251.75000","41.95862","600.14056"
"252.00000","42.00041","600.92444"
"252.25000","42.04211","600.29578"
"252.50000","42.08363","601.10260"
"252.75000","42.12532","600.43530"
"253.00000","42.16702","600.87994"
"253.25000","42.20863","600.37720"
"253.50000","42.25033","601.21997"
"253.75000","42.29203","600.28662"
"254.00000","42.33372","600.89453"
"254.25000","42.37524","600.35962"
"254.50000","42.41703","600.29260"
"254.75000","42.45864","599.76343"
"255.00000","42.50034","600.56006"
"255.25000","42.54194","599.59180"
"255.50000","42.58364","600.42114"
"255.75000","42.62534","599.21692"
"256.00000","42.66704","599.74316"
"256.25000","42.70883","599.32739"
"256.50000","42.75044","599.72369"
"256.75000","42.79195","599.55139"
"257.00000","42.83365","599.35229"
"257.25000","42.87535","599.24640"
"257.50000","42.91724","599.18256"
"257.75000","42.95866","597.76660"
"258.00000","43.00045","599.14105"
"258.25000","43.04206","598.29901"
"258.50000","43.08347","598.30719"
"258.75000","43.12536","598.13959"
"259.00000","43.16706","598.07953"
"259.25000","43.20867","597.52899"
"259.50000","43.24999","597.86121"
"259.75000","43.29197","596.79681"
"260.00000","43.33367","597.31268"
"260.25000","43.37527","596.35822"
"260.50000","43.41697","596.64374"
"260.75000","43.45868","595.54211"
"261.00000","43.50037","595.64264"
"261.25000","43.54207","595.11084"
"261.50000","43.58377","594.56049"
"261.75000","43.62538","594.62878"
"262.00000","43.66698","594.14142"
"262.25000","43.70877","593.86810"
"262.50000","43.75029","593.50067"
"262.75000","43.79199","592.91364"
"263.00000","43.83369","592.91473"
"263.25000","43.87539","592.03040"
"263.50000","43.91681","591.88849"
"263.75000","43.95823","591.24457"
"264.00000","44.00039","591.63959"
"264.25000","44.04209","590.92151"
"264.50000","44.08369","590.57568"
"264.75000","44.12531","590.60498"
"265.00000","44.16710","589.45563"
"265.25000","44.20879","589.11871"
"265.50000","44.25040","588.55109"
"265.75000","44.29182","587.71228"
"266.00000","44.33361","587.44708"
"266.25000","44.37531","587.03064"
"266.50000","44.41701","586.77173"
"266.75000","44.45899","586.31635"
"267.00000","44.50023","585.40179"
"267.25000","44.54202","585.02637"
"267.50000","44.58372","584.45398"
"267.75000","44.62542","584.52838"
"268.00000","44.66693","583.27533"
"268.25000","44.70872","582.48175"
"268.50000","44.75032","581.57874"
"268.75000","44.79212","581.43359"
"269.00000","44.83363","581.09631"
"269.25000","44.87533","580.37524"
"269.50000","44.91703","580.06653"
"269.75000","44.95854","579.43732"
"270.00000","45.00033","578.72461"
"270.25000","45.04194","578.28619"
"270.50000","45.08355","577.57416"
"270.75000","45.12534","578.39996"
"271.00000","45.16695","576.68341"
"271.25000","45.20864","575.68518"
"271.50000","45.25034","574.90265"
"271.75000","45.29204","574.60211"
"272.00000","45.33365","573.57587"
"272.25000","45.37535","572.73962"
"272.50000","45.41705","572.36798"
"272.75000","45.45912","571.72369"
"273.00000","45.50026","571.34326"
"273.25000","45.54196","570.12659"
"273.50000","45.58366","569.74640"
"273.75000","45.62545","568.82611"
"274.00000","45.66706","568.40735"
"274.25000","45.70876","567.69214"
"274.50000","45.75036","566.94287"
"274.75000","45.79178","566.08435"
"275.00000","45.83367","565.71210"
"275.25000","45.87537","564.77460"
"275.50000","45.91707","563.71747"
"275.75000","45.95867","563.94769"
"276.00000","46.00037","562.47150"
"276.25000","46.04207","561.78082"
"276.50000","46.08368","560.40741"
"276.75000","46.12556","559.64484"
"277.00000","46.16698","560.05304"
"277.25000","46.20868","559.37225"
"277.50000","46.25038","558.25061"
"277.75000","46.29208","557.20325"
"278.00000","46.33359","556.70709"
"278.25000","46.37529","555.98022"
"278.50000","46.41699","555.02576"
"278.75000","46.45860","554.12067"
"279.00000","46.50029","553.19446"
"279.25000","46.54200","552.30640"
"279.50000","46.58369","551.15631"
"279.75000","46.62502","550.57410"
"280.00000","46.66710","549.91071"
"280.25000","46.70870","549.37213"
"280.50000","46.75040","548.89124"
"280.75000","46.79200","548.18103"
"281.00000","46.83361","547.61652"
"281.25000","46.87540","546.46265"
"281.50000","46.91701","545.86816"
"281.75000","46.95861","545.35077"
"282.00000","47.00032","545.14490"
"282.25000","47.04201","543.91229"
"282.50000","47.08362","542.92108"
"282.75000","47.12532","542.46790"
"283.00000","47.16692","542.09802"
"283.25000","47.20872","540.93646"
"283.50000","47.25032","540.86639"
"283.75000","47.29193","540.08405"
"284.00000","47.33410","540.20148"
"284.25000","47.37533","538.45367"
"284.50000","47.41712","537.26978"
"284.75000","47.45863","537.17719"
"285.00000","47.50042","536.77484"
"285.25000","47.54203","535.04633"
"285.50000","47.58364","534.31952"
"285.75000","47.62524","533.77808"
"286.00000","47.66760","534.19434"
"286.25000","47.70873","531.89935"
"286.50000","47.75025","531.17535"
"286.75000","47.79195","530.42755"
"287.00000","47.83364","529.50214"
"287.25000","47.87534","528.83423"
"287.50000","47.91705","527.28357"
"287.75000","47.95875","526.82416"
"288.00000","48.00016","526.53754"
"288.25000","48.04195","525.65564"
"288.50000","48.08375","524.39331"
"288.75000","48.12545","523.45392"
"289.00000","48.16668","522.97400"
"289.25000","48.20875","521.53156"
"289.50000","48.25036","520.35486"
"289.75000","48.29206","519.38763"
"290.00000","48.33339","518.75293"
"290.25000","48.37536","517.54022"
"290.50000","48.41706","516.49573"
"290.75000","48.45876","515.85327"
"291.00000","48.49990","515.44489"
"291.25000","48.54197","514.34326"
"291.50000","48.58367","512.69891"
"291.75000","48.62538","511.80640"
"292.00000","48.66707","511.14798"
"292.25000","48.70868","509.52313"
"292.50000","48.75028","508.51852"
"292.75000","48.79198","507.45435"
"293.00000","48.83377","507.45905"
"293.25000","48.87529","505.67914"
"293.50000","48.91699","505.14368"
"293.75000","48.95878","503.43527"
"294.00000","49.00048","503.56946"
"294.25000","49.04199","501.66013"
"294.50000","49.08360","501.20383"
"294.75000","49.12529","499.91898"
"295.00000","49.16690","499.10922"
"295.25000","49.20869","498.24655"
"295.50000","49.25040","497.58237"
"295.75000","49.29200","496.00778"
"296.00000","49.33361","495.32199"
"296.25000","49.37540","494.29694"
"296.50000","49.41692","493.47818"
"296.75000","49.45871","492.42935"
"297.00000","49.50031","491.56183"
"297.25000","49.54201","490.44006"
"297.50000","49.58362","489.72852"
"297.75000","49.62532","488.35959"
"298.00000","49.66730","487.18491"
"298.25000","49.70872","486.69092"
"298.50000","49.75023","485.71997"
"298.75000","49.79211","484.50409"
"299.00000","49.83344","483.93951"
"299.25000","49.87542","483.32346"
"299.50000","49.91703","482.03873"
"299.75000","49.95872","480.91104"
"300.00000","50.00042","479.41641"
"300.25000","50.04212","478.62744"
"300.50000","50.08372","478.02374"
"300.75000","50.12542","476.44196"
"301.00000","50.16694","475.69458"
"301.25000","50.20883","474.64719"
"301.50000","50.25043","473.38895"
"301.75000","50.29204","471.96051"
"302.00000","50.33345","471.17834"
"302.25000","50.37544","470.52359"
"302.29400","50.38275","470.13177"